2019-02-12 16:39:31,627 - tools.log - ERROR - 任务开始！！！
2019-02-12 16:40:47,405 - tools.log - ERROR - 任务开始！！！
2019-02-12 16:42:11,916 - tools.log - ERROR - 任务开始！！！
2019-02-12 16:44:53,582 - tools.log - ERROR - 任务开始！！！
2019-02-12 16:45:30,610 - tools.log - ERROR - 任务开始！！！
2019-02-12 16:49:20,257 - tools.log - ERROR - 任务开始！！！
2019-02-12 16:49:47,800 - tools.log - ERROR - 任务开始！！！
2019-02-12 16:50:54,742 - tools.log - ERROR - 任务开始！！！
2019-02-12 16:53:22,747 - tools.log - ERROR - 任务开始！！！
2019-02-12 17:00:03,107 - tools.log - ERROR - 任务开始！！！
2019-02-12 17:01:33,288 - tools.log - ERROR - 任务开始！！！
2019-03-21 16:40:55,530 - tools.log - ERROR - invalid literal for int() with base 10: '["1"]'
2019-03-21 16:41:27,373 - tools.log - ERROR - invalid literal for int() with base 10: '["1"]'
2019-03-21 16:43:57,925 - tools.log - ERROR - invalid literal for int() with base 10: '['
2019-03-21 16:44:00,918 - tools.log - ERROR - invalid literal for int() with base 10: '['
2019-03-21 16:45:26,917 - tools.log - ERROR - invalid literal for int() with base 10: '['
2019-03-21 16:46:47,511 - tools.log - ERROR - 'int' object is not iterable
2019-03-21 16:48:13,198 - tools.log - ERROR - invalid literal for int() with base 10: '['
2019-03-21 17:01:41,008 - tools.log - ERROR - module 'django.core.serializers.json' has no attribute 'loads'
2019-03-21 17:12:31,212 - tools.log - ERROR - the JSON object must be str, bytes or bytearray, not 'NoneType'
2019-03-21 17:22:26,309 - tools.log - ERROR - the JSON object must be str, bytes or bytearray, not 'NoneType'
2019-04-29 20:26:20,604 - django.request - ERROR - Internal Server Error: /get_case_apis/
Traceback (most recent call last):
  File "D:\Program Files\python\lib\site-packages\django\core\handlers\exception.py", line 34, in inner
    response = get_response(request)
  File "D:\Program Files\python\lib\site-packages\django\core\handlers\base.py", line 126, in _get_response
    response = self.process_exception_by_middleware(e, request)
  File "D:\Program Files\python\lib\site-packages\django\core\handlers\base.py", line 124, in _get_response
    response = wrapped_callback(request, *callback_args, **callback_kwargs)
  File "D:\Program Files\python\lib\site-packages\django\contrib\auth\decorators.py", line 21, in _wrapped_view
    return view_func(request, *args, **kwargs)
  File "D:\Program Files\IAM\api\views.py", line 760, in get_case_apis
    de['case_api_update_time'] = ca.case_update_time.strftime("%Y-%m-%d %H:%M:%S")
AttributeError: 'CaseApi' object has no attribute 'case_update_time'
2019-05-14 15:33:12,854 - django.request - ERROR - Internal Server Error: /get_project_apis
Traceback (most recent call last):
  File "D:\Program Files\python\lib\site-packages\django\core\handlers\exception.py", line 34, in inner
    response = get_response(request)
  File "D:\Program Files\python\lib\site-packages\django\core\handlers\base.py", line 126, in _get_response
    response = self.process_exception_by_middleware(e, request)
  File "D:\Program Files\python\lib\site-packages\django\core\handlers\base.py", line 124, in _get_response
    response = wrapped_callback(request, *callback_args, **callback_kwargs)
  File "D:\Program Files\python\lib\site-packages\django\contrib\auth\decorators.py", line 21, in _wrapped_view
    return view_func(request, *args, **kwargs)
  File "D:\Program Files\IAM\api\views.py", line 379, in get_project_apis
    de['api_update_time'] = api.api_update_time.strftime("%Y-%m-%d %H:%M:%S")
AttributeError: 'NoneType' object has no attribute 'strftime'
2019-05-14 18:23:58,012 - apscheduler.jobstores.default - ERROR - Unable to restore job "1549960771.4634013" -- removing it
Traceback (most recent call last):
  File "D:\Program Files\python\lib\site-packages\apscheduler\util.py", line 289, in ref_to_obj
    obj = getattr(obj, name)
AttributeError: module '__main__' has no attribute 'APS'

During handling of the above exception, another exception occurred:

Traceback (most recent call last):
  File "D:\Program Files\python\lib\site-packages\apscheduler\jobstores\sqlalchemy.py", line 141, in _get_jobs
    jobs.append(self._reconstitute_job(row.job_state))
  File "D:\Program Files\python\lib\site-packages\apscheduler\jobstores\sqlalchemy.py", line 128, in _reconstitute_job
    job.__setstate__(job_state)
  File "D:\Program Files\python\lib\site-packages\apscheduler\job.py", line 268, in __setstate__
    self.func = ref_to_obj(self.func_ref)
  File "D:\Program Files\python\lib\site-packages\apscheduler\util.py", line 292, in ref_to_obj
    raise LookupError('Error resolving reference %s: error looking up object' % ref)
LookupError: Error resolving reference __main__:APS.get_api_case_coverage: error looking up object
2019-05-21 11:50:00,599 - tools.log - ERROR - list indices must be integers or slices, not str
2019-05-21 11:51:22,850 - tools.log - ERROR - list indices must be integers or slices, not str
2019-05-21 12:03:31,682 - tools.log - ERROR - 'project-case-add-name'
2019-05-21 12:03:56,473 - tools.log - ERROR - 'project-case-add-name'
2019-05-21 12:06:48,656 - tools.log - ERROR - 'project-case-add-name'
2019-05-21 13:07:36,240 - tools.log - ERROR - 'project-case-add-name'
2019-05-21 13:54:20,068 - django.request - ERROR - Internal Server Error: /get_project_case
Traceback (most recent call last):
  File "D:\Program Files\python\lib\site-packages\django\core\handlers\exception.py", line 34, in inner
    response = get_response(request)
  File "D:\Program Files\python\lib\site-packages\django\core\handlers\base.py", line 126, in _get_response
    response = self.process_exception_by_middleware(e, request)
  File "D:\Program Files\python\lib\site-packages\django\core\handlers\base.py", line 124, in _get_response
    response = wrapped_callback(request, *callback_args, **callback_kwargs)
  File "D:\Program Files\python\lib\site-packages\django\contrib\auth\decorators.py", line 21, in _wrapped_view
    return view_func(request, *args, **kwargs)
  File "D:\Program Files\IAM\api\views.py", line 681, in get_project_case
    return JsonResponse(resultdict,safe=False)
  File "D:\Program Files\python\lib\site-packages\django\http\response.py", line 558, in __init__
    data = json.dumps(data, cls=encoder, **json_dumps_params)
  File "D:\Program Files\python\lib\json\__init__.py", line 238, in dumps
    **kw).encode(obj)
  File "D:\Program Files\python\lib\json\encoder.py", line 199, in encode
    chunks = self.iterencode(o, _one_shot=True)
  File "D:\Program Files\python\lib\json\encoder.py", line 257, in iterencode
    return _iterencode(o, 0)
  File "D:\Program Files\python\lib\site-packages\django\core\serializers\json.py", line 104, in default
    return super().default(o)
  File "D:\Program Files\python\lib\json\encoder.py", line 180, in default
    o.__class__.__name__)
TypeError: Object of type 'Case' is not JSON serializable
2019-05-22 13:55:31,575 - tools.log - ERROR - The database backend does not accept 0 as a value for AutoField.
2019-05-22 13:57:16,233 - tools.log - ERROR - The database backend does not accept 0 as a value for AutoField.
2019-05-22 13:59:11,810 - tools.log - ERROR - The database backend does not accept 0 as a value for AutoField.
2019-05-22 14:00:28,993 - tools.log - ERROR - The database backend does not accept 0 as a value for AutoField.
2019-05-22 14:02:22,385 - tools.log - ERROR - 'int' object has no attribute 'save'
2019-05-22 14:03:08,032 - tools.log - ERROR - 'int' object has no attribute 'id'
2019-05-22 20:43:07,629 - tools.log - ERROR - 'project-case-add-name'
2019-05-22 20:45:52,913 - tools.log - ERROR - 'project-case-add-name'
2019-05-22 20:48:39,666 - django.request - ERROR - Internal Server Error: /add_project_case_api
Traceback (most recent call last):
  File "D:\Program Files\python\lib\site-packages\django\core\handlers\exception.py", line 34, in inner
    response = get_response(request)
  File "D:\Program Files\python\lib\site-packages\django\utils\deprecation.py", line 90, in __call__
    response = self.process_request(request)
  File "D:\Program Files\python\lib\site-packages\django\middleware\common.py", line 53, in process_request
    path = self.get_full_path_with_slash(request)
  File "D:\Program Files\python\lib\site-packages\django\middleware\common.py", line 93, in get_full_path_with_slash
    'url': request.get_host() + new_path,
RuntimeError: You called this URL via POST, but the URL doesn't end in a slash and you have APPEND_SLASH set. Django can't redirect to the slash URL while maintaining POST data. Change your form to point to 127.0.0.1:8000/add_project_case_api/ (note the trailing slash), or set APPEND_SLASH=False in your Django settings.
2019-05-22 20:52:34,001 - tools.log - ERROR - unsupported operand type(s) for +: 'dict' and 'int'
2019-05-22 20:53:26,954 - tools.log - ERROR - 'dict' object has no attribute 'sort'
2019-05-23 14:25:48,212 - tools.log - ERROR - 
2019-05-23 14:28:52,720 - tools.log - ERROR - 
2019-05-23 14:31:17,298 - tools.log - ERROR - 
2019-05-23 14:31:40,822 - tools.log - ERROR - eval() arg 1 must be a string, bytes or code object
2019-06-05 12:59:25,383 - django.request - ERROR - Internal Server Error: /get_case_api_detail
Traceback (most recent call last):
  File "D:\Program Files\python\lib\site-packages\django\core\handlers\exception.py", line 34, in inner
    response = get_response(request)
  File "D:\Program Files\python\lib\site-packages\django\core\handlers\base.py", line 126, in _get_response
    response = self.process_exception_by_middleware(e, request)
  File "D:\Program Files\python\lib\site-packages\django\core\handlers\base.py", line 124, in _get_response
    response = wrapped_callback(request, *callback_args, **callback_kwargs)
  File "D:\Program Files\python\lib\site-packages\django\contrib\auth\decorators.py", line 21, in _wrapped_view
    return view_func(request, *args, **kwargs)
  File "D:\Program Files\python\lib\site-packages\django\views\decorators\http.py", line 40, in inner
    return func(request, *args, **kwargs)
  File "D:\Program Files\IAM\api\views.py", line 932, in get_case_api_detail
    case_api_info['api_headers'] = case_api['api_headers']
TypeError: 'QuerySet' object does not support item assignment
2019-06-05 13:01:42,053 - django.request - ERROR - Internal Server Error: /get_case_api_detail
Traceback (most recent call last):
  File "D:\Program Files\python\lib\site-packages\django\core\handlers\exception.py", line 34, in inner
    response = get_response(request)
  File "D:\Program Files\python\lib\site-packages\django\core\handlers\base.py", line 126, in _get_response
    response = self.process_exception_by_middleware(e, request)
  File "D:\Program Files\python\lib\site-packages\django\core\handlers\base.py", line 124, in _get_response
    response = wrapped_callback(request, *callback_args, **callback_kwargs)
  File "D:\Program Files\python\lib\site-packages\django\contrib\auth\decorators.py", line 21, in _wrapped_view
    return view_func(request, *args, **kwargs)
  File "D:\Program Files\python\lib\site-packages\django\views\decorators\http.py", line 40, in inner
    return func(request, *args, **kwargs)
  File "D:\Program Files\IAM\api\views.py", line 933, in get_case_api_detail
    case_api_info['api_headers'] = case_api['api_headers']
TypeError: 'QuerySet' object does not support item assignment
2019-06-05 13:03:23,063 - django.request - ERROR - Internal Server Error: /get_case_api_detail
Traceback (most recent call last):
  File "D:\Program Files\python\lib\site-packages\django\core\handlers\exception.py", line 34, in inner
    response = get_response(request)
  File "D:\Program Files\python\lib\site-packages\django\core\handlers\base.py", line 126, in _get_response
    response = self.process_exception_by_middleware(e, request)
  File "D:\Program Files\python\lib\site-packages\django\core\handlers\base.py", line 124, in _get_response
    response = wrapped_callback(request, *callback_args, **callback_kwargs)
  File "D:\Program Files\python\lib\site-packages\django\contrib\auth\decorators.py", line 21, in _wrapped_view
    return view_func(request, *args, **kwargs)
  File "D:\Program Files\python\lib\site-packages\django\views\decorators\http.py", line 40, in inner
    return func(request, *args, **kwargs)
  File "D:\Program Files\IAM\api\views.py", line 932, in get_case_api_detail
    print(case_api.api_headers)
AttributeError: 'dict' object has no attribute 'api_headers'
2019-06-05 13:03:49,216 - django.request - ERROR - Internal Server Error: /get_case_api_detail
Traceback (most recent call last):
  File "D:\Program Files\python\lib\site-packages\django\core\handlers\exception.py", line 34, in inner
    response = get_response(request)
  File "D:\Program Files\python\lib\site-packages\django\core\handlers\base.py", line 126, in _get_response
    response = self.process_exception_by_middleware(e, request)
  File "D:\Program Files\python\lib\site-packages\django\core\handlers\base.py", line 124, in _get_response
    response = wrapped_callback(request, *callback_args, **callback_kwargs)
  File "D:\Program Files\python\lib\site-packages\django\contrib\auth\decorators.py", line 21, in _wrapped_view
    return view_func(request, *args, **kwargs)
  File "D:\Program Files\python\lib\site-packages\django\views\decorators\http.py", line 40, in inner
    return func(request, *args, **kwargs)
  File "D:\Program Files\IAM\api\views.py", line 933, in get_case_api_detail
    case_api_info['api_headers'] = case_api['api_headers']
TypeError: 'QuerySet' object does not support item assignment
2019-06-05 13:04:36,479 - django.request - ERROR - Internal Server Error: /get_case_api_detail
Traceback (most recent call last):
  File "D:\Program Files\python\lib\site-packages\django\core\handlers\exception.py", line 34, in inner
    response = get_response(request)
  File "D:\Program Files\python\lib\site-packages\django\core\handlers\base.py", line 126, in _get_response
    response = self.process_exception_by_middleware(e, request)
  File "D:\Program Files\python\lib\site-packages\django\core\handlers\base.py", line 124, in _get_response
    response = wrapped_callback(request, *callback_args, **callback_kwargs)
  File "D:\Program Files\python\lib\site-packages\django\contrib\auth\decorators.py", line 21, in _wrapped_view
    return view_func(request, *args, **kwargs)
  File "D:\Program Files\python\lib\site-packages\django\views\decorators\http.py", line 40, in inner
    return func(request, *args, **kwargs)
  File "D:\Program Files\IAM\api\views.py", line 933, in get_case_api_detail
    case_api_info['api_headers'] = case_api['api_headers']
TypeError: 'QuerySet' object does not support item assignment
2019-06-05 13:05:25,685 - django.request - ERROR - Internal Server Error: /get_case_api_detail
Traceback (most recent call last):
  File "D:\Program Files\python\lib\site-packages\django\core\handlers\exception.py", line 34, in inner
    response = get_response(request)
  File "D:\Program Files\python\lib\site-packages\django\core\handlers\base.py", line 126, in _get_response
    response = self.process_exception_by_middleware(e, request)
  File "D:\Program Files\python\lib\site-packages\django\core\handlers\base.py", line 124, in _get_response
    response = wrapped_callback(request, *callback_args, **callback_kwargs)
  File "D:\Program Files\python\lib\site-packages\django\contrib\auth\decorators.py", line 21, in _wrapped_view
    return view_func(request, *args, **kwargs)
  File "D:\Program Files\python\lib\site-packages\django\views\decorators\http.py", line 40, in inner
    return func(request, *args, **kwargs)
  File "D:\Program Files\IAM\api\views.py", line 943, in get_case_api_detail
    return JsonResponse(resultdict, safe=False)
  File "D:\Program Files\python\lib\site-packages\django\http\response.py", line 558, in __init__
    data = json.dumps(data, cls=encoder, **json_dumps_params)
  File "D:\Program Files\python\lib\json\__init__.py", line 238, in dumps
    **kw).encode(obj)
  File "D:\Program Files\python\lib\json\encoder.py", line 199, in encode
    chunks = self.iterencode(o, _one_shot=True)
  File "D:\Program Files\python\lib\json\encoder.py", line 257, in iterencode
    return _iterencode(o, 0)
  File "D:\Program Files\python\lib\site-packages\django\core\serializers\json.py", line 104, in default
    return super().default(o)
  File "D:\Program Files\python\lib\json\encoder.py", line 180, in default
    o.__class__.__name__)
TypeError: Object of type 'QuerySet' is not JSON serializable
2019-06-05 13:06:46,750 - django.request - ERROR - Internal Server Error: /get_case_api_detail
Traceback (most recent call last):
  File "D:\Program Files\python\lib\site-packages\django\core\handlers\exception.py", line 34, in inner
    response = get_response(request)
  File "D:\Program Files\python\lib\site-packages\django\core\handlers\base.py", line 126, in _get_response
    response = self.process_exception_by_middleware(e, request)
  File "D:\Program Files\python\lib\site-packages\django\core\handlers\base.py", line 124, in _get_response
    response = wrapped_callback(request, *callback_args, **callback_kwargs)
  File "D:\Program Files\python\lib\site-packages\django\contrib\auth\decorators.py", line 21, in _wrapped_view
    return view_func(request, *args, **kwargs)
  File "D:\Program Files\python\lib\site-packages\django\views\decorators\http.py", line 40, in inner
    return func(request, *args, **kwargs)
  File "D:\Program Files\IAM\api\views.py", line 943, in get_case_api_detail
    return JsonResponse(resultdict, safe=False)
  File "D:\Program Files\python\lib\site-packages\django\http\response.py", line 558, in __init__
    data = json.dumps(data, cls=encoder, **json_dumps_params)
  File "D:\Program Files\python\lib\json\__init__.py", line 238, in dumps
    **kw).encode(obj)
  File "D:\Program Files\python\lib\json\encoder.py", line 199, in encode
    chunks = self.iterencode(o, _one_shot=True)
  File "D:\Program Files\python\lib\json\encoder.py", line 257, in iterencode
    return _iterencode(o, 0)
  File "D:\Program Files\python\lib\site-packages\django\core\serializers\json.py", line 104, in default
    return super().default(o)
  File "D:\Program Files\python\lib\json\encoder.py", line 180, in default
    o.__class__.__name__)
TypeError: Object of type 'QuerySet' is not JSON serializable
2019-06-05 13:07:28,868 - django.request - ERROR - Internal Server Error: /get_case_api_detail
Traceback (most recent call last):
  File "D:\Program Files\python\lib\site-packages\django\core\handlers\exception.py", line 34, in inner
    response = get_response(request)
  File "D:\Program Files\python\lib\site-packages\django\core\handlers\base.py", line 126, in _get_response
    response = self.process_exception_by_middleware(e, request)
  File "D:\Program Files\python\lib\site-packages\django\core\handlers\base.py", line 124, in _get_response
    response = wrapped_callback(request, *callback_args, **callback_kwargs)
  File "D:\Program Files\python\lib\site-packages\django\contrib\auth\decorators.py", line 21, in _wrapped_view
    return view_func(request, *args, **kwargs)
  File "D:\Program Files\python\lib\site-packages\django\views\decorators\http.py", line 40, in inner
    return func(request, *args, **kwargs)
  File "D:\Program Files\IAM\api\views.py", line 943, in get_case_api_detail
    return JsonResponse(resultdict, safe=False)
  File "D:\Program Files\python\lib\site-packages\django\http\response.py", line 558, in __init__
    data = json.dumps(data, cls=encoder, **json_dumps_params)
  File "D:\Program Files\python\lib\json\__init__.py", line 238, in dumps
    **kw).encode(obj)
  File "D:\Program Files\python\lib\json\encoder.py", line 199, in encode
    chunks = self.iterencode(o, _one_shot=True)
  File "D:\Program Files\python\lib\json\encoder.py", line 257, in iterencode
    return _iterencode(o, 0)
  File "D:\Program Files\python\lib\site-packages\django\core\serializers\json.py", line 104, in default
    return super().default(o)
  File "D:\Program Files\python\lib\json\encoder.py", line 180, in default
    o.__class__.__name__)
TypeError: Object of type 'QuerySet' is not JSON serializable
2019-06-05 13:09:16,694 - django.request - ERROR - Internal Server Error: /get_case_api_detail
Traceback (most recent call last):
  File "D:\Program Files\python\lib\site-packages\django\core\handlers\exception.py", line 34, in inner
    response = get_response(request)
  File "D:\Program Files\python\lib\site-packages\django\core\handlers\base.py", line 126, in _get_response
    response = self.process_exception_by_middleware(e, request)
  File "D:\Program Files\python\lib\site-packages\django\core\handlers\base.py", line 124, in _get_response
    response = wrapped_callback(request, *callback_args, **callback_kwargs)
  File "D:\Program Files\python\lib\site-packages\django\contrib\auth\decorators.py", line 21, in _wrapped_view
    return view_func(request, *args, **kwargs)
  File "D:\Program Files\python\lib\site-packages\django\views\decorators\http.py", line 40, in inner
    return func(request, *args, **kwargs)
  File "D:\Program Files\IAM\api\views.py", line 935, in get_case_api_detail
    data['pre_steps'] = eval(pre_steps)
TypeError: eval() arg 1 must be a string, bytes or code object
2019-06-06 19:32:24,558 - tools.log - ERROR - 'project-case-add-name'
2019-06-17 14:07:48,352 - tools.log - ERROR - 'project-case-add-name'
2019-06-18 19:43:32,272 - tools.log - ERROR - The database backend does not accept 0 as a value for AutoField.
2019-06-18 19:54:55,492 - tools.log - ERROR - Cannot assign "0": "Step.CaseApi" must be a "CaseApi" instance.
2019-06-18 19:59:31,754 - tools.log - ERROR - CaseApi matching query does not exist.
2019-06-18 20:01:34,606 - tools.log - ERROR - The database backend does not accept 0 as a value for AutoField.
2019-06-19 10:06:39,984 - tools.log - ERROR - The database backend does not accept 0 as a value for AutoField.
2019-06-19 10:30:12,531 - tools.log - ERROR - invalid literal for int() with base 10: 'SQL'
2019-06-19 11:50:05,925 - django.request - ERROR - Internal Server Error: /get_case_api_detail
Traceback (most recent call last):
  File "D:\Program Files\python\lib\site-packages\django\core\handlers\exception.py", line 34, in inner
    response = get_response(request)
  File "D:\Program Files\python\lib\site-packages\django\core\handlers\base.py", line 126, in _get_response
    response = self.process_exception_by_middleware(e, request)
  File "D:\Program Files\python\lib\site-packages\django\core\handlers\base.py", line 124, in _get_response
    response = wrapped_callback(request, *callback_args, **callback_kwargs)
  File "D:\Program Files\python\lib\site-packages\django\contrib\auth\decorators.py", line 21, in _wrapped_view
    return view_func(request, *args, **kwargs)
  File "D:\Program Files\python\lib\site-packages\django\views\decorators\http.py", line 40, in inner
    return func(request, *args, **kwargs)
  File "D:\Program Files\IAM\api\views.py", line 954, in get_case_api_detail
    data['assertion'] = assertion.step_content
AttributeError: 'QuerySet' object has no attribute 'step_content'
2019-06-19 11:51:01,468 - django.request - ERROR - Internal Server Error: /get_case_api_detail
Traceback (most recent call last):
  File "D:\Program Files\python\lib\site-packages\django\core\handlers\exception.py", line 34, in inner
    response = get_response(request)
  File "D:\Program Files\python\lib\site-packages\django\core\handlers\base.py", line 126, in _get_response
    response = self.process_exception_by_middleware(e, request)
  File "D:\Program Files\python\lib\site-packages\django\core\handlers\base.py", line 124, in _get_response
    response = wrapped_callback(request, *callback_args, **callback_kwargs)
  File "D:\Program Files\python\lib\site-packages\django\contrib\auth\decorators.py", line 21, in _wrapped_view
    return view_func(request, *args, **kwargs)
  File "D:\Program Files\python\lib\site-packages\django\views\decorators\http.py", line 40, in inner
    return func(request, *args, **kwargs)
  File "D:\Program Files\IAM\api\views.py", line 954, in get_case_api_detail
    data['assertion'] = assertion['step_content']
  File "D:\Program Files\python\lib\site-packages\django\db\models\query.py", line 278, in __getitem__
    raise TypeError
TypeError
2019-06-19 11:55:06,982 - django.request - ERROR - Internal Server Error: /get_case_api_detail
Traceback (most recent call last):
  File "D:\Program Files\python\lib\site-packages\django\core\handlers\exception.py", line 34, in inner
    response = get_response(request)
  File "D:\Program Files\python\lib\site-packages\django\core\handlers\base.py", line 126, in _get_response
    response = self.process_exception_by_middleware(e, request)
  File "D:\Program Files\python\lib\site-packages\django\core\handlers\base.py", line 124, in _get_response
    response = wrapped_callback(request, *callback_args, **callback_kwargs)
  File "D:\Program Files\python\lib\site-packages\django\contrib\auth\decorators.py", line 21, in _wrapped_view
    return view_func(request, *args, **kwargs)
  File "D:\Program Files\python\lib\site-packages\django\views\decorators\http.py", line 40, in inner
    return func(request, *args, **kwargs)
  File "D:\Program Files\IAM\api\views.py", line 952, in get_case_api_detail
    data['pre_steps'] = eval(pre_steps)
TypeError: eval() arg 1 must be a string, bytes or code object
2019-06-19 11:55:41,734 - django.request - ERROR - Internal Server Error: /get_case_api_detail
Traceback (most recent call last):
  File "D:\Program Files\python\lib\site-packages\django\core\handlers\exception.py", line 34, in inner
    response = get_response(request)
  File "D:\Program Files\python\lib\site-packages\django\core\handlers\base.py", line 126, in _get_response
    response = self.process_exception_by_middleware(e, request)
  File "D:\Program Files\python\lib\site-packages\django\core\handlers\base.py", line 124, in _get_response
    response = wrapped_callback(request, *callback_args, **callback_kwargs)
  File "D:\Program Files\python\lib\site-packages\django\contrib\auth\decorators.py", line 21, in _wrapped_view
    return view_func(request, *args, **kwargs)
  File "D:\Program Files\python\lib\site-packages\django\views\decorators\http.py", line 40, in inner
    return func(request, *args, **kwargs)
  File "D:\Program Files\IAM\api\views.py", line 952, in get_case_api_detail
    data['pre_steps'] = json.loads(pre_steps)
  File "D:\Program Files\python\lib\json\__init__.py", line 348, in loads
    'not {!r}'.format(s.__class__.__name__))
TypeError: the JSON object must be str, bytes or bytearray, not 'QuerySet'
2019-06-19 11:58:03,522 - django.request - ERROR - Internal Server Error: /get_case_api_detail
Traceback (most recent call last):
  File "D:\Program Files\python\lib\site-packages\django\core\handlers\exception.py", line 34, in inner
    response = get_response(request)
  File "D:\Program Files\python\lib\site-packages\django\core\handlers\base.py", line 126, in _get_response
    response = self.process_exception_by_middleware(e, request)
  File "D:\Program Files\python\lib\site-packages\django\core\handlers\base.py", line 124, in _get_response
    response = wrapped_callback(request, *callback_args, **callback_kwargs)
  File "D:\Program Files\python\lib\site-packages\django\contrib\auth\decorators.py", line 21, in _wrapped_view
    return view_func(request, *args, **kwargs)
  File "D:\Program Files\python\lib\site-packages\django\views\decorators\http.py", line 40, in inner
    return func(request, *args, **kwargs)
  File "D:\Program Files\IAM\api\views.py", line 944, in get_case_api_detail
    assertion = Step.objects.filter(CaseApi_id=caid,step_type='Assertion').values().first().all()
AttributeError: 'dict' object has no attribute 'all'
2019-06-19 11:58:20,688 - django.request - ERROR - Internal Server Error: /get_case_api_detail
Traceback (most recent call last):
  File "D:\Program Files\python\lib\site-packages\django\core\handlers\exception.py", line 34, in inner
    response = get_response(request)
  File "D:\Program Files\python\lib\site-packages\django\core\handlers\base.py", line 126, in _get_response
    response = self.process_exception_by_middleware(e, request)
  File "D:\Program Files\python\lib\site-packages\django\core\handlers\base.py", line 124, in _get_response
    response = wrapped_callback(request, *callback_args, **callback_kwargs)
  File "D:\Program Files\python\lib\site-packages\django\contrib\auth\decorators.py", line 21, in _wrapped_view
    return view_func(request, *args, **kwargs)
  File "D:\Program Files\python\lib\site-packages\django\views\decorators\http.py", line 40, in inner
    return func(request, *args, **kwargs)
  File "D:\Program Files\IAM\api\views.py", line 952, in get_case_api_detail
    data['pre_steps'] = json.loads(pre_steps)
  File "D:\Program Files\python\lib\json\__init__.py", line 348, in loads
    'not {!r}'.format(s.__class__.__name__))
TypeError: the JSON object must be str, bytes or bytearray, not 'QuerySet'
2019-06-19 12:00:03,670 - django.request - ERROR - Internal Server Error: /get_case_api_detail
Traceback (most recent call last):
  File "D:\Program Files\python\lib\site-packages\django\core\handlers\exception.py", line 34, in inner
    response = get_response(request)
  File "D:\Program Files\python\lib\site-packages\django\core\handlers\base.py", line 126, in _get_response
    response = self.process_exception_by_middleware(e, request)
  File "D:\Program Files\python\lib\site-packages\django\core\handlers\base.py", line 124, in _get_response
    response = wrapped_callback(request, *callback_args, **callback_kwargs)
  File "D:\Program Files\python\lib\site-packages\django\contrib\auth\decorators.py", line 21, in _wrapped_view
    return view_func(request, *args, **kwargs)
  File "D:\Program Files\python\lib\site-packages\django\views\decorators\http.py", line 40, in inner
    return func(request, *args, **kwargs)
  File "D:\Program Files\IAM\api\views.py", line 952, in get_case_api_detail
    data['pre_steps'] = json.loads(list(pre_steps))
  File "D:\Program Files\python\lib\json\__init__.py", line 348, in loads
    'not {!r}'.format(s.__class__.__name__))
TypeError: the JSON object must be str, bytes or bytearray, not 'list'
2019-06-19 12:00:20,486 - django.request - ERROR - Internal Server Error: /get_case_api_detail
Traceback (most recent call last):
  File "D:\Program Files\python\lib\site-packages\django\core\handlers\exception.py", line 34, in inner
    response = get_response(request)
  File "D:\Program Files\python\lib\site-packages\django\core\handlers\base.py", line 126, in _get_response
    response = self.process_exception_by_middleware(e, request)
  File "D:\Program Files\python\lib\site-packages\django\core\handlers\base.py", line 124, in _get_response
    response = wrapped_callback(request, *callback_args, **callback_kwargs)
  File "D:\Program Files\python\lib\site-packages\django\contrib\auth\decorators.py", line 21, in _wrapped_view
    return view_func(request, *args, **kwargs)
  File "D:\Program Files\python\lib\site-packages\django\views\decorators\http.py", line 40, in inner
    return func(request, *args, **kwargs)
  File "D:\Program Files\IAM\api\views.py", line 952, in get_case_api_detail
    data['pre_steps'] = json.dumps(list(pre_steps))
  File "D:\Program Files\python\lib\json\__init__.py", line 231, in dumps
    return _default_encoder.encode(obj)
  File "D:\Program Files\python\lib\json\encoder.py", line 199, in encode
    chunks = self.iterencode(o, _one_shot=True)
  File "D:\Program Files\python\lib\json\encoder.py", line 257, in iterencode
    return _iterencode(o, 0)
  File "D:\Program Files\python\lib\json\encoder.py", line 180, in default
    o.__class__.__name__)
TypeError: Object of type 'datetime' is not JSON serializable
2019-06-19 12:00:34,142 - django.request - ERROR - Internal Server Error: /get_case_api_detail
Traceback (most recent call last):
  File "D:\Program Files\python\lib\site-packages\django\core\handlers\exception.py", line 34, in inner
    response = get_response(request)
  File "D:\Program Files\python\lib\site-packages\django\core\handlers\base.py", line 126, in _get_response
    response = self.process_exception_by_middleware(e, request)
  File "D:\Program Files\python\lib\site-packages\django\core\handlers\base.py", line 124, in _get_response
    response = wrapped_callback(request, *callback_args, **callback_kwargs)
  File "D:\Program Files\python\lib\site-packages\django\contrib\auth\decorators.py", line 21, in _wrapped_view
    return view_func(request, *args, **kwargs)
  File "D:\Program Files\python\lib\site-packages\django\views\decorators\http.py", line 40, in inner
    return func(request, *args, **kwargs)
  File "D:\Program Files\IAM\api\views.py", line 952, in get_case_api_detail
    data['pre_steps'] = json.loads(list(pre_steps))
  File "D:\Program Files\python\lib\json\__init__.py", line 348, in loads
    'not {!r}'.format(s.__class__.__name__))
TypeError: the JSON object must be str, bytes or bytearray, not 'list'
2019-06-19 12:00:43,299 - django.request - ERROR - Internal Server Error: /get_case_api_detail
Traceback (most recent call last):
  File "D:\Program Files\python\lib\site-packages\django\core\handlers\exception.py", line 34, in inner
    response = get_response(request)
  File "D:\Program Files\python\lib\site-packages\django\core\handlers\base.py", line 126, in _get_response
    response = self.process_exception_by_middleware(e, request)
  File "D:\Program Files\python\lib\site-packages\django\core\handlers\base.py", line 124, in _get_response
    response = wrapped_callback(request, *callback_args, **callback_kwargs)
  File "D:\Program Files\python\lib\site-packages\django\contrib\auth\decorators.py", line 21, in _wrapped_view
    return view_func(request, *args, **kwargs)
  File "D:\Program Files\python\lib\site-packages\django\views\decorators\http.py", line 40, in inner
    return func(request, *args, **kwargs)
  File "D:\Program Files\IAM\api\views.py", line 952, in get_case_api_detail
    data['pre_steps'] = eval(list(pre_steps))
TypeError: eval() arg 1 must be a string, bytes or code object
2019-06-19 14:32:33,172 - django.request - ERROR - Internal Server Error: /get_case_api_detail
Traceback (most recent call last):
  File "D:\Program Files\python\lib\site-packages\django\core\handlers\exception.py", line 34, in inner
    response = get_response(request)
  File "D:\Program Files\python\lib\site-packages\django\core\handlers\base.py", line 126, in _get_response
    response = self.process_exception_by_middleware(e, request)
  File "D:\Program Files\python\lib\site-packages\django\core\handlers\base.py", line 124, in _get_response
    response = wrapped_callback(request, *callback_args, **callback_kwargs)
  File "D:\Program Files\python\lib\site-packages\django\contrib\auth\decorators.py", line 21, in _wrapped_view
    return view_func(request, *args, **kwargs)
  File "D:\Program Files\python\lib\site-packages\django\views\decorators\http.py", line 40, in inner
    return func(request, *args, **kwargs)
  File "D:\Program Files\IAM\api\views.py", line 952, in get_case_api_detail
    data['pre_steps'] = json.loads(str(pre_steps))
  File "D:\Program Files\python\lib\json\__init__.py", line 354, in loads
    return _default_decoder.decode(s)
  File "D:\Program Files\python\lib\json\decoder.py", line 339, in decode
    obj, end = self.raw_decode(s, idx=_w(s, 0).end())
  File "D:\Program Files\python\lib\json\decoder.py", line 357, in raw_decode
    raise JSONDecodeError("Expecting value", s, err.value) from None
json.decoder.JSONDecodeError: Expecting value: line 1 column 1 (char 0)
2019-06-19 14:34:35,810 - django.request - ERROR - Internal Server Error: /get_case_api_detail
Traceback (most recent call last):
  File "D:\Program Files\python\lib\site-packages\django\core\handlers\exception.py", line 34, in inner
    response = get_response(request)
  File "D:\Program Files\python\lib\site-packages\django\core\handlers\base.py", line 126, in _get_response
    response = self.process_exception_by_middleware(e, request)
  File "D:\Program Files\python\lib\site-packages\django\core\handlers\base.py", line 124, in _get_response
    response = wrapped_callback(request, *callback_args, **callback_kwargs)
  File "D:\Program Files\python\lib\site-packages\django\contrib\auth\decorators.py", line 21, in _wrapped_view
    return view_func(request, *args, **kwargs)
  File "D:\Program Files\python\lib\site-packages\django\views\decorators\http.py", line 40, in inner
    return func(request, *args, **kwargs)
  File "D:\Program Files\IAM\api\views.py", line 952, in get_case_api_detail
    data['pre_steps'] = eval(str(pre_steps))
  File "<string>", line 1
    <QuerySet [{'id': 1, 'CaseApi_id': 19, 'step_type': 'SQL', 'step_sort': 1, 'step_content': '{\'pre_sqlenv\': \'${qapmfmysql}\', \'pre_content\': \'select username from user where mobile="15921720233"\', \'pre_variable\': \'username\'}', 'step_create_time': datetime.datetime(2019, 6, 19, 11, 31, 37), 'step_update_time': None}]>
    ^
SyntaxError: invalid syntax
