2019-01-31 14:54:42,585 - django.request - WARNING - Not Found: /search_project_cases
2019-01-31 14:54:45,472 - django.request - WARNING - Not Found: /search_project_cases
2019-01-31 14:58:45,188 - django.request - WARNING - Not Found: /get_project_case
2019-01-31 14:58:46,491 - django.request - WARNING - Not Found: /get_project_case
2019-01-31 14:58:46,944 - django.request - WARNING - Not Found: /get_project_case
2019-01-31 14:59:05,843 - django.request - WARNING - Not Found: /demo/project_task
2019-02-11 15:59:30,167 - django.request - WARNING - Not Found: /favicon.ico
2019-02-11 16:06:16,185 - django.request - WARNING - Not Found: /demo/project_task
2019-02-11 16:06:39,189 - django.request - WARNING - Not Found: /search_project_cases
2019-02-11 16:06:41,210 - django.request - WARNING - Not Found: /search_project_cases
2019-02-11 16:06:42,401 - django.request - WARNING - Not Found: /search_project_cases
2019-02-11 16:06:45,707 - django.request - WARNING - Not Found: /search_project_cases
2019-02-11 16:06:46,754 - django.request - WARNING - Not Found: /search_project_cases
2019-02-11 16:06:47,346 - django.request - WARNING - Not Found: /search_project_cases
2019-02-11 16:06:47,538 - django.request - WARNING - Not Found: /search_project_cases
2019-02-11 17:46:58,938 - django.request - WARNING - Not Found: /search_project_cases
2019-02-11 18:37:26,867 - django.request - WARNING - Not Found: /favicon.ico
2019-02-11 18:57:34,342 - django.request - WARNING - Not Found: /search_project_cases
2019-02-11 18:58:34,064 - django.request - WARNING - Not Found: /search_project_cases
2019-02-11 19:11:42,448 - django.request - WARNING - Not Found: /search_project_cases
2019-02-11 19:11:46,768 - django.request - WARNING - Not Found: /search_project_cases
2019-02-11 19:12:58,706 - django.request - WARNING - Not Found: /favicon.ico
2019-02-11 19:13:13,450 - django.request - WARNING - Not Found: /favicon.ico
2019-02-12 11:00:06,779 - django.request - WARNING - Not Found: /favicon.ico
2019-02-12 11:00:18,087 - django.request - WARNING - Not Found: /favicon.ico
2019-02-12 11:00:34,034 - django.request - WARNING - Not Found: /favicon.ico
2019-02-12 11:33:44,883 - django.request - WARNING - Not Found: /favicon.ico
2019-02-12 11:46:03,857 - django.request - WARNING - Not Found: /favicon.ico
2019-02-12 11:48:24,593 - django.request - WARNING - Not Found: /favicon.ico
2019-02-12 11:48:35,735 - django.request - WARNING - Not Found: /favicon.ico
2019-02-12 11:49:24,144 - django.request - WARNING - Not Found: /favicon.ico
2019-02-12 11:49:42,358 - django.request - WARNING - Not Found: /favicon.ico
2019-02-12 11:55:12,726 - django.request - WARNING - Not Found: /favicon.ico
2019-02-12 13:37:44,251 - django.request - WARNING - Not Found: /favicon.ico
2019-02-12 14:05:18,213 - django.request - WARNING - Not Found: /favicon.ico
2019-02-12 16:39:31,508 - apscheduler.scheduler - INFO - Adding job tentatively -- it will be properly scheduled when the scheduler starts
2019-02-12 16:39:31,626 - apscheduler.scheduler - INFO - Added job "APS.get_api_case_coverage" to job store "default"
2019-02-12 16:39:31,626 - apscheduler.scheduler - INFO - Scheduler started
2019-02-12 16:39:31,627 - tools.log - ERROR - 任务开始！！！
2019-02-12 16:39:41,677 - apscheduler.executors.default - INFO - Running job "APS.get_api_case_coverage (trigger: interval[0:00:10], next run at: 2019-02-12 16:39:41 CST)" (scheduled at 2019-02-12 16:39:41.507906+08:00)
2019-02-12 16:39:41,736 - tools.log - INFO - 'dict' object has no attribute 'api_path'
2019-02-12 16:39:41,761 - tools.log - INFO - 'dict' object has no attribute 'api_path'
2019-02-12 16:39:41,771 - tools.log - INFO - 'dict' object has no attribute 'api_path'
2019-02-12 16:39:41,792 - tools.log - INFO - 'dict' object has no attribute 'api_path'
2019-02-12 16:39:41,817 - tools.log - INFO - 'dict' object has no attribute 'api_path'
2019-02-12 16:39:41,822 - tools.log - INFO - 'dict' object has no attribute 'api_path'
2019-02-12 16:39:41,827 - tools.log - INFO - 'dict' object has no attribute 'api_path'
2019-02-12 16:39:41,862 - tools.log - INFO - 'dict' object has no attribute 'api_path'
2019-02-12 16:39:41,892 - tools.log - INFO - 'dict' object has no attribute 'api_path'
2019-02-12 16:39:41,902 - tools.log - INFO - 'dict' object has no attribute 'api_path'
2019-02-12 16:39:41,917 - tools.log - INFO - 'dict' object has no attribute 'api_path'
2019-02-12 16:39:41,917 - tools.log - INFO - 'dict' object has no attribute 'api_path'
2019-02-12 16:39:41,922 - tools.log - INFO - 'dict' object has no attribute 'api_path'
2019-02-12 16:39:41,947 - apscheduler.executors.default - INFO - Job "APS.get_api_case_coverage (trigger: interval[0:00:10], next run at: 2019-02-12 16:39:51 CST)" executed successfully
2019-02-12 16:39:51,825 - apscheduler.executors.default - INFO - Running job "APS.get_api_case_coverage (trigger: interval[0:00:10], next run at: 2019-02-12 16:40:01 CST)" (scheduled at 2019-02-12 16:39:51.507906+08:00)
2019-02-12 16:39:51,958 - tools.log - INFO - 'dict' object has no attribute 'api_path'
2019-02-12 16:39:51,963 - tools.log - INFO - 'dict' object has no attribute 'api_path'
2019-02-12 16:39:51,968 - tools.log - INFO - 'dict' object has no attribute 'api_path'
2019-02-12 16:39:51,968 - tools.log - INFO - 'dict' object has no attribute 'api_path'
2019-02-12 16:39:51,968 - tools.log - INFO - 'dict' object has no attribute 'api_path'
2019-02-12 16:39:51,969 - tools.log - INFO - 'dict' object has no attribute 'api_path'
2019-02-12 16:39:51,984 - tools.log - INFO - 'dict' object has no attribute 'api_path'
2019-02-12 16:39:52,004 - tools.log - INFO - 'dict' object has no attribute 'api_path'
2019-02-12 16:39:52,024 - tools.log - INFO - 'dict' object has no attribute 'api_path'
2019-02-12 16:39:52,039 - tools.log - INFO - 'dict' object has no attribute 'api_path'
2019-02-12 16:39:52,064 - tools.log - INFO - 'dict' object has no attribute 'api_path'
2019-02-12 16:39:52,079 - tools.log - INFO - 'dict' object has no attribute 'api_path'
2019-02-12 16:39:52,094 - tools.log - INFO - 'dict' object has no attribute 'api_path'
2019-02-12 16:39:52,124 - apscheduler.executors.default - INFO - Job "APS.get_api_case_coverage (trigger: interval[0:00:10], next run at: 2019-02-12 16:40:01 CST)" executed successfully
2019-02-12 16:40:01,818 - apscheduler.executors.default - INFO - Running job "APS.get_api_case_coverage (trigger: interval[0:00:10], next run at: 2019-02-12 16:40:11 CST)" (scheduled at 2019-02-12 16:40:01.507906+08:00)
2019-02-12 16:40:02,033 - tools.log - INFO - 'dict' object has no attribute 'api_path'
2019-02-12 16:40:02,058 - tools.log - INFO - 'dict' object has no attribute 'api_path'
2019-02-12 16:40:02,078 - tools.log - INFO - 'dict' object has no attribute 'api_path'
2019-02-12 16:40:02,088 - tools.log - INFO - 'dict' object has no attribute 'api_path'
2019-02-12 16:40:02,093 - tools.log - INFO - 'dict' object has no attribute 'api_path'
2019-02-12 16:40:02,108 - tools.log - INFO - 'dict' object has no attribute 'api_path'
2019-02-12 16:40:02,133 - tools.log - INFO - 'dict' object has no attribute 'api_path'
2019-02-12 16:40:02,153 - tools.log - INFO - 'dict' object has no attribute 'api_path'
2019-02-12 16:40:02,173 - tools.log - INFO - 'dict' object has no attribute 'api_path'
2019-02-12 16:40:02,193 - tools.log - INFO - 'dict' object has no attribute 'api_path'
2019-02-12 16:40:02,203 - tools.log - INFO - 'dict' object has no attribute 'api_path'
2019-02-12 16:40:02,204 - tools.log - INFO - 'dict' object has no attribute 'api_path'
2019-02-12 16:40:02,204 - tools.log - INFO - 'dict' object has no attribute 'api_path'
2019-02-12 16:40:02,224 - apscheduler.executors.default - INFO - Job "APS.get_api_case_coverage (trigger: interval[0:00:10], next run at: 2019-02-12 16:40:11 CST)" executed successfully
2019-02-12 16:40:47,404 - apscheduler.scheduler - INFO - Scheduler started
2019-02-12 16:40:47,405 - tools.log - ERROR - 任务开始！！！
2019-02-12 16:40:47,467 - apscheduler.executors.default - WARNING - Run time of job "APS.get_api_case_coverage (trigger: interval[0:00:10], next run at: 2019-02-12 16:40:51 CST)" was missed by 0:00:05.959146
2019-02-12 16:40:51,780 - apscheduler.executors.default - INFO - Running job "APS.get_api_case_coverage (trigger: interval[0:00:10], next run at: 2019-02-12 16:41:01 CST)" (scheduled at 2019-02-12 16:40:51.507906+08:00)
2019-02-12 16:40:51,868 - tools.log - INFO - 'dict' object has no attribute 'api_path'
2019-02-12 16:40:51,893 - tools.log - INFO - 'dict' object has no attribute 'api_path'
2019-02-12 16:40:51,939 - tools.log - INFO - 'dict' object has no attribute 'api_path'
2019-02-12 16:40:51,974 - tools.log - INFO - 'dict' object has no attribute 'api_path'
2019-02-12 16:40:51,989 - tools.log - INFO - 'dict' object has no attribute 'api_path'
2019-02-12 16:40:52,004 - tools.log - INFO - 'dict' object has no attribute 'api_path'
2019-02-12 16:40:52,014 - tools.log - INFO - 'dict' object has no attribute 'api_path'
2019-02-12 16:40:52,029 - tools.log - INFO - 'dict' object has no attribute 'api_path'
2019-02-12 16:40:52,034 - tools.log - INFO - 'dict' object has no attribute 'api_path'
2019-02-12 16:40:52,039 - tools.log - INFO - 'dict' object has no attribute 'api_path'
2019-02-12 16:40:52,059 - tools.log - INFO - 'dict' object has no attribute 'api_path'
2019-02-12 16:40:52,074 - tools.log - INFO - 'dict' object has no attribute 'api_path'
2019-02-12 16:40:52,094 - tools.log - INFO - 'dict' object has no attribute 'api_path'
2019-02-12 16:40:52,119 - apscheduler.executors.default - INFO - Job "APS.get_api_case_coverage (trigger: interval[0:00:10], next run at: 2019-02-12 16:41:01 CST)" executed successfully
2019-02-12 16:42:11,915 - apscheduler.scheduler - INFO - Scheduler started
2019-02-12 16:42:11,916 - tools.log - ERROR - 任务开始！！！
2019-02-12 16:42:11,993 - apscheduler.executors.default - INFO - Running job "APS.get_api_case_coverage (trigger: interval[0:00:10], next run at: 2019-02-12 16:41:01 CST)" (scheduled at 2019-02-12 16:42:11.507906+08:00)
2019-02-12 16:42:12,293 - tools.log - INFO - Expecting value: line 2 column 1 (char 1)
2019-02-12 16:42:12,416 - tools.log - INFO - ('Connection aborted.', ConnectionResetError(10054, '远程主机强迫关闭了一个现有的连接。', None, 10054, None))
2019-02-12 16:42:12,518 - tools.log - INFO - ('Connection aborted.', ConnectionResetError(10054, '远程主机强迫关闭了一个现有的连接。', None, 10054, None))
2019-02-12 16:42:12,600 - tools.log - INFO - ('Connection aborted.', ConnectionResetError(10054, '远程主机强迫关闭了一个现有的连接。', None, 10054, None))
2019-02-12 16:42:12,694 - tools.log - INFO - ('Connection aborted.', ConnectionResetError(10054, '远程主机强迫关闭了一个现有的连接。', None, 10054, None))
2019-02-12 16:42:12,785 - tools.log - INFO - ('Connection aborted.', ConnectionResetError(10054, '远程主机强迫关闭了一个现有的连接。', None, 10054, None))
2019-02-12 16:42:12,901 - tools.log - INFO - ('Connection aborted.', ConnectionResetError(10054, '远程主机强迫关闭了一个现有的连接。', None, 10054, None))
2019-02-12 16:42:12,999 - tools.log - INFO - ('Connection aborted.', ConnectionResetError(10054, '远程主机强迫关闭了一个现有的连接。', None, 10054, None))
2019-02-12 16:42:13,082 - tools.log - INFO - ('Connection aborted.', ConnectionResetError(10054, '远程主机强迫关闭了一个现有的连接。', None, 10054, None))
2019-02-12 16:42:13,184 - tools.log - INFO - ('Connection aborted.', ConnectionResetError(10054, '远程主机强迫关闭了一个现有的连接。', None, 10054, None))
2019-02-12 16:42:13,269 - tools.log - INFO - ('Connection aborted.', ConnectionResetError(10054, '远程主机强迫关闭了一个现有的连接。', None, 10054, None))
2019-02-12 16:42:13,362 - tools.log - INFO - ('Connection aborted.', ConnectionResetError(10054, '远程主机强迫关闭了一个现有的连接。', None, 10054, None))
2019-02-12 16:42:13,455 - tools.log - INFO - ('Connection aborted.', ConnectionResetError(10054, '远程主机强迫关闭了一个现有的连接。', None, 10054, None))
2019-02-12 16:42:13,471 - apscheduler.executors.default - INFO - Job "APS.get_api_case_coverage (trigger: interval[0:00:10], next run at: 2019-02-12 16:42:21 CST)" executed successfully
2019-02-12 16:44:53,581 - apscheduler.scheduler - INFO - Scheduler started
2019-02-12 16:44:53,582 - tools.log - ERROR - 任务开始！！！
2019-02-12 16:44:53,693 - apscheduler.executors.default - WARNING - Run time of job "APS.get_api_case_coverage (trigger: interval[0:00:10], next run at: 2019-02-12 16:45:01 CST)" was missed by 0:00:02.185913
2019-02-12 16:45:01,876 - apscheduler.executors.default - INFO - Running job "APS.get_api_case_coverage (trigger: interval[0:00:10], next run at: 2019-02-12 16:45:01 CST)" (scheduled at 2019-02-12 16:45:01.507906+08:00)
2019-02-12 16:45:02,252 - tools.log - INFO - ('Connection aborted.', ConnectionResetError(10054, '远程主机强迫关闭了一个现有的连接。', None, 10054, None))
2019-02-12 16:45:02,375 - tools.log - INFO - ('Connection aborted.', ConnectionResetError(10054, '远程主机强迫关闭了一个现有的连接。', None, 10054, None))
2019-02-12 16:45:02,478 - tools.log - INFO - ('Connection aborted.', ConnectionResetError(10054, '远程主机强迫关闭了一个现有的连接。', None, 10054, None))
2019-02-12 16:45:02,544 - tools.log - INFO - ('Connection aborted.', ConnectionResetError(10054, '远程主机强迫关闭了一个现有的连接。', None, 10054, None))
2019-02-12 16:45:02,648 - tools.log - INFO - ('Connection aborted.', ConnectionResetError(10054, '远程主机强迫关闭了一个现有的连接。', None, 10054, None))
2019-02-12 16:45:02,748 - tools.log - INFO - ('Connection aborted.', ConnectionResetError(10054, '远程主机强迫关闭了一个现有的连接。', None, 10054, None))
2019-02-12 16:45:02,830 - tools.log - INFO - ('Connection aborted.', ConnectionResetError(10054, '远程主机强迫关闭了一个现有的连接。', None, 10054, None))
2019-02-12 16:45:02,896 - tools.log - INFO - ('Connection aborted.', ConnectionResetError(10054, '远程主机强迫关闭了一个现有的连接。', None, 10054, None))
2019-02-12 16:45:03,009 - tools.log - INFO - ('Connection aborted.', ConnectionResetError(10054, '远程主机强迫关闭了一个现有的连接。', None, 10054, None))
2019-02-12 16:45:03,118 - tools.log - INFO - ('Connection aborted.', ConnectionResetError(10054, '远程主机强迫关闭了一个现有的连接。', None, 10054, None))
2019-02-12 16:45:03,227 - tools.log - INFO - ('Connection aborted.', ConnectionResetError(10054, '远程主机强迫关闭了一个现有的连接。', None, 10054, None))
2019-02-12 16:45:03,326 - tools.log - INFO - ('Connection aborted.', ConnectionResetError(10054, '远程主机强迫关闭了一个现有的连接。', None, 10054, None))
2019-02-12 16:45:03,433 - tools.log - INFO - ('Connection aborted.', ConnectionResetError(10054, '远程主机强迫关闭了一个现有的连接。', None, 10054, None))
2019-02-12 16:45:03,458 - apscheduler.executors.default - INFO - Job "APS.get_api_case_coverage (trigger: interval[0:00:10], next run at: 2019-02-12 16:45:11 CST)" executed successfully
2019-02-12 16:45:30,609 - apscheduler.scheduler - INFO - Scheduler started
2019-02-12 16:45:30,610 - tools.log - ERROR - 任务开始！！！
2019-02-12 16:45:30,746 - apscheduler.executors.default - WARNING - Run time of job "APS.get_api_case_coverage (trigger: interval[0:00:10], next run at: 2019-02-12 16:45:31 CST)" was missed by 0:00:09.238618
2019-02-12 16:45:31,930 - apscheduler.executors.default - INFO - Running job "APS.get_api_case_coverage (trigger: interval[0:00:10], next run at: 2019-02-12 16:45:31 CST)" (scheduled at 2019-02-12 16:45:31.507906+08:00)
2019-02-12 16:45:32,226 - tools.log - INFO - ('Connection aborted.', ConnectionResetError(10054, '远程主机强迫关闭了一个现有的连接。', None, 10054, None))
2019-02-12 16:45:32,333 - tools.log - INFO - ('Connection aborted.', ConnectionResetError(10054, '远程主机强迫关闭了一个现有的连接。', None, 10054, None))
2019-02-12 16:45:32,431 - tools.log - INFO - ('Connection aborted.', ConnectionResetError(10054, '远程主机强迫关闭了一个现有的连接。', None, 10054, None))
2019-02-12 16:45:32,550 - tools.log - INFO - Expecting value: line 2 column 1 (char 1)
2019-02-12 16:45:32,648 - tools.log - INFO - ('Connection aborted.', ConnectionResetError(10054, '远程主机强迫关闭了一个现有的连接。', None, 10054, None))
2019-02-12 16:45:32,713 - tools.log - INFO - ('Connection aborted.', ConnectionResetError(10054, '远程主机强迫关闭了一个现有的连接。', None, 10054, None))
2019-02-12 16:45:32,835 - tools.log - INFO - ('Connection aborted.', ConnectionResetError(10054, '远程主机强迫关闭了一个现有的连接。', None, 10054, None))
2019-02-12 16:45:32,943 - tools.log - INFO - ('Connection aborted.', ConnectionResetError(10054, '远程主机强迫关闭了一个现有的连接。', None, 10054, None))
2019-02-12 16:45:33,036 - tools.log - INFO - ('Connection aborted.', ConnectionResetError(10054, '远程主机强迫关闭了一个现有的连接。', None, 10054, None))
2019-02-12 16:45:33,123 - tools.log - INFO - ('Connection aborted.', ConnectionResetError(10054, '远程主机强迫关闭了一个现有的连接。', None, 10054, None))
2019-02-12 16:45:33,227 - tools.log - INFO - ('Connection aborted.', ConnectionResetError(10054, '远程主机强迫关闭了一个现有的连接。', None, 10054, None))
2019-02-12 16:45:33,326 - tools.log - INFO - ('Connection aborted.', ConnectionResetError(10054, '远程主机强迫关闭了一个现有的连接。', None, 10054, None))
2019-02-12 16:45:33,420 - tools.log - INFO - ('Connection aborted.', ConnectionResetError(10054, '远程主机强迫关闭了一个现有的连接。', None, 10054, None))
2019-02-12 16:45:33,440 - apscheduler.executors.default - INFO - Job "APS.get_api_case_coverage (trigger: interval[0:00:10], next run at: 2019-02-12 16:45:41 CST)" executed successfully
2019-02-12 16:49:20,256 - apscheduler.scheduler - INFO - Scheduler started
2019-02-12 16:49:20,257 - tools.log - ERROR - 任务开始！！！
2019-02-12 16:49:20,325 - apscheduler.executors.default - WARNING - Run time of job "APS.get_api_case_coverage (trigger: interval[0:00:10], next run at: 2019-02-12 16:49:21 CST)" was missed by 0:00:08.817271
2019-02-12 16:49:21,777 - apscheduler.executors.default - INFO - Running job "APS.get_api_case_coverage (trigger: interval[0:00:10], next run at: 2019-02-12 16:49:31 CST)" (scheduled at 2019-02-12 16:49:21.507906+08:00)
2019-02-12 16:49:22,242 - tools.log - INFO - Expecting value: line 2 column 1 (char 1)
2019-02-12 16:49:22,369 - tools.log - INFO - Expecting value: line 2 column 1 (char 1)
2019-02-12 16:49:22,515 - tools.log - INFO - Expecting value: line 2 column 1 (char 1)
2019-02-12 16:49:22,658 - tools.log - INFO - Expecting value: line 2 column 1 (char 1)
2019-02-12 16:49:22,803 - tools.log - INFO - Expecting value: line 2 column 1 (char 1)
2019-02-12 16:49:22,914 - tools.log - INFO - Expecting value: line 2 column 1 (char 1)
2019-02-12 16:49:23,081 - tools.log - INFO - Expecting value: line 2 column 1 (char 1)
2019-02-12 16:49:23,205 - tools.log - INFO - Expecting value: line 2 column 1 (char 1)
2019-02-12 16:49:23,308 - tools.log - INFO - Expecting value: line 2 column 1 (char 1)
2019-02-12 16:49:23,428 - tools.log - INFO - Expecting value: line 2 column 1 (char 1)
2019-02-12 16:49:23,581 - tools.log - INFO - Expecting value: line 2 column 1 (char 1)
2019-02-12 16:49:23,736 - tools.log - INFO - Expecting value: line 2 column 1 (char 1)
2019-02-12 16:49:23,865 - tools.log - INFO - Expecting value: line 2 column 1 (char 1)
2019-02-12 16:49:23,892 - apscheduler.executors.default - INFO - Job "APS.get_api_case_coverage (trigger: interval[0:00:10], next run at: 2019-02-12 16:49:31 CST)" executed successfully
2019-02-12 16:49:47,799 - apscheduler.scheduler - INFO - Scheduler started
2019-02-12 16:49:47,800 - tools.log - ERROR - 任务开始！！！
2019-02-12 16:49:47,902 - apscheduler.executors.default - WARNING - Run time of job "APS.get_api_case_coverage (trigger: interval[0:00:10], next run at: 2019-02-12 16:49:51 CST)" was missed by 0:00:06.394273
2019-02-12 16:49:51,830 - apscheduler.executors.default - INFO - Running job "APS.get_api_case_coverage (trigger: interval[0:00:10], next run at: 2019-02-12 16:49:51 CST)" (scheduled at 2019-02-12 16:49:51.507906+08:00)
2019-02-12 16:49:51,925 - tools.log - INFO - request() got an unexpected keyword argument 'param'
2019-02-12 16:49:51,955 - tools.log - INFO - request() got an unexpected keyword argument 'param'
2019-02-12 16:49:51,976 - tools.log - INFO - request() got an unexpected keyword argument 'param'
2019-02-12 16:49:51,987 - tools.log - INFO - request() got an unexpected keyword argument 'param'
2019-02-12 16:49:52,012 - tools.log - INFO - request() got an unexpected keyword argument 'param'
2019-02-12 16:49:52,047 - tools.log - INFO - request() got an unexpected keyword argument 'param'
2019-02-12 16:49:52,053 - tools.log - INFO - request() got an unexpected keyword argument 'param'
2019-02-12 16:49:52,068 - tools.log - INFO - request() got an unexpected keyword argument 'param'
2019-02-12 16:49:52,073 - tools.log - INFO - request() got an unexpected keyword argument 'param'
2019-02-12 16:49:52,089 - tools.log - INFO - request() got an unexpected keyword argument 'param'
2019-02-12 16:49:52,104 - tools.log - INFO - request() got an unexpected keyword argument 'param'
2019-02-12 16:49:52,129 - tools.log - INFO - request() got an unexpected keyword argument 'param'
2019-02-12 16:49:52,149 - tools.log - INFO - request() got an unexpected keyword argument 'param'
2019-02-12 16:49:52,184 - apscheduler.executors.default - INFO - Job "APS.get_api_case_coverage (trigger: interval[0:00:10], next run at: 2019-02-12 16:50:01 CST)" executed successfully
2019-02-12 16:50:54,741 - apscheduler.scheduler - INFO - Scheduler started
2019-02-12 16:50:54,742 - tools.log - ERROR - 任务开始！！！
2019-02-12 16:50:54,878 - apscheduler.executors.default - WARNING - Run time of job "APS.get_api_case_coverage (trigger: interval[0:00:10], next run at: 2019-02-12 16:51:01 CST)" was missed by 0:00:03.370277
2019-02-12 16:51:01,899 - apscheduler.executors.default - INFO - Running job "APS.get_api_case_coverage (trigger: interval[0:00:10], next run at: 2019-02-12 16:51:01 CST)" (scheduled at 2019-02-12 16:51:01.507906+08:00)
2019-02-12 16:51:02,506 - tools.log - INFO - (1064, "You have an error in your SQL syntax; check the manual that corresponds to your MySQL server version for the right syntax to use near '/api/test1' at line 1")
2019-02-12 16:51:02,873 - tools.log - INFO - (1064, "You have an error in your SQL syntax; check the manual that corresponds to your MySQL server version for the right syntax to use near '/api/test2' at line 1")
2019-02-12 16:51:03,283 - tools.log - INFO - (1064, "You have an error in your SQL syntax; check the manual that corresponds to your MySQL server version for the right syntax to use near '/aaa/aaab' at line 1")
2019-02-12 16:51:03,657 - tools.log - INFO - (1054, "Unknown column 'fsdafdsafsad' in 'where clause'")
2019-02-12 16:51:04,044 - tools.log - INFO - (1054, "Unknown column 'api' in 'where clause'")
2019-02-12 16:51:04,381 - tools.log - INFO - (1054, "Unknown column 'safdfasdf' in 'where clause'")
2019-02-12 16:51:04,736 - tools.log - INFO - (1054, "Unknown column 'sagdasdg' in 'where clause'")
2019-02-12 16:51:05,122 - tools.log - INFO - (1054, "Unknown column 'fasdf' in 'where clause'")
2019-02-12 16:51:05,467 - tools.log - INFO - (1054, "Unknown column 'sdgsadgasdg' in 'where clause'")
2019-02-12 16:51:05,833 - tools.log - INFO - (1054, "Unknown column 'sdafsdaf' in 'where clause'")
2019-02-12 16:51:06,227 - tools.log - INFO - (1054, "Unknown column 'cvsdasdfsaf' in 'where clause'")
2019-02-12 16:51:06,566 - tools.log - INFO - (1054, "Unknown column 'zxvccZ' in 'where clause'")
2019-02-12 16:51:06,898 - tools.log - INFO - (1064, "You have an error in your SQL syntax; check the manual that corresponds to your MySQL server version for the right syntax to use near '/api/user/mobileLogin' at line 1")
2019-02-12 16:51:06,923 - apscheduler.executors.default - INFO - Job "APS.get_api_case_coverage (trigger: interval[0:00:10], next run at: 2019-02-12 16:51:11 CST)" executed successfully
2019-02-12 16:51:11,930 - apscheduler.executors.default - INFO - Running job "APS.get_api_case_coverage (trigger: interval[0:00:10], next run at: 2019-02-12 16:51:21 CST)" (scheduled at 2019-02-12 16:51:11.507906+08:00)
2019-02-12 16:51:12,424 - tools.log - INFO - (1064, "You have an error in your SQL syntax; check the manual that corresponds to your MySQL server version for the right syntax to use near '/api/test1' at line 1")
2019-02-12 16:51:12,802 - tools.log - INFO - (1064, "You have an error in your SQL syntax; check the manual that corresponds to your MySQL server version for the right syntax to use near '/api/test2' at line 1")
2019-02-12 16:51:13,189 - tools.log - INFO - (1064, "You have an error in your SQL syntax; check the manual that corresponds to your MySQL server version for the right syntax to use near '/aaa/aaab' at line 1")
2019-02-12 16:51:13,553 - tools.log - INFO - (1054, "Unknown column 'fsdafdsafsad' in 'where clause'")
2019-02-12 16:51:13,930 - tools.log - INFO - (1054, "Unknown column 'api' in 'where clause'")
2019-02-12 16:51:14,292 - tools.log - INFO - (1054, "Unknown column 'safdfasdf' in 'where clause'")
2019-02-12 16:51:14,680 - tools.log - INFO - (1054, "Unknown column 'sagdasdg' in 'where clause'")
2019-02-12 16:51:15,015 - tools.log - INFO - (1054, "Unknown column 'fasdf' in 'where clause'")
2019-02-12 16:51:15,366 - tools.log - INFO - (1054, "Unknown column 'sdgsadgasdg' in 'where clause'")
2019-02-12 16:51:15,747 - tools.log - INFO - (1054, "Unknown column 'sdafsdaf' in 'where clause'")
2019-02-12 16:51:16,125 - tools.log - INFO - (1054, "Unknown column 'cvsdasdfsaf' in 'where clause'")
2019-02-12 16:51:16,484 - tools.log - INFO - (1054, "Unknown column 'zxvccZ' in 'where clause'")
2019-02-12 16:51:16,841 - tools.log - INFO - (1064, "You have an error in your SQL syntax; check the manual that corresponds to your MySQL server version for the right syntax to use near '/api/user/mobileLogin' at line 1")
2019-02-12 16:51:16,847 - apscheduler.executors.default - INFO - Job "APS.get_api_case_coverage (trigger: interval[0:00:10], next run at: 2019-02-12 16:51:21 CST)" executed successfully
2019-02-12 16:51:21,906 - apscheduler.executors.default - INFO - Running job "APS.get_api_case_coverage (trigger: interval[0:00:10], next run at: 2019-02-12 16:51:21 CST)" (scheduled at 2019-02-12 16:51:21.507906+08:00)
2019-02-12 16:51:22,433 - tools.log - INFO - (1064, "You have an error in your SQL syntax; check the manual that corresponds to your MySQL server version for the right syntax to use near '/api/test1' at line 1")
2019-02-12 16:51:22,787 - tools.log - INFO - (1064, "You have an error in your SQL syntax; check the manual that corresponds to your MySQL server version for the right syntax to use near '/api/test2' at line 1")
2019-02-12 16:51:23,117 - tools.log - INFO - (1064, "You have an error in your SQL syntax; check the manual that corresponds to your MySQL server version for the right syntax to use near '/aaa/aaab' at line 1")
2019-02-12 16:51:23,473 - tools.log - INFO - (1054, "Unknown column 'fsdafdsafsad' in 'where clause'")
2019-02-12 16:51:23,841 - tools.log - INFO - (1054, "Unknown column 'api' in 'where clause'")
2019-02-12 16:51:24,233 - tools.log - INFO - (1054, "Unknown column 'safdfasdf' in 'where clause'")
2019-02-12 16:51:24,642 - tools.log - INFO - (1054, "Unknown column 'sagdasdg' in 'where clause'")
2019-02-12 16:51:25,024 - tools.log - INFO - (1054, "Unknown column 'fasdf' in 'where clause'")
2019-02-12 16:51:25,411 - tools.log - INFO - (1054, "Unknown column 'sdgsadgasdg' in 'where clause'")
2019-02-12 16:51:25,781 - tools.log - INFO - (1054, "Unknown column 'sdafsdaf' in 'where clause'")
2019-02-12 16:51:26,110 - tools.log - INFO - (1054, "Unknown column 'cvsdasdfsaf' in 'where clause'")
2019-02-12 16:51:26,500 - tools.log - INFO - (1054, "Unknown column 'zxvccZ' in 'where clause'")
2019-02-12 16:51:26,881 - tools.log - INFO - (1064, "You have an error in your SQL syntax; check the manual that corresponds to your MySQL server version for the right syntax to use near '/api/user/mobileLogin' at line 1")
2019-02-12 16:51:26,906 - apscheduler.executors.default - INFO - Job "APS.get_api_case_coverage (trigger: interval[0:00:10], next run at: 2019-02-12 16:51:31 CST)" executed successfully
2019-02-12 16:53:22,746 - apscheduler.scheduler - INFO - Scheduler started
2019-02-12 16:53:22,747 - tools.log - ERROR - 任务开始！！！
2019-02-12 16:53:22,819 - apscheduler.executors.default - WARNING - Run time of job "APS.get_api_case_coverage (trigger: interval[0:00:10], next run at: 2019-02-12 16:53:31 CST)" was missed by 0:00:01.312064
2019-02-12 16:53:31,894 - apscheduler.executors.default - INFO - Running job "APS.get_api_case_coverage (trigger: interval[0:00:10], next run at: 2019-02-12 16:53:41 CST)" (scheduled at 2019-02-12 16:53:31.507906+08:00)
2019-02-12 16:53:37,533 - apscheduler.executors.default - INFO - Job "APS.get_api_case_coverage (trigger: interval[0:00:10], next run at: 2019-02-12 16:53:41 CST)" executed successfully
2019-02-12 17:00:03,106 - apscheduler.scheduler - INFO - Scheduler started
2019-02-12 17:00:03,107 - tools.log - ERROR - 任务开始！！！
2019-02-12 17:00:03,233 - apscheduler.executors.default - WARNING - Run time of job "APS.get_api_case_coverage (trigger: interval[0:00:10], next run at: 2019-02-12 16:53:41 CST)" was missed by 0:00:01.725910
2019-02-12 17:00:11,827 - apscheduler.executors.default - INFO - Running job "APS.get_api_case_coverage (trigger: interval[0:00:10], next run at: 2019-02-12 17:00:11 CST)" (scheduled at 2019-02-12 17:00:11.507906+08:00)
2019-02-12 17:00:14,022 - tools.log - INFO - 'dict' object has no attribute 'if_cn'
2019-02-12 17:00:17,250 - apscheduler.executors.default - INFO - Job "APS.get_api_case_coverage (trigger: interval[0:00:10], next run at: 2019-02-12 17:00:21 CST)" executed successfully
2019-02-12 17:00:21,810 - apscheduler.executors.default - INFO - Running job "APS.get_api_case_coverage (trigger: interval[0:00:10], next run at: 2019-02-12 17:00:31 CST)" (scheduled at 2019-02-12 17:00:21.507906+08:00)
2019-02-12 17:00:23,922 - tools.log - INFO - 'dict' object has no attribute 'if_cn'
2019-02-12 17:00:27,078 - apscheduler.executors.default - INFO - Job "APS.get_api_case_coverage (trigger: interval[0:00:10], next run at: 2019-02-12 17:00:31 CST)" executed successfully
2019-02-12 17:01:33,286 - apscheduler.scheduler - INFO - Scheduler started
2019-02-12 17:01:33,288 - tools.log - ERROR - 任务开始！！！
2019-02-12 17:01:33,374 - apscheduler.executors.default - WARNING - Run time of job "APS.get_api_case_coverage (trigger: interval[0:00:10], next run at: 2019-02-12 17:00:31 CST)" was missed by 0:00:01.866356
2019-02-12 17:01:41,799 - apscheduler.executors.default - INFO - Running job "APS.get_api_case_coverage (trigger: interval[0:00:10], next run at: 2019-02-12 17:01:51 CST)" (scheduled at 2019-02-12 17:01:41.507906+08:00)
2019-02-12 17:01:47,083 - apscheduler.executors.default - INFO - Job "APS.get_api_case_coverage (trigger: interval[0:00:10], next run at: 2019-02-12 17:01:51 CST)" executed successfully
2019-02-12 19:03:33,493 - apscheduler.scheduler - INFO - Scheduler started
2019-02-12 19:03:33,494 - tools.log - INFO - 任务开始！！！
2019-02-12 19:03:33,660 - apscheduler.executors.default - WARNING - Run time of job "APS.get_api_case_coverage (trigger: interval[0:00:10], next run at: 2019-02-12 19:03:41 CST)" was missed by 0:00:02.152914
2019-02-12 19:03:41,859 - apscheduler.executors.default - INFO - Running job "APS.get_api_case_coverage (trigger: interval[0:00:10], next run at: 2019-02-12 19:03:41 CST)" (scheduled at 2019-02-12 19:03:41.507906+08:00)
2019-02-12 19:03:55,847 - apscheduler.scheduler - INFO - Scheduler started
2019-02-12 19:03:55,849 - tools.log - INFO - 任务开始！！！
2019-02-12 19:03:55,939 - apscheduler.executors.default - WARNING - Run time of job "APS.get_api_case_coverage (trigger: interval[0:00:10], next run at: 2019-02-12 19:04:01 CST)" was missed by 0:00:04.431744
2019-02-12 19:04:01,794 - apscheduler.executors.default - INFO - Running job "APS.get_api_case_coverage (trigger: interval[0:00:10], next run at: 2019-02-12 19:04:01 CST)" (scheduled at 2019-02-12 19:04:01.507906+08:00)
2019-02-12 19:04:06,204 - apscheduler.executors.default - INFO - Job "APS.get_api_case_coverage (trigger: interval[0:00:10], next run at: 2019-02-12 19:04:11 CST)" executed successfully
2019-02-21 14:33:03,647 - django.request - WARNING - Not Found: /get_project_case
2019-02-21 14:33:17,012 - django.request - WARNING - Not Found: /get_project_case
2019-02-21 14:33:19,285 - django.request - WARNING - Not Found: /get_project_case
2019-02-28 19:22:44,286 - django.request - WARNING - Not Found: /demo/project_task
2019-03-01 16:29:00,386 - django.request - WARNING - Not Found: /demo/project_task
2019-03-04 17:12:48,923 - django.request - WARNING - Not Found: /get_project_case
2019-03-04 17:12:50,434 - django.request - WARNING - Not Found: /get_project_case
2019-03-04 17:14:52,057 - django.request - WARNING - Not Found: /get_project_case
2019-03-05 11:23:53,535 - django.request - WARNING - Not Found: /get_project_case
2019-03-05 11:23:56,030 - django.request - WARNING - Not Found: /get_project_case
2019-03-20 18:10:01,702 - django.request - WARNING - Not Found: /templates/403.html
2019-03-21 16:40:55,530 - tools.log - ERROR - invalid literal for int() with base 10: '["1"]'
2019-03-21 16:41:27,373 - tools.log - ERROR - invalid literal for int() with base 10: '["1"]'
2019-03-21 16:43:57,925 - tools.log - ERROR - invalid literal for int() with base 10: '['
2019-03-21 16:44:00,918 - tools.log - ERROR - invalid literal for int() with base 10: '['
2019-03-21 16:45:26,917 - tools.log - ERROR - invalid literal for int() with base 10: '['
2019-03-21 16:46:47,511 - tools.log - ERROR - 'int' object is not iterable
2019-03-21 16:48:13,198 - tools.log - ERROR - invalid literal for int() with base 10: '['
2019-03-21 17:01:41,008 - tools.log - ERROR - module 'django.core.serializers.json' has no attribute 'loads'
2019-03-21 17:12:31,212 - tools.log - ERROR - the JSON object must be str, bytes or bytearray, not 'NoneType'
2019-03-21 17:22:26,309 - tools.log - ERROR - the JSON object must be str, bytes or bytearray, not 'NoneType'
2019-04-28 13:23:15,595 - django.request - WARNING - Not Found: /login1
2019-04-29 15:16:38,074 - django.request - WARNING - Not Found: /demo/project_task
2019-04-29 20:26:20,604 - django.request - ERROR - Internal Server Error: /get_case_apis/
Traceback (most recent call last):
  File "D:\Program Files\python\lib\site-packages\django\core\handlers\exception.py", line 34, in inner
    response = get_response(request)
  File "D:\Program Files\python\lib\site-packages\django\core\handlers\base.py", line 126, in _get_response
    response = self.process_exception_by_middleware(e, request)
  File "D:\Program Files\python\lib\site-packages\django\core\handlers\base.py", line 124, in _get_response
    response = wrapped_callback(request, *callback_args, **callback_kwargs)
  File "D:\Program Files\python\lib\site-packages\django\contrib\auth\decorators.py", line 21, in _wrapped_view
    return view_func(request, *args, **kwargs)
  File "D:\Program Files\IAM\api\views.py", line 760, in get_case_apis
    de['case_api_update_time'] = ca.case_update_time.strftime("%Y-%m-%d %H:%M:%S")
AttributeError: 'CaseApi' object has no attribute 'case_update_time'
2019-04-29 20:36:36,102 - django.request - WARNING - Not Found: /case_apis/1/1
2019-04-29 20:37:22,856 - django.security.csrf - WARNING - Forbidden (CSRF token missing or incorrect.): /get_case_apis/
2019-05-14 15:33:12,854 - django.request - ERROR - Internal Server Error: /get_project_apis
Traceback (most recent call last):
  File "D:\Program Files\python\lib\site-packages\django\core\handlers\exception.py", line 34, in inner
    response = get_response(request)
  File "D:\Program Files\python\lib\site-packages\django\core\handlers\base.py", line 126, in _get_response
    response = self.process_exception_by_middleware(e, request)
  File "D:\Program Files\python\lib\site-packages\django\core\handlers\base.py", line 124, in _get_response
    response = wrapped_callback(request, *callback_args, **callback_kwargs)
  File "D:\Program Files\python\lib\site-packages\django\contrib\auth\decorators.py", line 21, in _wrapped_view
    return view_func(request, *args, **kwargs)
  File "D:\Program Files\IAM\api\views.py", line 379, in get_project_apis
    de['api_update_time'] = api.api_update_time.strftime("%Y-%m-%d %H:%M:%S")
AttributeError: 'NoneType' object has no attribute 'strftime'
2019-05-14 18:23:57,833 - apscheduler.scheduler - INFO - Scheduler started
2019-05-14 18:23:57,834 - tools.log - INFO - 任务开始！！！
2019-05-14 18:23:58,012 - apscheduler.jobstores.default - ERROR - Unable to restore job "1549960771.4634013" -- removing it
Traceback (most recent call last):
  File "D:\Program Files\python\lib\site-packages\apscheduler\util.py", line 289, in ref_to_obj
    obj = getattr(obj, name)
AttributeError: module '__main__' has no attribute 'APS'

During handling of the above exception, another exception occurred:

Traceback (most recent call last):
  File "D:\Program Files\python\lib\site-packages\apscheduler\jobstores\sqlalchemy.py", line 141, in _get_jobs
    jobs.append(self._reconstitute_job(row.job_state))
  File "D:\Program Files\python\lib\site-packages\apscheduler\jobstores\sqlalchemy.py", line 128, in _reconstitute_job
    job.__setstate__(job_state)
  File "D:\Program Files\python\lib\site-packages\apscheduler\job.py", line 268, in __setstate__
    self.func = ref_to_obj(self.func_ref)
  File "D:\Program Files\python\lib\site-packages\apscheduler\util.py", line 292, in ref_to_obj
    raise LookupError('Error resolving reference %s: error looking up object' % ref)
LookupError: Error resolving reference __main__:APS.get_api_case_coverage: error looking up object
2019-05-14 18:24:02,836 - apscheduler.scheduler - INFO - Scheduler has been shut down
2019-05-14 18:24:02,842 - tools.log - INFO - 任务结束！！！
2019-05-14 18:26:28,412 - apscheduler.scheduler - INFO - Adding job tentatively -- it will be properly scheduled when the scheduler starts
2019-05-14 18:26:28,569 - apscheduler.scheduler - INFO - Added job "APS.get_api_case_coverage" to job store "default"
2019-05-14 18:26:28,570 - apscheduler.scheduler - INFO - Scheduler started
2019-05-14 18:26:28,571 - tools.log - INFO - 任务开始！！！
2019-05-14 18:26:38,530 - apscheduler.executors.default - INFO - Running job "APS.get_api_case_coverage (trigger: interval[0:00:10], next run at: 2019-05-14 18:26:38 CST)" (scheduled at 2019-05-14 18:26:38.412867+08:00)
2019-05-14 18:26:48,617 - apscheduler.executors.default - INFO - Running job "APS.get_api_case_coverage (trigger: interval[0:00:10], next run at: 2019-05-14 18:26:48 CST)" (scheduled at 2019-05-14 18:26:48.412867+08:00)
2019-05-14 18:26:58,693 - apscheduler.executors.default - INFO - Running job "APS.get_api_case_coverage (trigger: interval[0:00:10], next run at: 2019-05-14 18:27:08 CST)" (scheduled at 2019-05-14 18:26:58.412867+08:00)
2019-05-14 18:27:08,612 - apscheduler.executors.default - INFO - Running job "APS.get_api_case_coverage (trigger: interval[0:00:10], next run at: 2019-05-14 18:27:08 CST)" (scheduled at 2019-05-14 18:27:08.412867+08:00)
2019-05-14 18:27:18,720 - apscheduler.executors.default - INFO - Running job "APS.get_api_case_coverage (trigger: interval[0:00:10], next run at: 2019-05-14 18:27:18 CST)" (scheduled at 2019-05-14 18:27:18.412867+08:00)
2019-05-14 18:27:28,736 - apscheduler.executors.default - INFO - Running job "APS.get_api_case_coverage (trigger: interval[0:00:10], next run at: 2019-05-14 18:27:38 CST)" (scheduled at 2019-05-14 18:27:28.412867+08:00)
2019-05-14 18:27:38,834 - apscheduler.executors.default - INFO - Running job "APS.get_api_case_coverage (trigger: interval[0:00:10], next run at: 2019-05-14 18:27:38 CST)" (scheduled at 2019-05-14 18:27:38.412867+08:00)
2019-05-14 18:27:48,703 - apscheduler.executors.default - INFO - Running job "APS.get_api_case_coverage (trigger: interval[0:00:10], next run at: 2019-05-14 18:27:48 CST)" (scheduled at 2019-05-14 18:27:48.412867+08:00)
2019-05-14 18:38:04,275 - apscheduler.scheduler - INFO - Adding job tentatively -- it will be properly scheduled when the scheduler starts
2019-05-14 18:38:04,420 - apscheduler.scheduler - INFO - Added job "APS.get_api_case_coverage" to job store "default"
2019-05-14 18:38:04,420 - apscheduler.scheduler - INFO - Scheduler started
2019-05-14 18:38:04,421 - tools.log - INFO - 任务开始！！！
2019-05-14 18:38:04,462 - apscheduler.executors.default - WARNING - Run time of job "APS.get_api_case_coverage (trigger: interval[0:00:10], next run at: 2019-05-14 18:27:58 CST)" was missed by 0:00:06.049387
2019-05-14 18:38:08,693 - apscheduler.executors.default - INFO - Running job "APS.get_api_case_coverage (trigger: interval[0:00:10], next run at: 2019-05-14 18:38:08 CST)" (scheduled at 2019-05-14 18:38:08.412867+08:00)
2019-05-14 18:38:18,680 - apscheduler.executors.default - INFO - Running job "APS.get_api_case_coverage (trigger: interval[0:00:10], next run at: 2019-05-14 18:38:28 CST)" (scheduled at 2019-05-14 18:38:18.412867+08:00)
2019-05-14 18:38:28,782 - apscheduler.executors.default - INFO - Running job "APS.get_api_case_coverage (trigger: interval[0:00:10], next run at: 2019-05-14 18:38:28 CST)" (scheduled at 2019-05-14 18:38:28.412867+08:00)
2019-05-14 18:38:38,711 - apscheduler.executors.default - INFO - Running job "APS.get_api_case_coverage (trigger: interval[0:00:10], next run at: 2019-05-14 18:38:48 CST)" (scheduled at 2019-05-14 18:38:38.412867+08:00)
2019-05-14 18:38:48,735 - apscheduler.executors.default - INFO - Running job "APS.get_api_case_coverage (trigger: interval[0:00:10], next run at: 2019-05-14 18:38:48 CST)" (scheduled at 2019-05-14 18:38:48.412867+08:00)
2019-05-14 18:39:24,808 - apscheduler.scheduler - INFO - Adding job tentatively -- it will be properly scheduled when the scheduler starts
2019-05-14 18:39:24,872 - apscheduler.scheduler - INFO - Added job "APS.get_api_case_coverage" to job store "default"
2019-05-14 18:39:24,873 - apscheduler.scheduler - INFO - Scheduler started
2019-05-14 18:39:24,874 - tools.log - INFO - 任务开始！！！
2019-05-14 19:39:25,008 - apscheduler.executors.default - INFO - Running job "APS.get_api_case_coverage (trigger: interval[1:00:00], next run at: 2019-05-14 20:39:24 CST)" (scheduled at 2019-05-14 19:39:24.808957+08:00)
2019-05-14 19:42:18,748 - apscheduler.executors.default - INFO - Job "APS.get_api_case_coverage (trigger: interval[1:00:00], next run at: 2019-05-14 20:39:24 CST)" executed successfully
2019-05-14 20:39:25,049 - apscheduler.executors.default - INFO - Running job "APS.get_api_case_coverage (trigger: interval[1:00:00], next run at: 2019-05-14 21:39:24 CST)" (scheduled at 2019-05-14 20:39:24.808957+08:00)
2019-05-14 20:42:19,782 - apscheduler.executors.default - INFO - Job "APS.get_api_case_coverage (trigger: interval[1:00:00], next run at: 2019-05-14 21:39:24 CST)" executed successfully
2019-05-14 21:39:25,094 - apscheduler.executors.default - INFO - Running job "APS.get_api_case_coverage (trigger: interval[1:00:00], next run at: 2019-05-14 22:39:24 CST)" (scheduled at 2019-05-14 21:39:24.808957+08:00)
2019-05-14 21:42:20,435 - apscheduler.executors.default - INFO - Job "APS.get_api_case_coverage (trigger: interval[1:00:00], next run at: 2019-05-14 22:39:24 CST)" executed successfully
2019-05-14 22:39:25,172 - apscheduler.executors.default - INFO - Running job "APS.get_api_case_coverage (trigger: interval[1:00:00], next run at: 2019-05-14 23:39:24 CST)" (scheduled at 2019-05-14 22:39:24.808957+08:00)
2019-05-14 22:42:20,277 - apscheduler.executors.default - INFO - Job "APS.get_api_case_coverage (trigger: interval[1:00:00], next run at: 2019-05-14 23:39:24 CST)" executed successfully
2019-05-14 23:39:25,149 - apscheduler.executors.default - INFO - Running job "APS.get_api_case_coverage (trigger: interval[1:00:00], next run at: 2019-05-14 23:39:24 CST)" (scheduled at 2019-05-14 23:39:24.808957+08:00)
2019-05-14 23:42:21,184 - apscheduler.executors.default - INFO - Job "APS.get_api_case_coverage (trigger: interval[1:00:00], next run at: 2019-05-15 00:39:24 CST)" executed successfully
2019-05-15 00:39:25,135 - apscheduler.executors.default - INFO - Running job "APS.get_api_case_coverage (trigger: interval[1:00:00], next run at: 2019-05-15 00:39:24 CST)" (scheduled at 2019-05-15 00:39:24.808957+08:00)
2019-05-15 00:42:20,962 - apscheduler.executors.default - INFO - Job "APS.get_api_case_coverage (trigger: interval[1:00:00], next run at: 2019-05-15 01:39:24 CST)" executed successfully
2019-05-15 01:39:25,084 - apscheduler.executors.default - INFO - Running job "APS.get_api_case_coverage (trigger: interval[1:00:00], next run at: 2019-05-15 02:39:24 CST)" (scheduled at 2019-05-15 01:39:24.808957+08:00)
2019-05-15 01:42:20,983 - apscheduler.executors.default - INFO - Job "APS.get_api_case_coverage (trigger: interval[1:00:00], next run at: 2019-05-15 02:39:24 CST)" executed successfully
2019-05-15 02:39:25,033 - apscheduler.executors.default - INFO - Running job "APS.get_api_case_coverage (trigger: interval[1:00:00], next run at: 2019-05-15 02:39:24 CST)" (scheduled at 2019-05-15 02:39:24.808957+08:00)
2019-05-15 02:42:20,450 - apscheduler.executors.default - INFO - Job "APS.get_api_case_coverage (trigger: interval[1:00:00], next run at: 2019-05-15 03:39:24 CST)" executed successfully
2019-05-15 03:39:25,126 - apscheduler.executors.default - INFO - Running job "APS.get_api_case_coverage (trigger: interval[1:00:00], next run at: 2019-05-15 03:39:24 CST)" (scheduled at 2019-05-15 03:39:24.808957+08:00)
2019-05-15 03:42:21,503 - apscheduler.executors.default - INFO - Job "APS.get_api_case_coverage (trigger: interval[1:00:00], next run at: 2019-05-15 04:39:24 CST)" executed successfully
2019-05-15 04:39:25,130 - apscheduler.executors.default - INFO - Running job "APS.get_api_case_coverage (trigger: interval[1:00:00], next run at: 2019-05-15 04:39:24 CST)" (scheduled at 2019-05-15 04:39:24.808957+08:00)
2019-05-15 04:42:22,430 - apscheduler.executors.default - INFO - Job "APS.get_api_case_coverage (trigger: interval[1:00:00], next run at: 2019-05-15 05:39:24 CST)" executed successfully
2019-05-15 05:39:25,077 - apscheduler.executors.default - INFO - Running job "APS.get_api_case_coverage (trigger: interval[1:00:00], next run at: 2019-05-15 06:39:24 CST)" (scheduled at 2019-05-15 05:39:24.808957+08:00)
2019-05-15 05:42:20,809 - apscheduler.executors.default - INFO - Job "APS.get_api_case_coverage (trigger: interval[1:00:00], next run at: 2019-05-15 06:39:24 CST)" executed successfully
2019-05-15 06:39:25,000 - apscheduler.executors.default - INFO - Running job "APS.get_api_case_coverage (trigger: interval[1:00:00], next run at: 2019-05-15 07:39:24 CST)" (scheduled at 2019-05-15 06:39:24.808957+08:00)
2019-05-15 06:42:21,334 - apscheduler.executors.default - INFO - Job "APS.get_api_case_coverage (trigger: interval[1:00:00], next run at: 2019-05-15 07:39:24 CST)" executed successfully
2019-05-15 07:39:25,040 - apscheduler.executors.default - INFO - Running job "APS.get_api_case_coverage (trigger: interval[1:00:00], next run at: 2019-05-15 08:39:24 CST)" (scheduled at 2019-05-15 07:39:24.808957+08:00)
2019-05-15 07:42:19,492 - apscheduler.executors.default - INFO - Job "APS.get_api_case_coverage (trigger: interval[1:00:00], next run at: 2019-05-15 08:39:24 CST)" executed successfully
2019-05-15 08:39:25,023 - apscheduler.executors.default - INFO - Running job "APS.get_api_case_coverage (trigger: interval[1:00:00], next run at: 2019-05-15 09:39:24 CST)" (scheduled at 2019-05-15 08:39:24.808957+08:00)
2019-05-15 08:42:20,503 - apscheduler.executors.default - INFO - Job "APS.get_api_case_coverage (trigger: interval[1:00:00], next run at: 2019-05-15 09:39:24 CST)" executed successfully
2019-05-15 09:39:25,089 - apscheduler.executors.default - INFO - Running job "APS.get_api_case_coverage (trigger: interval[1:00:00], next run at: 2019-05-15 10:39:24 CST)" (scheduled at 2019-05-15 09:39:24.808957+08:00)
2019-05-15 09:42:31,304 - apscheduler.executors.default - INFO - Job "APS.get_api_case_coverage (trigger: interval[1:00:00], next run at: 2019-05-15 10:39:24 CST)" executed successfully
2019-05-15 10:39:25,035 - apscheduler.executors.default - INFO - Running job "APS.get_api_case_coverage (trigger: interval[1:00:00], next run at: 2019-05-15 11:39:24 CST)" (scheduled at 2019-05-15 10:39:24.808957+08:00)
2019-05-15 10:42:45,901 - apscheduler.executors.default - INFO - Job "APS.get_api_case_coverage (trigger: interval[1:00:00], next run at: 2019-05-15 11:39:24 CST)" executed successfully
2019-05-15 11:39:25,102 - apscheduler.executors.default - INFO - Running job "APS.get_api_case_coverage (trigger: interval[1:00:00], next run at: 2019-05-15 12:39:24 CST)" (scheduled at 2019-05-15 11:39:24.808957+08:00)
2019-05-15 11:42:28,524 - apscheduler.executors.default - INFO - Job "APS.get_api_case_coverage (trigger: interval[1:00:00], next run at: 2019-05-15 12:39:24 CST)" executed successfully
2019-05-21 11:06:21,792 - django.request - WARNING - Not Found: /project_case/
2019-05-21 11:07:09,600 - django.request - WARNING - Not Found: /project_case/
2019-05-21 11:07:13,248 - django.request - WARNING - Not Found: /project_case/
2019-05-21 11:08:02,613 - django.request - WARNING - Not Found: /project_case/
2019-05-21 11:10:34,442 - django.request - WARNING - Not Found: /demo/admin.html
2019-05-21 11:10:37,517 - django.request - WARNING - Not Found: /demo/project_task
2019-05-21 11:20:08,197 - django.request - WARNING - Not Found: /get_project_case
2019-05-21 11:20:09,695 - django.request - WARNING - Not Found: /get_project_case
2019-05-21 11:20:11,236 - django.request - WARNING - Not Found: /get_project_case
2019-05-21 11:20:21,934 - django.request - WARNING - Not Found: /del_project_case
2019-05-21 11:50:00,599 - tools.log - ERROR - list indices must be integers or slices, not str
2019-05-21 11:51:22,850 - tools.log - ERROR - list indices must be integers or slices, not str
2019-05-21 12:03:31,682 - tools.log - ERROR - 'project-case-add-name'
2019-05-21 12:03:56,473 - tools.log - ERROR - 'project-case-add-name'
2019-05-21 12:06:48,656 - tools.log - ERROR - 'project-case-add-name'
2019-05-21 13:07:36,240 - tools.log - ERROR - 'project-case-add-name'
2019-05-21 13:54:20,068 - django.request - ERROR - Internal Server Error: /get_project_case
Traceback (most recent call last):
  File "D:\Program Files\python\lib\site-packages\django\core\handlers\exception.py", line 34, in inner
    response = get_response(request)
  File "D:\Program Files\python\lib\site-packages\django\core\handlers\base.py", line 126, in _get_response
    response = self.process_exception_by_middleware(e, request)
  File "D:\Program Files\python\lib\site-packages\django\core\handlers\base.py", line 124, in _get_response
    response = wrapped_callback(request, *callback_args, **callback_kwargs)
  File "D:\Program Files\python\lib\site-packages\django\contrib\auth\decorators.py", line 21, in _wrapped_view
    return view_func(request, *args, **kwargs)
  File "D:\Program Files\IAM\api\views.py", line 681, in get_project_case
    return JsonResponse(resultdict,safe=False)
  File "D:\Program Files\python\lib\site-packages\django\http\response.py", line 558, in __init__
    data = json.dumps(data, cls=encoder, **json_dumps_params)
  File "D:\Program Files\python\lib\json\__init__.py", line 238, in dumps
    **kw).encode(obj)
  File "D:\Program Files\python\lib\json\encoder.py", line 199, in encode
    chunks = self.iterencode(o, _one_shot=True)
  File "D:\Program Files\python\lib\json\encoder.py", line 257, in iterencode
    return _iterencode(o, 0)
  File "D:\Program Files\python\lib\site-packages\django\core\serializers\json.py", line 104, in default
    return super().default(o)
  File "D:\Program Files\python\lib\json\encoder.py", line 180, in default
    o.__class__.__name__)
TypeError: Object of type 'Case' is not JSON serializable
2019-05-21 14:23:27,421 - django.request - WARNING - Not Found: /edit_project_case
2019-05-22 13:55:31,575 - tools.log - ERROR - The database backend does not accept 0 as a value for AutoField.
2019-05-22 13:57:16,233 - tools.log - ERROR - The database backend does not accept 0 as a value for AutoField.
2019-05-22 13:59:11,810 - tools.log - ERROR - The database backend does not accept 0 as a value for AutoField.
2019-05-22 14:00:28,993 - tools.log - ERROR - The database backend does not accept 0 as a value for AutoField.
2019-05-22 14:02:22,385 - tools.log - ERROR - 'int' object has no attribute 'save'
2019-05-22 14:03:08,032 - tools.log - ERROR - 'int' object has no attribute 'id'
2019-05-22 14:29:18,375 - django.request - WARNING - Not Found: /demo/project_task
2019-05-22 20:43:07,629 - tools.log - ERROR - 'project-case-add-name'
2019-05-22 20:45:52,913 - tools.log - ERROR - 'project-case-add-name'
2019-05-22 20:48:39,666 - django.request - ERROR - Internal Server Error: /add_project_case_api
Traceback (most recent call last):
  File "D:\Program Files\python\lib\site-packages\django\core\handlers\exception.py", line 34, in inner
    response = get_response(request)
  File "D:\Program Files\python\lib\site-packages\django\utils\deprecation.py", line 90, in __call__
    response = self.process_request(request)
  File "D:\Program Files\python\lib\site-packages\django\middleware\common.py", line 53, in process_request
    path = self.get_full_path_with_slash(request)
  File "D:\Program Files\python\lib\site-packages\django\middleware\common.py", line 93, in get_full_path_with_slash
    'url': request.get_host() + new_path,
RuntimeError: You called this URL via POST, but the URL doesn't end in a slash and you have APPEND_SLASH set. Django can't redirect to the slash URL while maintaining POST data. Change your form to point to 127.0.0.1:8000/add_project_case_api/ (note the trailing slash), or set APPEND_SLASH=False in your Django settings.
2019-05-22 20:52:34,001 - tools.log - ERROR - unsupported operand type(s) for +: 'dict' and 'int'
2019-05-22 20:53:26,954 - tools.log - ERROR - 'dict' object has no attribute 'sort'
2019-05-22 20:59:20,850 - django.request - WARNING - Not Found: /demo/project_task
2019-05-23 14:25:48,212 - tools.log - ERROR - 
2019-05-23 14:28:52,720 - tools.log - ERROR - 
2019-05-23 14:31:17,298 - tools.log - ERROR - 
2019-05-23 14:31:40,822 - tools.log - ERROR - eval() arg 1 must be a string, bytes or code object
2019-06-04 14:02:20,638 - django.request - WARNING - Not Found: /get_case_api_detail
2019-06-05 12:59:25,383 - django.request - ERROR - Internal Server Error: /get_case_api_detail
Traceback (most recent call last):
  File "D:\Program Files\python\lib\site-packages\django\core\handlers\exception.py", line 34, in inner
    response = get_response(request)
  File "D:\Program Files\python\lib\site-packages\django\core\handlers\base.py", line 126, in _get_response
    response = self.process_exception_by_middleware(e, request)
  File "D:\Program Files\python\lib\site-packages\django\core\handlers\base.py", line 124, in _get_response
    response = wrapped_callback(request, *callback_args, **callback_kwargs)
  File "D:\Program Files\python\lib\site-packages\django\contrib\auth\decorators.py", line 21, in _wrapped_view
    return view_func(request, *args, **kwargs)
  File "D:\Program Files\python\lib\site-packages\django\views\decorators\http.py", line 40, in inner
    return func(request, *args, **kwargs)
  File "D:\Program Files\IAM\api\views.py", line 932, in get_case_api_detail
    case_api_info['api_headers'] = case_api['api_headers']
TypeError: 'QuerySet' object does not support item assignment
2019-06-05 13:01:42,053 - django.request - ERROR - Internal Server Error: /get_case_api_detail
Traceback (most recent call last):
  File "D:\Program Files\python\lib\site-packages\django\core\handlers\exception.py", line 34, in inner
    response = get_response(request)
  File "D:\Program Files\python\lib\site-packages\django\core\handlers\base.py", line 126, in _get_response
    response = self.process_exception_by_middleware(e, request)
  File "D:\Program Files\python\lib\site-packages\django\core\handlers\base.py", line 124, in _get_response
    response = wrapped_callback(request, *callback_args, **callback_kwargs)
  File "D:\Program Files\python\lib\site-packages\django\contrib\auth\decorators.py", line 21, in _wrapped_view
    return view_func(request, *args, **kwargs)
  File "D:\Program Files\python\lib\site-packages\django\views\decorators\http.py", line 40, in inner
    return func(request, *args, **kwargs)
  File "D:\Program Files\IAM\api\views.py", line 933, in get_case_api_detail
    case_api_info['api_headers'] = case_api['api_headers']
TypeError: 'QuerySet' object does not support item assignment
2019-06-05 13:03:23,063 - django.request - ERROR - Internal Server Error: /get_case_api_detail
Traceback (most recent call last):
  File "D:\Program Files\python\lib\site-packages\django\core\handlers\exception.py", line 34, in inner
    response = get_response(request)
  File "D:\Program Files\python\lib\site-packages\django\core\handlers\base.py", line 126, in _get_response
    response = self.process_exception_by_middleware(e, request)
  File "D:\Program Files\python\lib\site-packages\django\core\handlers\base.py", line 124, in _get_response
    response = wrapped_callback(request, *callback_args, **callback_kwargs)
  File "D:\Program Files\python\lib\site-packages\django\contrib\auth\decorators.py", line 21, in _wrapped_view
    return view_func(request, *args, **kwargs)
  File "D:\Program Files\python\lib\site-packages\django\views\decorators\http.py", line 40, in inner
    return func(request, *args, **kwargs)
  File "D:\Program Files\IAM\api\views.py", line 932, in get_case_api_detail
    print(case_api.api_headers)
AttributeError: 'dict' object has no attribute 'api_headers'
2019-06-05 13:03:49,216 - django.request - ERROR - Internal Server Error: /get_case_api_detail
Traceback (most recent call last):
  File "D:\Program Files\python\lib\site-packages\django\core\handlers\exception.py", line 34, in inner
    response = get_response(request)
  File "D:\Program Files\python\lib\site-packages\django\core\handlers\base.py", line 126, in _get_response
    response = self.process_exception_by_middleware(e, request)
  File "D:\Program Files\python\lib\site-packages\django\core\handlers\base.py", line 124, in _get_response
    response = wrapped_callback(request, *callback_args, **callback_kwargs)
  File "D:\Program Files\python\lib\site-packages\django\contrib\auth\decorators.py", line 21, in _wrapped_view
    return view_func(request, *args, **kwargs)
  File "D:\Program Files\python\lib\site-packages\django\views\decorators\http.py", line 40, in inner
    return func(request, *args, **kwargs)
  File "D:\Program Files\IAM\api\views.py", line 933, in get_case_api_detail
    case_api_info['api_headers'] = case_api['api_headers']
TypeError: 'QuerySet' object does not support item assignment
2019-06-05 13:04:36,479 - django.request - ERROR - Internal Server Error: /get_case_api_detail
Traceback (most recent call last):
  File "D:\Program Files\python\lib\site-packages\django\core\handlers\exception.py", line 34, in inner
    response = get_response(request)
  File "D:\Program Files\python\lib\site-packages\django\core\handlers\base.py", line 126, in _get_response
    response = self.process_exception_by_middleware(e, request)
  File "D:\Program Files\python\lib\site-packages\django\core\handlers\base.py", line 124, in _get_response
    response = wrapped_callback(request, *callback_args, **callback_kwargs)
  File "D:\Program Files\python\lib\site-packages\django\contrib\auth\decorators.py", line 21, in _wrapped_view
    return view_func(request, *args, **kwargs)
  File "D:\Program Files\python\lib\site-packages\django\views\decorators\http.py", line 40, in inner
    return func(request, *args, **kwargs)
  File "D:\Program Files\IAM\api\views.py", line 933, in get_case_api_detail
    case_api_info['api_headers'] = case_api['api_headers']
TypeError: 'QuerySet' object does not support item assignment
2019-06-05 13:05:25,685 - django.request - ERROR - Internal Server Error: /get_case_api_detail
Traceback (most recent call last):
  File "D:\Program Files\python\lib\site-packages\django\core\handlers\exception.py", line 34, in inner
    response = get_response(request)
  File "D:\Program Files\python\lib\site-packages\django\core\handlers\base.py", line 126, in _get_response
    response = self.process_exception_by_middleware(e, request)
  File "D:\Program Files\python\lib\site-packages\django\core\handlers\base.py", line 124, in _get_response
    response = wrapped_callback(request, *callback_args, **callback_kwargs)
  File "D:\Program Files\python\lib\site-packages\django\contrib\auth\decorators.py", line 21, in _wrapped_view
    return view_func(request, *args, **kwargs)
  File "D:\Program Files\python\lib\site-packages\django\views\decorators\http.py", line 40, in inner
    return func(request, *args, **kwargs)
  File "D:\Program Files\IAM\api\views.py", line 943, in get_case_api_detail
    return JsonResponse(resultdict, safe=False)
  File "D:\Program Files\python\lib\site-packages\django\http\response.py", line 558, in __init__
    data = json.dumps(data, cls=encoder, **json_dumps_params)
  File "D:\Program Files\python\lib\json\__init__.py", line 238, in dumps
    **kw).encode(obj)
  File "D:\Program Files\python\lib\json\encoder.py", line 199, in encode
    chunks = self.iterencode(o, _one_shot=True)
  File "D:\Program Files\python\lib\json\encoder.py", line 257, in iterencode
    return _iterencode(o, 0)
  File "D:\Program Files\python\lib\site-packages\django\core\serializers\json.py", line 104, in default
    return super().default(o)
  File "D:\Program Files\python\lib\json\encoder.py", line 180, in default
    o.__class__.__name__)
TypeError: Object of type 'QuerySet' is not JSON serializable
2019-06-05 13:06:46,750 - django.request - ERROR - Internal Server Error: /get_case_api_detail
Traceback (most recent call last):
  File "D:\Program Files\python\lib\site-packages\django\core\handlers\exception.py", line 34, in inner
    response = get_response(request)
  File "D:\Program Files\python\lib\site-packages\django\core\handlers\base.py", line 126, in _get_response
    response = self.process_exception_by_middleware(e, request)
  File "D:\Program Files\python\lib\site-packages\django\core\handlers\base.py", line 124, in _get_response
    response = wrapped_callback(request, *callback_args, **callback_kwargs)
  File "D:\Program Files\python\lib\site-packages\django\contrib\auth\decorators.py", line 21, in _wrapped_view
    return view_func(request, *args, **kwargs)
  File "D:\Program Files\python\lib\site-packages\django\views\decorators\http.py", line 40, in inner
    return func(request, *args, **kwargs)
  File "D:\Program Files\IAM\api\views.py", line 943, in get_case_api_detail
    return JsonResponse(resultdict, safe=False)
  File "D:\Program Files\python\lib\site-packages\django\http\response.py", line 558, in __init__
    data = json.dumps(data, cls=encoder, **json_dumps_params)
  File "D:\Program Files\python\lib\json\__init__.py", line 238, in dumps
    **kw).encode(obj)
  File "D:\Program Files\python\lib\json\encoder.py", line 199, in encode
    chunks = self.iterencode(o, _one_shot=True)
  File "D:\Program Files\python\lib\json\encoder.py", line 257, in iterencode
    return _iterencode(o, 0)
  File "D:\Program Files\python\lib\site-packages\django\core\serializers\json.py", line 104, in default
    return super().default(o)
  File "D:\Program Files\python\lib\json\encoder.py", line 180, in default
    o.__class__.__name__)
TypeError: Object of type 'QuerySet' is not JSON serializable
2019-06-05 13:07:28,868 - django.request - ERROR - Internal Server Error: /get_case_api_detail
Traceback (most recent call last):
  File "D:\Program Files\python\lib\site-packages\django\core\handlers\exception.py", line 34, in inner
    response = get_response(request)
  File "D:\Program Files\python\lib\site-packages\django\core\handlers\base.py", line 126, in _get_response
    response = self.process_exception_by_middleware(e, request)
  File "D:\Program Files\python\lib\site-packages\django\core\handlers\base.py", line 124, in _get_response
    response = wrapped_callback(request, *callback_args, **callback_kwargs)
  File "D:\Program Files\python\lib\site-packages\django\contrib\auth\decorators.py", line 21, in _wrapped_view
    return view_func(request, *args, **kwargs)
  File "D:\Program Files\python\lib\site-packages\django\views\decorators\http.py", line 40, in inner
    return func(request, *args, **kwargs)
  File "D:\Program Files\IAM\api\views.py", line 943, in get_case_api_detail
    return JsonResponse(resultdict, safe=False)
  File "D:\Program Files\python\lib\site-packages\django\http\response.py", line 558, in __init__
    data = json.dumps(data, cls=encoder, **json_dumps_params)
  File "D:\Program Files\python\lib\json\__init__.py", line 238, in dumps
    **kw).encode(obj)
  File "D:\Program Files\python\lib\json\encoder.py", line 199, in encode
    chunks = self.iterencode(o, _one_shot=True)
  File "D:\Program Files\python\lib\json\encoder.py", line 257, in iterencode
    return _iterencode(o, 0)
  File "D:\Program Files\python\lib\site-packages\django\core\serializers\json.py", line 104, in default
    return super().default(o)
  File "D:\Program Files\python\lib\json\encoder.py", line 180, in default
    o.__class__.__name__)
TypeError: Object of type 'QuerySet' is not JSON serializable
2019-06-05 13:09:16,694 - django.request - ERROR - Internal Server Error: /get_case_api_detail
Traceback (most recent call last):
  File "D:\Program Files\python\lib\site-packages\django\core\handlers\exception.py", line 34, in inner
    response = get_response(request)
  File "D:\Program Files\python\lib\site-packages\django\core\handlers\base.py", line 126, in _get_response
    response = self.process_exception_by_middleware(e, request)
  File "D:\Program Files\python\lib\site-packages\django\core\handlers\base.py", line 124, in _get_response
    response = wrapped_callback(request, *callback_args, **callback_kwargs)
  File "D:\Program Files\python\lib\site-packages\django\contrib\auth\decorators.py", line 21, in _wrapped_view
    return view_func(request, *args, **kwargs)
  File "D:\Program Files\python\lib\site-packages\django\views\decorators\http.py", line 40, in inner
    return func(request, *args, **kwargs)
  File "D:\Program Files\IAM\api\views.py", line 935, in get_case_api_detail
    data['pre_steps'] = eval(pre_steps)
TypeError: eval() arg 1 must be a string, bytes or code object
2019-06-06 19:32:24,558 - tools.log - ERROR - 'project-case-add-name'
2019-06-10 13:16:58,191 - django.request - WARNING - Method Not Allowed (POST): /get_case_api_detail
2019-06-10 13:17:01,887 - django.request - WARNING - Method Not Allowed (POST): /get_case_api_detail
2019-06-10 13:23:36,960 - django.request - WARNING - Method Not Allowed (POST): /get_case_api_detail
2019-06-17 14:07:48,352 - tools.log - ERROR - 'project-case-add-name'
2019-06-17 16:08:11,128 - django.request - WARNING - Not Found: /edit_case_api
2019-06-17 16:16:41,186 - django.request - WARNING - Not Found: /edit_case_api
2019-06-18 19:43:32,272 - tools.log - ERROR - The database backend does not accept 0 as a value for AutoField.
2019-06-18 19:54:55,492 - tools.log - ERROR - Cannot assign "0": "Step.CaseApi" must be a "CaseApi" instance.
2019-06-18 19:59:31,754 - tools.log - ERROR - CaseApi matching query does not exist.
2019-06-18 20:01:34,606 - tools.log - ERROR - The database backend does not accept 0 as a value for AutoField.
2019-06-19 10:06:39,984 - tools.log - ERROR - The database backend does not accept 0 as a value for AutoField.
2019-06-19 10:30:12,531 - tools.log - ERROR - invalid literal for int() with base 10: 'SQL'
2019-06-19 11:50:05,925 - django.request - ERROR - Internal Server Error: /get_case_api_detail
Traceback (most recent call last):
  File "D:\Program Files\python\lib\site-packages\django\core\handlers\exception.py", line 34, in inner
    response = get_response(request)
  File "D:\Program Files\python\lib\site-packages\django\core\handlers\base.py", line 126, in _get_response
    response = self.process_exception_by_middleware(e, request)
  File "D:\Program Files\python\lib\site-packages\django\core\handlers\base.py", line 124, in _get_response
    response = wrapped_callback(request, *callback_args, **callback_kwargs)
  File "D:\Program Files\python\lib\site-packages\django\contrib\auth\decorators.py", line 21, in _wrapped_view
    return view_func(request, *args, **kwargs)
  File "D:\Program Files\python\lib\site-packages\django\views\decorators\http.py", line 40, in inner
    return func(request, *args, **kwargs)
  File "D:\Program Files\IAM\api\views.py", line 954, in get_case_api_detail
    data['assertion'] = assertion.step_content
AttributeError: 'QuerySet' object has no attribute 'step_content'
2019-06-19 11:51:01,468 - django.request - ERROR - Internal Server Error: /get_case_api_detail
Traceback (most recent call last):
  File "D:\Program Files\python\lib\site-packages\django\core\handlers\exception.py", line 34, in inner
    response = get_response(request)
  File "D:\Program Files\python\lib\site-packages\django\core\handlers\base.py", line 126, in _get_response
    response = self.process_exception_by_middleware(e, request)
  File "D:\Program Files\python\lib\site-packages\django\core\handlers\base.py", line 124, in _get_response
    response = wrapped_callback(request, *callback_args, **callback_kwargs)
  File "D:\Program Files\python\lib\site-packages\django\contrib\auth\decorators.py", line 21, in _wrapped_view
    return view_func(request, *args, **kwargs)
  File "D:\Program Files\python\lib\site-packages\django\views\decorators\http.py", line 40, in inner
    return func(request, *args, **kwargs)
  File "D:\Program Files\IAM\api\views.py", line 954, in get_case_api_detail
    data['assertion'] = assertion['step_content']
  File "D:\Program Files\python\lib\site-packages\django\db\models\query.py", line 278, in __getitem__
    raise TypeError
TypeError
2019-06-19 11:55:06,982 - django.request - ERROR - Internal Server Error: /get_case_api_detail
Traceback (most recent call last):
  File "D:\Program Files\python\lib\site-packages\django\core\handlers\exception.py", line 34, in inner
    response = get_response(request)
  File "D:\Program Files\python\lib\site-packages\django\core\handlers\base.py", line 126, in _get_response
    response = self.process_exception_by_middleware(e, request)
  File "D:\Program Files\python\lib\site-packages\django\core\handlers\base.py", line 124, in _get_response
    response = wrapped_callback(request, *callback_args, **callback_kwargs)
  File "D:\Program Files\python\lib\site-packages\django\contrib\auth\decorators.py", line 21, in _wrapped_view
    return view_func(request, *args, **kwargs)
  File "D:\Program Files\python\lib\site-packages\django\views\decorators\http.py", line 40, in inner
    return func(request, *args, **kwargs)
  File "D:\Program Files\IAM\api\views.py", line 952, in get_case_api_detail
    data['pre_steps'] = eval(pre_steps)
TypeError: eval() arg 1 must be a string, bytes or code object
2019-06-19 11:55:41,734 - django.request - ERROR - Internal Server Error: /get_case_api_detail
Traceback (most recent call last):
  File "D:\Program Files\python\lib\site-packages\django\core\handlers\exception.py", line 34, in inner
    response = get_response(request)
  File "D:\Program Files\python\lib\site-packages\django\core\handlers\base.py", line 126, in _get_response
    response = self.process_exception_by_middleware(e, request)
  File "D:\Program Files\python\lib\site-packages\django\core\handlers\base.py", line 124, in _get_response
    response = wrapped_callback(request, *callback_args, **callback_kwargs)
  File "D:\Program Files\python\lib\site-packages\django\contrib\auth\decorators.py", line 21, in _wrapped_view
    return view_func(request, *args, **kwargs)
  File "D:\Program Files\python\lib\site-packages\django\views\decorators\http.py", line 40, in inner
    return func(request, *args, **kwargs)
  File "D:\Program Files\IAM\api\views.py", line 952, in get_case_api_detail
    data['pre_steps'] = json.loads(pre_steps)
  File "D:\Program Files\python\lib\json\__init__.py", line 348, in loads
    'not {!r}'.format(s.__class__.__name__))
TypeError: the JSON object must be str, bytes or bytearray, not 'QuerySet'
2019-06-19 11:58:03,522 - django.request - ERROR - Internal Server Error: /get_case_api_detail
Traceback (most recent call last):
  File "D:\Program Files\python\lib\site-packages\django\core\handlers\exception.py", line 34, in inner
    response = get_response(request)
  File "D:\Program Files\python\lib\site-packages\django\core\handlers\base.py", line 126, in _get_response
    response = self.process_exception_by_middleware(e, request)
  File "D:\Program Files\python\lib\site-packages\django\core\handlers\base.py", line 124, in _get_response
    response = wrapped_callback(request, *callback_args, **callback_kwargs)
  File "D:\Program Files\python\lib\site-packages\django\contrib\auth\decorators.py", line 21, in _wrapped_view
    return view_func(request, *args, **kwargs)
  File "D:\Program Files\python\lib\site-packages\django\views\decorators\http.py", line 40, in inner
    return func(request, *args, **kwargs)
  File "D:\Program Files\IAM\api\views.py", line 944, in get_case_api_detail
    assertion = Step.objects.filter(CaseApi_id=caid,step_type='Assertion').values().first().all()
AttributeError: 'dict' object has no attribute 'all'
2019-06-19 11:58:20,688 - django.request - ERROR - Internal Server Error: /get_case_api_detail
Traceback (most recent call last):
  File "D:\Program Files\python\lib\site-packages\django\core\handlers\exception.py", line 34, in inner
    response = get_response(request)
  File "D:\Program Files\python\lib\site-packages\django\core\handlers\base.py", line 126, in _get_response
    response = self.process_exception_by_middleware(e, request)
  File "D:\Program Files\python\lib\site-packages\django\core\handlers\base.py", line 124, in _get_response
    response = wrapped_callback(request, *callback_args, **callback_kwargs)
  File "D:\Program Files\python\lib\site-packages\django\contrib\auth\decorators.py", line 21, in _wrapped_view
    return view_func(request, *args, **kwargs)
  File "D:\Program Files\python\lib\site-packages\django\views\decorators\http.py", line 40, in inner
    return func(request, *args, **kwargs)
  File "D:\Program Files\IAM\api\views.py", line 952, in get_case_api_detail
    data['pre_steps'] = json.loads(pre_steps)
  File "D:\Program Files\python\lib\json\__init__.py", line 348, in loads
    'not {!r}'.format(s.__class__.__name__))
TypeError: the JSON object must be str, bytes or bytearray, not 'QuerySet'
2019-06-19 12:00:03,670 - django.request - ERROR - Internal Server Error: /get_case_api_detail
Traceback (most recent call last):
  File "D:\Program Files\python\lib\site-packages\django\core\handlers\exception.py", line 34, in inner
    response = get_response(request)
  File "D:\Program Files\python\lib\site-packages\django\core\handlers\base.py", line 126, in _get_response
    response = self.process_exception_by_middleware(e, request)
  File "D:\Program Files\python\lib\site-packages\django\core\handlers\base.py", line 124, in _get_response
    response = wrapped_callback(request, *callback_args, **callback_kwargs)
  File "D:\Program Files\python\lib\site-packages\django\contrib\auth\decorators.py", line 21, in _wrapped_view
    return view_func(request, *args, **kwargs)
  File "D:\Program Files\python\lib\site-packages\django\views\decorators\http.py", line 40, in inner
    return func(request, *args, **kwargs)
  File "D:\Program Files\IAM\api\views.py", line 952, in get_case_api_detail
    data['pre_steps'] = json.loads(list(pre_steps))
  File "D:\Program Files\python\lib\json\__init__.py", line 348, in loads
    'not {!r}'.format(s.__class__.__name__))
TypeError: the JSON object must be str, bytes or bytearray, not 'list'
2019-06-19 12:00:20,486 - django.request - ERROR - Internal Server Error: /get_case_api_detail
Traceback (most recent call last):
  File "D:\Program Files\python\lib\site-packages\django\core\handlers\exception.py", line 34, in inner
    response = get_response(request)
  File "D:\Program Files\python\lib\site-packages\django\core\handlers\base.py", line 126, in _get_response
    response = self.process_exception_by_middleware(e, request)
  File "D:\Program Files\python\lib\site-packages\django\core\handlers\base.py", line 124, in _get_response
    response = wrapped_callback(request, *callback_args, **callback_kwargs)
  File "D:\Program Files\python\lib\site-packages\django\contrib\auth\decorators.py", line 21, in _wrapped_view
    return view_func(request, *args, **kwargs)
  File "D:\Program Files\python\lib\site-packages\django\views\decorators\http.py", line 40, in inner
    return func(request, *args, **kwargs)
  File "D:\Program Files\IAM\api\views.py", line 952, in get_case_api_detail
    data['pre_steps'] = json.dumps(list(pre_steps))
  File "D:\Program Files\python\lib\json\__init__.py", line 231, in dumps
    return _default_encoder.encode(obj)
  File "D:\Program Files\python\lib\json\encoder.py", line 199, in encode
    chunks = self.iterencode(o, _one_shot=True)
  File "D:\Program Files\python\lib\json\encoder.py", line 257, in iterencode
    return _iterencode(o, 0)
  File "D:\Program Files\python\lib\json\encoder.py", line 180, in default
    o.__class__.__name__)
TypeError: Object of type 'datetime' is not JSON serializable
2019-06-19 12:00:34,142 - django.request - ERROR - Internal Server Error: /get_case_api_detail
Traceback (most recent call last):
  File "D:\Program Files\python\lib\site-packages\django\core\handlers\exception.py", line 34, in inner
    response = get_response(request)
  File "D:\Program Files\python\lib\site-packages\django\core\handlers\base.py", line 126, in _get_response
    response = self.process_exception_by_middleware(e, request)
  File "D:\Program Files\python\lib\site-packages\django\core\handlers\base.py", line 124, in _get_response
    response = wrapped_callback(request, *callback_args, **callback_kwargs)
  File "D:\Program Files\python\lib\site-packages\django\contrib\auth\decorators.py", line 21, in _wrapped_view
    return view_func(request, *args, **kwargs)
  File "D:\Program Files\python\lib\site-packages\django\views\decorators\http.py", line 40, in inner
    return func(request, *args, **kwargs)
  File "D:\Program Files\IAM\api\views.py", line 952, in get_case_api_detail
    data['pre_steps'] = json.loads(list(pre_steps))
  File "D:\Program Files\python\lib\json\__init__.py", line 348, in loads
    'not {!r}'.format(s.__class__.__name__))
TypeError: the JSON object must be str, bytes or bytearray, not 'list'
2019-06-19 12:00:43,299 - django.request - ERROR - Internal Server Error: /get_case_api_detail
Traceback (most recent call last):
  File "D:\Program Files\python\lib\site-packages\django\core\handlers\exception.py", line 34, in inner
    response = get_response(request)
  File "D:\Program Files\python\lib\site-packages\django\core\handlers\base.py", line 126, in _get_response
    response = self.process_exception_by_middleware(e, request)
  File "D:\Program Files\python\lib\site-packages\django\core\handlers\base.py", line 124, in _get_response
    response = wrapped_callback(request, *callback_args, **callback_kwargs)
  File "D:\Program Files\python\lib\site-packages\django\contrib\auth\decorators.py", line 21, in _wrapped_view
    return view_func(request, *args, **kwargs)
  File "D:\Program Files\python\lib\site-packages\django\views\decorators\http.py", line 40, in inner
    return func(request, *args, **kwargs)
  File "D:\Program Files\IAM\api\views.py", line 952, in get_case_api_detail
    data['pre_steps'] = eval(list(pre_steps))
TypeError: eval() arg 1 must be a string, bytes or code object
2019-06-19 14:32:33,172 - django.request - ERROR - Internal Server Error: /get_case_api_detail
Traceback (most recent call last):
  File "D:\Program Files\python\lib\site-packages\django\core\handlers\exception.py", line 34, in inner
    response = get_response(request)
  File "D:\Program Files\python\lib\site-packages\django\core\handlers\base.py", line 126, in _get_response
    response = self.process_exception_by_middleware(e, request)
  File "D:\Program Files\python\lib\site-packages\django\core\handlers\base.py", line 124, in _get_response
    response = wrapped_callback(request, *callback_args, **callback_kwargs)
  File "D:\Program Files\python\lib\site-packages\django\contrib\auth\decorators.py", line 21, in _wrapped_view
    return view_func(request, *args, **kwargs)
  File "D:\Program Files\python\lib\site-packages\django\views\decorators\http.py", line 40, in inner
    return func(request, *args, **kwargs)
  File "D:\Program Files\IAM\api\views.py", line 952, in get_case_api_detail
    data['pre_steps'] = json.loads(str(pre_steps))
  File "D:\Program Files\python\lib\json\__init__.py", line 354, in loads
    return _default_decoder.decode(s)
  File "D:\Program Files\python\lib\json\decoder.py", line 339, in decode
    obj, end = self.raw_decode(s, idx=_w(s, 0).end())
  File "D:\Program Files\python\lib\json\decoder.py", line 357, in raw_decode
    raise JSONDecodeError("Expecting value", s, err.value) from None
json.decoder.JSONDecodeError: Expecting value: line 1 column 1 (char 0)
2019-06-19 14:34:35,810 - django.request - ERROR - Internal Server Error: /get_case_api_detail
Traceback (most recent call last):
  File "D:\Program Files\python\lib\site-packages\django\core\handlers\exception.py", line 34, in inner
    response = get_response(request)
  File "D:\Program Files\python\lib\site-packages\django\core\handlers\base.py", line 126, in _get_response
    response = self.process_exception_by_middleware(e, request)
  File "D:\Program Files\python\lib\site-packages\django\core\handlers\base.py", line 124, in _get_response
    response = wrapped_callback(request, *callback_args, **callback_kwargs)
  File "D:\Program Files\python\lib\site-packages\django\contrib\auth\decorators.py", line 21, in _wrapped_view
    return view_func(request, *args, **kwargs)
  File "D:\Program Files\python\lib\site-packages\django\views\decorators\http.py", line 40, in inner
    return func(request, *args, **kwargs)
  File "D:\Program Files\IAM\api\views.py", line 952, in get_case_api_detail
    data['pre_steps'] = eval(str(pre_steps))
  File "<string>", line 1
    <QuerySet [{'id': 1, 'CaseApi_id': 19, 'step_type': 'SQL', 'step_sort': 1, 'step_content': '{\'pre_sqlenv\': \'${qapmfmysql}\', \'pre_content\': \'select username from user where mobile="15921720233"\', \'pre_variable\': \'username\'}', 'step_create_time': datetime.datetime(2019, 6, 19, 11, 31, 37), 'step_update_time': None}]>
    ^
SyntaxError: invalid syntax
2019-07-01 12:36:45,577 - django.request - ERROR - Internal Server Error: /testjson
Traceback (most recent call last):
  File "D:\Program Files\python\lib\site-packages\django\core\handlers\exception.py", line 34, in inner
    response = get_response(request)
  File "D:\Program Files\python\lib\site-packages\django\core\handlers\base.py", line 126, in _get_response
    response = self.process_exception_by_middleware(e, request)
  File "D:\Program Files\python\lib\site-packages\django\core\handlers\base.py", line 124, in _get_response
    response = wrapped_callback(request, *callback_args, **callback_kwargs)
  File "D:\Program Files\IAM\api\views.py", line 62, in testjson
    data = json.loads(request.body)
  File "D:\Program Files\python\lib\json\__init__.py", line 354, in loads
    return _default_decoder.decode(s)
  File "D:\Program Files\python\lib\json\decoder.py", line 339, in decode
    obj, end = self.raw_decode(s, idx=_w(s, 0).end())
  File "D:\Program Files\python\lib\json\decoder.py", line 357, in raw_decode
    raise JSONDecodeError("Expecting value", s, err.value) from None
json.decoder.JSONDecodeError: Expecting value: line 1 column 1 (char 0)
2019-07-08 16:31:11,561 - django.request - ERROR - Internal Server Error: /get_case_api_detail
Traceback (most recent call last):
  File "D:\Program Files\python\lib\site-packages\django\core\handlers\exception.py", line 34, in inner
    response = get_response(request)
  File "D:\Program Files\python\lib\site-packages\django\core\handlers\base.py", line 126, in _get_response
    response = self.process_exception_by_middleware(e, request)
  File "D:\Program Files\python\lib\site-packages\django\core\handlers\base.py", line 124, in _get_response
    response = wrapped_callback(request, *callback_args, **callback_kwargs)
  File "D:\Program Files\python\lib\site-packages\django\contrib\auth\decorators.py", line 21, in _wrapped_view
    return view_func(request, *args, **kwargs)
  File "D:\Program Files\python\lib\site-packages\django\views\decorators\http.py", line 40, in inner
    return func(request, *args, **kwargs)
  File "D:\Program Files\IAM\api\views.py", line 957, in get_case_api_detail
    data['assertion'] = assertion['step_content']
TypeError: 'NoneType' object is not subscriptable
2019-07-08 16:31:12,344 - django.request - ERROR - Internal Server Error: /get_case_api_detail
Traceback (most recent call last):
  File "D:\Program Files\python\lib\site-packages\django\core\handlers\exception.py", line 34, in inner
    response = get_response(request)
  File "D:\Program Files\python\lib\site-packages\django\core\handlers\base.py", line 126, in _get_response
    response = self.process_exception_by_middleware(e, request)
  File "D:\Program Files\python\lib\site-packages\django\core\handlers\base.py", line 124, in _get_response
    response = wrapped_callback(request, *callback_args, **callback_kwargs)
  File "D:\Program Files\python\lib\site-packages\django\contrib\auth\decorators.py", line 21, in _wrapped_view
    return view_func(request, *args, **kwargs)
  File "D:\Program Files\python\lib\site-packages\django\views\decorators\http.py", line 40, in inner
    return func(request, *args, **kwargs)
  File "D:\Program Files\IAM\api\views.py", line 957, in get_case_api_detail
    data['assertion'] = assertion['step_content']
TypeError: 'NoneType' object is not subscriptable
2019-07-08 16:31:13,104 - django.request - ERROR - Internal Server Error: /get_case_api_detail
Traceback (most recent call last):
  File "D:\Program Files\python\lib\site-packages\django\core\handlers\exception.py", line 34, in inner
    response = get_response(request)
  File "D:\Program Files\python\lib\site-packages\django\core\handlers\base.py", line 126, in _get_response
    response = self.process_exception_by_middleware(e, request)
  File "D:\Program Files\python\lib\site-packages\django\core\handlers\base.py", line 124, in _get_response
    response = wrapped_callback(request, *callback_args, **callback_kwargs)
  File "D:\Program Files\python\lib\site-packages\django\contrib\auth\decorators.py", line 21, in _wrapped_view
    return view_func(request, *args, **kwargs)
  File "D:\Program Files\python\lib\site-packages\django\views\decorators\http.py", line 40, in inner
    return func(request, *args, **kwargs)
  File "D:\Program Files\IAM\api\views.py", line 957, in get_case_api_detail
    data['assertion'] = assertion['step_content']
TypeError: 'NoneType' object is not subscriptable
2019-07-08 16:31:13,634 - django.request - ERROR - Internal Server Error: /get_case_api_detail
Traceback (most recent call last):
  File "D:\Program Files\python\lib\site-packages\django\core\handlers\exception.py", line 34, in inner
    response = get_response(request)
  File "D:\Program Files\python\lib\site-packages\django\core\handlers\base.py", line 126, in _get_response
    response = self.process_exception_by_middleware(e, request)
  File "D:\Program Files\python\lib\site-packages\django\core\handlers\base.py", line 124, in _get_response
    response = wrapped_callback(request, *callback_args, **callback_kwargs)
  File "D:\Program Files\python\lib\site-packages\django\contrib\auth\decorators.py", line 21, in _wrapped_view
    return view_func(request, *args, **kwargs)
  File "D:\Program Files\python\lib\site-packages\django\views\decorators\http.py", line 40, in inner
    return func(request, *args, **kwargs)
  File "D:\Program Files\IAM\api\views.py", line 957, in get_case_api_detail
    data['assertion'] = assertion['step_content']
TypeError: 'NoneType' object is not subscriptable
2019-07-08 16:31:15,573 - django.request - ERROR - Internal Server Error: /get_case_api_detail
Traceback (most recent call last):
  File "D:\Program Files\python\lib\site-packages\django\core\handlers\exception.py", line 34, in inner
    response = get_response(request)
  File "D:\Program Files\python\lib\site-packages\django\core\handlers\base.py", line 126, in _get_response
    response = self.process_exception_by_middleware(e, request)
  File "D:\Program Files\python\lib\site-packages\django\core\handlers\base.py", line 124, in _get_response
    response = wrapped_callback(request, *callback_args, **callback_kwargs)
  File "D:\Program Files\python\lib\site-packages\django\contrib\auth\decorators.py", line 21, in _wrapped_view
    return view_func(request, *args, **kwargs)
  File "D:\Program Files\python\lib\site-packages\django\views\decorators\http.py", line 40, in inner
    return func(request, *args, **kwargs)
  File "D:\Program Files\IAM\api\views.py", line 957, in get_case_api_detail
    data['assertion'] = assertion['step_content']
TypeError: 'NoneType' object is not subscriptable
2019-07-08 16:31:16,177 - django.request - ERROR - Internal Server Error: /get_case_api_detail
Traceback (most recent call last):
  File "D:\Program Files\python\lib\site-packages\django\core\handlers\exception.py", line 34, in inner
    response = get_response(request)
  File "D:\Program Files\python\lib\site-packages\django\core\handlers\base.py", line 126, in _get_response
    response = self.process_exception_by_middleware(e, request)
  File "D:\Program Files\python\lib\site-packages\django\core\handlers\base.py", line 124, in _get_response
    response = wrapped_callback(request, *callback_args, **callback_kwargs)
  File "D:\Program Files\python\lib\site-packages\django\contrib\auth\decorators.py", line 21, in _wrapped_view
    return view_func(request, *args, **kwargs)
  File "D:\Program Files\python\lib\site-packages\django\views\decorators\http.py", line 40, in inner
    return func(request, *args, **kwargs)
  File "D:\Program Files\IAM\api\views.py", line 957, in get_case_api_detail
    data['assertion'] = assertion['step_content']
TypeError: 'NoneType' object is not subscriptable
2019-07-22 13:39:10,466 - django.request - WARNING - Not Found: /testjson/
2019-07-22 13:39:32,229 - django.request - WARNING - Not Found: /testjson/
2019-07-22 14:12:07,295 - django.request - WARNING - Not Found: /testjson/
2019-07-22 14:12:17,534 - django.request - WARNING - Not Found: /testjson/
2019-07-22 14:12:53,503 - django.request - WARNING - Not Found: /testjson/
2019-07-22 14:13:02,710 - django.request - WARNING - Not Found: /testjson/
2019-07-22 14:13:21,233 - django.request - ERROR - Internal Server Error: /testjson
Traceback (most recent call last):
  File "D:\Program Files\python\lib\site-packages\django\core\handlers\exception.py", line 34, in inner
    response = get_response(request)
  File "D:\Program Files\python\lib\site-packages\django\core\handlers\base.py", line 126, in _get_response
    response = self.process_exception_by_middleware(e, request)
  File "D:\Program Files\python\lib\site-packages\django\core\handlers\base.py", line 124, in _get_response
    response = wrapped_callback(request, *callback_args, **callback_kwargs)
  File "D:\Program Files\IAM\api\views.py", line 62, in testjson
    data = json.loads(request.body)
  File "D:\Program Files\python\lib\json\__init__.py", line 354, in loads
    return _default_decoder.decode(s)
  File "D:\Program Files\python\lib\json\decoder.py", line 339, in decode
    obj, end = self.raw_decode(s, idx=_w(s, 0).end())
  File "D:\Program Files\python\lib\json\decoder.py", line 357, in raw_decode
    raise JSONDecodeError("Expecting value", s, err.value) from None
json.decoder.JSONDecodeError: Expecting value: line 1 column 1 (char 0)
2019-07-24 19:26:12,556 - django.request - WARNING - Not Found: /get_project_tasks
2019-07-24 19:27:45,313 - django.request - WARNING - Not Found: /get_project_tasks
2019-08-01 18:58:22,917 - django.request - WARNING - Not Found: /get_project_tasks
2019-08-05 13:33:43,703 - django.request - ERROR - Internal Server Error: /get_project_tasks
Traceback (most recent call last):
  File "D:\Program Files\python\lib\site-packages\django\core\handlers\exception.py", line 34, in inner
    response = get_response(request)
  File "D:\Program Files\python\lib\site-packages\django\core\handlers\base.py", line 126, in _get_response
    response = self.process_exception_by_middleware(e, request)
  File "D:\Program Files\python\lib\site-packages\django\core\handlers\base.py", line 124, in _get_response
    response = wrapped_callback(request, *callback_args, **callback_kwargs)
  File "D:\Program Files\python\lib\site-packages\django\contrib\auth\decorators.py", line 21, in _wrapped_view
    return view_func(request, *args, **kwargs)
  File "D:\Program Files\python\lib\site-packages\django\views\decorators\http.py", line 40, in inner
    return func(request, *args, **kwargs)
  File "D:\Program Files\IAM\api\views.py", line 1050, in get_project_tasks
    de['id'] = task.id
AttributeError: 'dict' object has no attribute 'id'
2019-08-05 13:34:46,434 - django.request - ERROR - Internal Server Error: /get_project_tasks
Traceback (most recent call last):
  File "D:\Program Files\python\lib\site-packages\django\core\handlers\exception.py", line 34, in inner
    response = get_response(request)
  File "D:\Program Files\python\lib\site-packages\django\core\handlers\base.py", line 126, in _get_response
    response = self.process_exception_by_middleware(e, request)
  File "D:\Program Files\python\lib\site-packages\django\core\handlers\base.py", line 124, in _get_response
    response = wrapped_callback(request, *callback_args, **callback_kwargs)
  File "D:\Program Files\python\lib\site-packages\django\contrib\auth\decorators.py", line 21, in _wrapped_view
    return view_func(request, *args, **kwargs)
  File "D:\Program Files\python\lib\site-packages\django\views\decorators\http.py", line 40, in inner
    return func(request, *args, **kwargs)
  File "D:\Program Files\IAM\api\views.py", line 1051, in get_project_tasks
    de['id'] = task.id
AttributeError: 'dict' object has no attribute 'id'
2019-08-05 13:36:14,847 - django.request - ERROR - Internal Server Error: /get_project_tasks
Traceback (most recent call last):
  File "D:\Program Files\python\lib\site-packages\django\core\handlers\exception.py", line 34, in inner
    response = get_response(request)
  File "D:\Program Files\python\lib\site-packages\django\core\handlers\base.py", line 126, in _get_response
    response = self.process_exception_by_middleware(e, request)
  File "D:\Program Files\python\lib\site-packages\django\core\handlers\base.py", line 124, in _get_response
    response = wrapped_callback(request, *callback_args, **callback_kwargs)
  File "D:\Program Files\python\lib\site-packages\django\contrib\auth\decorators.py", line 21, in _wrapped_view
    return view_func(request, *args, **kwargs)
  File "D:\Program Files\python\lib\site-packages\django\views\decorators\http.py", line 40, in inner
    return func(request, *args, **kwargs)
  File "D:\Program Files\IAM\api\views.py", line 1055, in get_project_tasks
    de['last_task_time'] = last_task_log.get('create_time')
AttributeError: 'NoneType' object has no attribute 'get'
2019-08-05 13:36:53,057 - django.request - ERROR - Internal Server Error: /get_project_tasks
Traceback (most recent call last):
  File "D:\Program Files\python\lib\site-packages\django\core\handlers\exception.py", line 34, in inner
    response = get_response(request)
  File "D:\Program Files\python\lib\site-packages\django\core\handlers\base.py", line 126, in _get_response
    response = self.process_exception_by_middleware(e, request)
  File "D:\Program Files\python\lib\site-packages\django\core\handlers\base.py", line 124, in _get_response
    response = wrapped_callback(request, *callback_args, **callback_kwargs)
  File "D:\Program Files\python\lib\site-packages\django\contrib\auth\decorators.py", line 21, in _wrapped_view
    return view_func(request, *args, **kwargs)
  File "D:\Program Files\python\lib\site-packages\django\views\decorators\http.py", line 40, in inner
    return func(request, *args, **kwargs)
  File "D:\Program Files\IAM\api\views.py", line 1055, in get_project_tasks
    de['last_task_time'] = last_task_log.get('create_time')
AttributeError: 'NoneType' object has no attribute 'get'
2019-08-05 13:50:39,405 - django.request - WARNING - Not Found: /set_task_status/
2019-08-05 14:03:03,973 - django.request - WARNING - Not Found: /search_project_tasks
2019-08-23 15:31:12,764 - django.request - ERROR - Internal Server Error: /index/
Traceback (most recent call last):
  File "D:\Program Files\python\lib\site-packages\django\contrib\sessions\backends\base.py", line 190, in _get_session
    return self._session_cache
AttributeError: 'SessionStore' object has no attribute '_session_cache'

During handling of the above exception, another exception occurred:

Traceback (most recent call last):
  File "D:\Program Files\python\lib\site-packages\pymysql\connections.py", line 916, in connect
    **kwargs)
  File "D:\Program Files\python\lib\socket.py", line 722, in create_connection
    raise err
  File "D:\Program Files\python\lib\socket.py", line 713, in create_connection
    sock.connect(sa)
ConnectionRefusedError: [WinError 10061] 由于目标计算机积极拒绝，无法连接。

During handling of the above exception, another exception occurred:

Traceback (most recent call last):
  File "D:\Program Files\python\lib\site-packages\django\db\backends\base\base.py", line 216, in ensure_connection
    self.connect()
  File "D:\Program Files\python\lib\site-packages\django\db\backends\base\base.py", line 194, in connect
    self.connection = self.get_new_connection(conn_params)
  File "D:\Program Files\python\lib\site-packages\django\db\backends\mysql\base.py", line 227, in get_new_connection
    return Database.connect(**conn_params)
  File "D:\Program Files\python\lib\site-packages\pymysql\__init__.py", line 90, in Connect
    return Connection(*args, **kwargs)
  File "D:\Program Files\python\lib\site-packages\pymysql\connections.py", line 706, in __init__
    self.connect()
  File "D:\Program Files\python\lib\site-packages\pymysql\connections.py", line 963, in connect
    raise exc
pymysql.err.OperationalError: (2003, "Can't connect to MySQL server on '127.0.0.1' ([WinError 10061] 由于目标计算机积极拒绝，无法连接。)")

The above exception was the direct cause of the following exception:

Traceback (most recent call last):
  File "D:\Program Files\python\lib\site-packages\django\core\handlers\exception.py", line 34, in inner
    response = get_response(request)
  File "D:\Program Files\python\lib\site-packages\django\core\handlers\base.py", line 126, in _get_response
    response = self.process_exception_by_middleware(e, request)
  File "D:\Program Files\python\lib\site-packages\django\core\handlers\base.py", line 124, in _get_response
    response = wrapped_callback(request, *callback_args, **callback_kwargs)
  File "D:\Program Files\python\lib\site-packages\django\contrib\auth\decorators.py", line 20, in _wrapped_view
    if test_func(request.user):
  File "D:\Program Files\python\lib\site-packages\django\contrib\auth\decorators.py", line 44, in <lambda>
    lambda u: u.is_authenticated,
  File "D:\Program Files\python\lib\site-packages\django\utils\functional.py", line 213, in inner
    self._setup()
  File "D:\Program Files\python\lib\site-packages\django\utils\functional.py", line 347, in _setup
    self._wrapped = self._setupfunc()
  File "D:\Program Files\python\lib\site-packages\django\contrib\auth\middleware.py", line 24, in <lambda>
    request.user = SimpleLazyObject(lambda: get_user(request))
  File "D:\Program Files\python\lib\site-packages\django\contrib\auth\middleware.py", line 12, in get_user
    request._cached_user = auth.get_user(request)
  File "D:\Program Files\python\lib\site-packages\django\contrib\auth\__init__.py", line 182, in get_user
    user_id = _get_user_session_key(request)
  File "D:\Program Files\python\lib\site-packages\django\contrib\auth\__init__.py", line 59, in _get_user_session_key
    return get_user_model()._meta.pk.to_python(request.session[SESSION_KEY])
  File "D:\Program Files\python\lib\site-packages\django\contrib\sessions\backends\base.py", line 55, in __getitem__
    return self._session[key]
  File "D:\Program Files\python\lib\site-packages\django\contrib\sessions\backends\base.py", line 195, in _get_session
    self._session_cache = self.load()
  File "D:\Program Files\python\lib\site-packages\django\contrib\sessions\backends\db.py", line 43, in load
    s = self._get_session_from_db()
  File "D:\Program Files\python\lib\site-packages\django\contrib\sessions\backends\db.py", line 34, in _get_session_from_db
    expire_date__gt=timezone.now()
  File "D:\Program Files\python\lib\site-packages\django\db\models\manager.py", line 82, in manager_method
    return getattr(self.get_queryset(), name)(*args, **kwargs)
  File "D:\Program Files\python\lib\site-packages\django\db\models\query.py", line 393, in get
    num = len(clone)
  File "D:\Program Files\python\lib\site-packages\django\db\models\query.py", line 250, in __len__
    self._fetch_all()
  File "D:\Program Files\python\lib\site-packages\django\db\models\query.py", line 1183, in _fetch_all
    self._result_cache = list(self._iterable_class(self))
  File "D:\Program Files\python\lib\site-packages\django\db\models\query.py", line 54, in __iter__
    results = compiler.execute_sql(chunked_fetch=self.chunked_fetch, chunk_size=self.chunk_size)
  File "D:\Program Files\python\lib\site-packages\django\db\models\sql\compiler.py", line 1059, in execute_sql
    cursor = self.connection.cursor()
  File "D:\Program Files\python\lib\site-packages\django\db\backends\base\base.py", line 255, in cursor
    return self._cursor()
  File "D:\Program Files\python\lib\site-packages\django\db\backends\base\base.py", line 232, in _cursor
    self.ensure_connection()
  File "D:\Program Files\python\lib\site-packages\django\db\backends\base\base.py", line 216, in ensure_connection
    self.connect()
  File "D:\Program Files\python\lib\site-packages\django\db\utils.py", line 89, in __exit__
    raise dj_exc_value.with_traceback(traceback) from exc_value
  File "D:\Program Files\python\lib\site-packages\django\db\backends\base\base.py", line 216, in ensure_connection
    self.connect()
  File "D:\Program Files\python\lib\site-packages\django\db\backends\base\base.py", line 194, in connect
    self.connection = self.get_new_connection(conn_params)
  File "D:\Program Files\python\lib\site-packages\django\db\backends\mysql\base.py", line 227, in get_new_connection
    return Database.connect(**conn_params)
  File "D:\Program Files\python\lib\site-packages\pymysql\__init__.py", line 90, in Connect
    return Connection(*args, **kwargs)
  File "D:\Program Files\python\lib\site-packages\pymysql\connections.py", line 706, in __init__
    self.connect()
  File "D:\Program Files\python\lib\site-packages\pymysql\connections.py", line 963, in connect
    raise exc
django.db.utils.OperationalError: (2003, "Can't connect to MySQL server on '127.0.0.1' ([WinError 10061] 由于目标计算机积极拒绝，无法连接。)")
2019-08-23 15:31:15,713 - django.request - ERROR - Internal Server Error: /project_env/21
Traceback (most recent call last):
  File "D:\Program Files\python\lib\site-packages\django\contrib\sessions\backends\base.py", line 190, in _get_session
    return self._session_cache
AttributeError: 'SessionStore' object has no attribute '_session_cache'

During handling of the above exception, another exception occurred:

Traceback (most recent call last):
  File "D:\Program Files\python\lib\site-packages\pymysql\connections.py", line 916, in connect
    **kwargs)
  File "D:\Program Files\python\lib\socket.py", line 722, in create_connection
    raise err
  File "D:\Program Files\python\lib\socket.py", line 713, in create_connection
    sock.connect(sa)
ConnectionRefusedError: [WinError 10061] 由于目标计算机积极拒绝，无法连接。

During handling of the above exception, another exception occurred:

Traceback (most recent call last):
  File "D:\Program Files\python\lib\site-packages\django\db\backends\base\base.py", line 216, in ensure_connection
    self.connect()
  File "D:\Program Files\python\lib\site-packages\django\db\backends\base\base.py", line 194, in connect
    self.connection = self.get_new_connection(conn_params)
  File "D:\Program Files\python\lib\site-packages\django\db\backends\mysql\base.py", line 227, in get_new_connection
    return Database.connect(**conn_params)
  File "D:\Program Files\python\lib\site-packages\pymysql\__init__.py", line 90, in Connect
    return Connection(*args, **kwargs)
  File "D:\Program Files\python\lib\site-packages\pymysql\connections.py", line 706, in __init__
    self.connect()
  File "D:\Program Files\python\lib\site-packages\pymysql\connections.py", line 963, in connect
    raise exc
pymysql.err.OperationalError: (2003, "Can't connect to MySQL server on '127.0.0.1' ([WinError 10061] 由于目标计算机积极拒绝，无法连接。)")

The above exception was the direct cause of the following exception:

Traceback (most recent call last):
  File "D:\Program Files\python\lib\site-packages\django\core\handlers\exception.py", line 34, in inner
    response = get_response(request)
  File "D:\Program Files\python\lib\site-packages\django\core\handlers\base.py", line 126, in _get_response
    response = self.process_exception_by_middleware(e, request)
  File "D:\Program Files\python\lib\site-packages\django\core\handlers\base.py", line 124, in _get_response
    response = wrapped_callback(request, *callback_args, **callback_kwargs)
  File "D:\Program Files\python\lib\site-packages\django\contrib\auth\decorators.py", line 20, in _wrapped_view
    if test_func(request.user):
  File "D:\Program Files\python\lib\site-packages\django\contrib\auth\decorators.py", line 44, in <lambda>
    lambda u: u.is_authenticated,
  File "D:\Program Files\python\lib\site-packages\django\utils\functional.py", line 213, in inner
    self._setup()
  File "D:\Program Files\python\lib\site-packages\django\utils\functional.py", line 347, in _setup
    self._wrapped = self._setupfunc()
  File "D:\Program Files\python\lib\site-packages\django\contrib\auth\middleware.py", line 24, in <lambda>
    request.user = SimpleLazyObject(lambda: get_user(request))
  File "D:\Program Files\python\lib\site-packages\django\contrib\auth\middleware.py", line 12, in get_user
    request._cached_user = auth.get_user(request)
  File "D:\Program Files\python\lib\site-packages\django\contrib\auth\__init__.py", line 182, in get_user
    user_id = _get_user_session_key(request)
  File "D:\Program Files\python\lib\site-packages\django\contrib\auth\__init__.py", line 59, in _get_user_session_key
    return get_user_model()._meta.pk.to_python(request.session[SESSION_KEY])
  File "D:\Program Files\python\lib\site-packages\django\contrib\sessions\backends\base.py", line 55, in __getitem__
    return self._session[key]
  File "D:\Program Files\python\lib\site-packages\django\contrib\sessions\backends\base.py", line 195, in _get_session
    self._session_cache = self.load()
  File "D:\Program Files\python\lib\site-packages\django\contrib\sessions\backends\db.py", line 43, in load
    s = self._get_session_from_db()
  File "D:\Program Files\python\lib\site-packages\django\contrib\sessions\backends\db.py", line 34, in _get_session_from_db
    expire_date__gt=timezone.now()
  File "D:\Program Files\python\lib\site-packages\django\db\models\manager.py", line 82, in manager_method
    return getattr(self.get_queryset(), name)(*args, **kwargs)
  File "D:\Program Files\python\lib\site-packages\django\db\models\query.py", line 393, in get
    num = len(clone)
  File "D:\Program Files\python\lib\site-packages\django\db\models\query.py", line 250, in __len__
    self._fetch_all()
  File "D:\Program Files\python\lib\site-packages\django\db\models\query.py", line 1183, in _fetch_all
    self._result_cache = list(self._iterable_class(self))
  File "D:\Program Files\python\lib\site-packages\django\db\models\query.py", line 54, in __iter__
    results = compiler.execute_sql(chunked_fetch=self.chunked_fetch, chunk_size=self.chunk_size)
  File "D:\Program Files\python\lib\site-packages\django\db\models\sql\compiler.py", line 1059, in execute_sql
    cursor = self.connection.cursor()
  File "D:\Program Files\python\lib\site-packages\django\db\backends\base\base.py", line 255, in cursor
    return self._cursor()
  File "D:\Program Files\python\lib\site-packages\django\db\backends\base\base.py", line 232, in _cursor
    self.ensure_connection()
  File "D:\Program Files\python\lib\site-packages\django\db\backends\base\base.py", line 216, in ensure_connection
    self.connect()
  File "D:\Program Files\python\lib\site-packages\django\db\utils.py", line 89, in __exit__
    raise dj_exc_value.with_traceback(traceback) from exc_value
  File "D:\Program Files\python\lib\site-packages\django\db\backends\base\base.py", line 216, in ensure_connection
    self.connect()
  File "D:\Program Files\python\lib\site-packages\django\db\backends\base\base.py", line 194, in connect
    self.connection = self.get_new_connection(conn_params)
  File "D:\Program Files\python\lib\site-packages\django\db\backends\mysql\base.py", line 227, in get_new_connection
    return Database.connect(**conn_params)
  File "D:\Program Files\python\lib\site-packages\pymysql\__init__.py", line 90, in Connect
    return Connection(*args, **kwargs)
  File "D:\Program Files\python\lib\site-packages\pymysql\connections.py", line 706, in __init__
    self.connect()
  File "D:\Program Files\python\lib\site-packages\pymysql\connections.py", line 963, in connect
    raise exc
django.db.utils.OperationalError: (2003, "Can't connect to MySQL server on '127.0.0.1' ([WinError 10061] 由于目标计算机积极拒绝，无法连接。)")
2019-08-23 15:31:17,198 - django.request - ERROR - Internal Server Error: /project_api/1
Traceback (most recent call last):
  File "D:\Program Files\python\lib\site-packages\django\contrib\sessions\backends\base.py", line 190, in _get_session
    return self._session_cache
AttributeError: 'SessionStore' object has no attribute '_session_cache'

During handling of the above exception, another exception occurred:

Traceback (most recent call last):
  File "D:\Program Files\python\lib\site-packages\pymysql\connections.py", line 916, in connect
    **kwargs)
  File "D:\Program Files\python\lib\socket.py", line 722, in create_connection
    raise err
  File "D:\Program Files\python\lib\socket.py", line 713, in create_connection
    sock.connect(sa)
ConnectionRefusedError: [WinError 10061] 由于目标计算机积极拒绝，无法连接。

During handling of the above exception, another exception occurred:

Traceback (most recent call last):
  File "D:\Program Files\python\lib\site-packages\django\db\backends\base\base.py", line 216, in ensure_connection
    self.connect()
  File "D:\Program Files\python\lib\site-packages\django\db\backends\base\base.py", line 194, in connect
    self.connection = self.get_new_connection(conn_params)
  File "D:\Program Files\python\lib\site-packages\django\db\backends\mysql\base.py", line 227, in get_new_connection
    return Database.connect(**conn_params)
  File "D:\Program Files\python\lib\site-packages\pymysql\__init__.py", line 90, in Connect
    return Connection(*args, **kwargs)
  File "D:\Program Files\python\lib\site-packages\pymysql\connections.py", line 706, in __init__
    self.connect()
  File "D:\Program Files\python\lib\site-packages\pymysql\connections.py", line 963, in connect
    raise exc
pymysql.err.OperationalError: (2003, "Can't connect to MySQL server on '127.0.0.1' ([WinError 10061] 由于目标计算机积极拒绝，无法连接。)")

The above exception was the direct cause of the following exception:

Traceback (most recent call last):
  File "D:\Program Files\python\lib\site-packages\django\core\handlers\exception.py", line 34, in inner
    response = get_response(request)
  File "D:\Program Files\python\lib\site-packages\django\core\handlers\base.py", line 126, in _get_response
    response = self.process_exception_by_middleware(e, request)
  File "D:\Program Files\python\lib\site-packages\django\core\handlers\base.py", line 124, in _get_response
    response = wrapped_callback(request, *callback_args, **callback_kwargs)
  File "D:\Program Files\python\lib\site-packages\django\contrib\auth\decorators.py", line 20, in _wrapped_view
    if test_func(request.user):
  File "D:\Program Files\python\lib\site-packages\django\contrib\auth\decorators.py", line 44, in <lambda>
    lambda u: u.is_authenticated,
  File "D:\Program Files\python\lib\site-packages\django\utils\functional.py", line 213, in inner
    self._setup()
  File "D:\Program Files\python\lib\site-packages\django\utils\functional.py", line 347, in _setup
    self._wrapped = self._setupfunc()
  File "D:\Program Files\python\lib\site-packages\django\contrib\auth\middleware.py", line 24, in <lambda>
    request.user = SimpleLazyObject(lambda: get_user(request))
  File "D:\Program Files\python\lib\site-packages\django\contrib\auth\middleware.py", line 12, in get_user
    request._cached_user = auth.get_user(request)
  File "D:\Program Files\python\lib\site-packages\django\contrib\auth\__init__.py", line 182, in get_user
    user_id = _get_user_session_key(request)
  File "D:\Program Files\python\lib\site-packages\django\contrib\auth\__init__.py", line 59, in _get_user_session_key
    return get_user_model()._meta.pk.to_python(request.session[SESSION_KEY])
  File "D:\Program Files\python\lib\site-packages\django\contrib\sessions\backends\base.py", line 55, in __getitem__
    return self._session[key]
  File "D:\Program Files\python\lib\site-packages\django\contrib\sessions\backends\base.py", line 195, in _get_session
    self._session_cache = self.load()
  File "D:\Program Files\python\lib\site-packages\django\contrib\sessions\backends\db.py", line 43, in load
    s = self._get_session_from_db()
  File "D:\Program Files\python\lib\site-packages\django\contrib\sessions\backends\db.py", line 34, in _get_session_from_db
    expire_date__gt=timezone.now()
  File "D:\Program Files\python\lib\site-packages\django\db\models\manager.py", line 82, in manager_method
    return getattr(self.get_queryset(), name)(*args, **kwargs)
  File "D:\Program Files\python\lib\site-packages\django\db\models\query.py", line 393, in get
    num = len(clone)
  File "D:\Program Files\python\lib\site-packages\django\db\models\query.py", line 250, in __len__
    self._fetch_all()
  File "D:\Program Files\python\lib\site-packages\django\db\models\query.py", line 1183, in _fetch_all
    self._result_cache = list(self._iterable_class(self))
  File "D:\Program Files\python\lib\site-packages\django\db\models\query.py", line 54, in __iter__
    results = compiler.execute_sql(chunked_fetch=self.chunked_fetch, chunk_size=self.chunk_size)
  File "D:\Program Files\python\lib\site-packages\django\db\models\sql\compiler.py", line 1059, in execute_sql
    cursor = self.connection.cursor()
  File "D:\Program Files\python\lib\site-packages\django\db\backends\base\base.py", line 255, in cursor
    return self._cursor()
  File "D:\Program Files\python\lib\site-packages\django\db\backends\base\base.py", line 232, in _cursor
    self.ensure_connection()
  File "D:\Program Files\python\lib\site-packages\django\db\backends\base\base.py", line 216, in ensure_connection
    self.connect()
  File "D:\Program Files\python\lib\site-packages\django\db\utils.py", line 89, in __exit__
    raise dj_exc_value.with_traceback(traceback) from exc_value
  File "D:\Program Files\python\lib\site-packages\django\db\backends\base\base.py", line 216, in ensure_connection
    self.connect()
  File "D:\Program Files\python\lib\site-packages\django\db\backends\base\base.py", line 194, in connect
    self.connection = self.get_new_connection(conn_params)
  File "D:\Program Files\python\lib\site-packages\django\db\backends\mysql\base.py", line 227, in get_new_connection
    return Database.connect(**conn_params)
  File "D:\Program Files\python\lib\site-packages\pymysql\__init__.py", line 90, in Connect
    return Connection(*args, **kwargs)
  File "D:\Program Files\python\lib\site-packages\pymysql\connections.py", line 706, in __init__
    self.connect()
  File "D:\Program Files\python\lib\site-packages\pymysql\connections.py", line 963, in connect
    raise exc
django.db.utils.OperationalError: (2003, "Can't connect to MySQL server on '127.0.0.1' ([WinError 10061] 由于目标计算机积极拒绝，无法连接。)")
2019-08-23 15:31:17,796 - django.request - ERROR - Internal Server Error: /project_case/1
Traceback (most recent call last):
  File "D:\Program Files\python\lib\site-packages\django\contrib\sessions\backends\base.py", line 190, in _get_session
    return self._session_cache
AttributeError: 'SessionStore' object has no attribute '_session_cache'

During handling of the above exception, another exception occurred:

Traceback (most recent call last):
  File "D:\Program Files\python\lib\site-packages\pymysql\connections.py", line 916, in connect
    **kwargs)
  File "D:\Program Files\python\lib\socket.py", line 722, in create_connection
    raise err
  File "D:\Program Files\python\lib\socket.py", line 713, in create_connection
    sock.connect(sa)
ConnectionRefusedError: [WinError 10061] 由于目标计算机积极拒绝，无法连接。

During handling of the above exception, another exception occurred:

Traceback (most recent call last):
  File "D:\Program Files\python\lib\site-packages\django\db\backends\base\base.py", line 216, in ensure_connection
    self.connect()
  File "D:\Program Files\python\lib\site-packages\django\db\backends\base\base.py", line 194, in connect
    self.connection = self.get_new_connection(conn_params)
  File "D:\Program Files\python\lib\site-packages\django\db\backends\mysql\base.py", line 227, in get_new_connection
    return Database.connect(**conn_params)
  File "D:\Program Files\python\lib\site-packages\pymysql\__init__.py", line 90, in Connect
    return Connection(*args, **kwargs)
  File "D:\Program Files\python\lib\site-packages\pymysql\connections.py", line 706, in __init__
    self.connect()
  File "D:\Program Files\python\lib\site-packages\pymysql\connections.py", line 963, in connect
    raise exc
pymysql.err.OperationalError: (2003, "Can't connect to MySQL server on '127.0.0.1' ([WinError 10061] 由于目标计算机积极拒绝，无法连接。)")

The above exception was the direct cause of the following exception:

Traceback (most recent call last):
  File "D:\Program Files\python\lib\site-packages\django\core\handlers\exception.py", line 34, in inner
    response = get_response(request)
  File "D:\Program Files\python\lib\site-packages\django\core\handlers\base.py", line 126, in _get_response
    response = self.process_exception_by_middleware(e, request)
  File "D:\Program Files\python\lib\site-packages\django\core\handlers\base.py", line 124, in _get_response
    response = wrapped_callback(request, *callback_args, **callback_kwargs)
  File "D:\Program Files\python\lib\site-packages\django\contrib\auth\decorators.py", line 20, in _wrapped_view
    if test_func(request.user):
  File "D:\Program Files\python\lib\site-packages\django\contrib\auth\decorators.py", line 44, in <lambda>
    lambda u: u.is_authenticated,
  File "D:\Program Files\python\lib\site-packages\django\utils\functional.py", line 213, in inner
    self._setup()
  File "D:\Program Files\python\lib\site-packages\django\utils\functional.py", line 347, in _setup
    self._wrapped = self._setupfunc()
  File "D:\Program Files\python\lib\site-packages\django\contrib\auth\middleware.py", line 24, in <lambda>
    request.user = SimpleLazyObject(lambda: get_user(request))
  File "D:\Program Files\python\lib\site-packages\django\contrib\auth\middleware.py", line 12, in get_user
    request._cached_user = auth.get_user(request)
  File "D:\Program Files\python\lib\site-packages\django\contrib\auth\__init__.py", line 182, in get_user
    user_id = _get_user_session_key(request)
  File "D:\Program Files\python\lib\site-packages\django\contrib\auth\__init__.py", line 59, in _get_user_session_key
    return get_user_model()._meta.pk.to_python(request.session[SESSION_KEY])
  File "D:\Program Files\python\lib\site-packages\django\contrib\sessions\backends\base.py", line 55, in __getitem__
    return self._session[key]
  File "D:\Program Files\python\lib\site-packages\django\contrib\sessions\backends\base.py", line 195, in _get_session
    self._session_cache = self.load()
  File "D:\Program Files\python\lib\site-packages\django\contrib\sessions\backends\db.py", line 43, in load
    s = self._get_session_from_db()
  File "D:\Program Files\python\lib\site-packages\django\contrib\sessions\backends\db.py", line 34, in _get_session_from_db
    expire_date__gt=timezone.now()
  File "D:\Program Files\python\lib\site-packages\django\db\models\manager.py", line 82, in manager_method
    return getattr(self.get_queryset(), name)(*args, **kwargs)
  File "D:\Program Files\python\lib\site-packages\django\db\models\query.py", line 393, in get
    num = len(clone)
  File "D:\Program Files\python\lib\site-packages\django\db\models\query.py", line 250, in __len__
    self._fetch_all()
  File "D:\Program Files\python\lib\site-packages\django\db\models\query.py", line 1183, in _fetch_all
    self._result_cache = list(self._iterable_class(self))
  File "D:\Program Files\python\lib\site-packages\django\db\models\query.py", line 54, in __iter__
    results = compiler.execute_sql(chunked_fetch=self.chunked_fetch, chunk_size=self.chunk_size)
  File "D:\Program Files\python\lib\site-packages\django\db\models\sql\compiler.py", line 1059, in execute_sql
    cursor = self.connection.cursor()
  File "D:\Program Files\python\lib\site-packages\django\db\backends\base\base.py", line 255, in cursor
    return self._cursor()
  File "D:\Program Files\python\lib\site-packages\django\db\backends\base\base.py", line 232, in _cursor
    self.ensure_connection()
  File "D:\Program Files\python\lib\site-packages\django\db\backends\base\base.py", line 216, in ensure_connection
    self.connect()
  File "D:\Program Files\python\lib\site-packages\django\db\utils.py", line 89, in __exit__
    raise dj_exc_value.with_traceback(traceback) from exc_value
  File "D:\Program Files\python\lib\site-packages\django\db\backends\base\base.py", line 216, in ensure_connection
    self.connect()
  File "D:\Program Files\python\lib\site-packages\django\db\backends\base\base.py", line 194, in connect
    self.connection = self.get_new_connection(conn_params)
  File "D:\Program Files\python\lib\site-packages\django\db\backends\mysql\base.py", line 227, in get_new_connection
    return Database.connect(**conn_params)
  File "D:\Program Files\python\lib\site-packages\pymysql\__init__.py", line 90, in Connect
    return Connection(*args, **kwargs)
  File "D:\Program Files\python\lib\site-packages\pymysql\connections.py", line 706, in __init__
    self.connect()
  File "D:\Program Files\python\lib\site-packages\pymysql\connections.py", line 963, in connect
    raise exc
django.db.utils.OperationalError: (2003, "Can't connect to MySQL server on '127.0.0.1' ([WinError 10061] 由于目标计算机积极拒绝，无法连接。)")
2019-08-23 15:31:27,540 - django.request - ERROR - Internal Server Error: /project_env/1
Traceback (most recent call last):
  File "D:\Program Files\python\lib\site-packages\django\contrib\sessions\backends\base.py", line 190, in _get_session
    return self._session_cache
AttributeError: 'SessionStore' object has no attribute '_session_cache'

During handling of the above exception, another exception occurred:

Traceback (most recent call last):
  File "D:\Program Files\python\lib\site-packages\pymysql\connections.py", line 916, in connect
    **kwargs)
  File "D:\Program Files\python\lib\socket.py", line 722, in create_connection
    raise err
  File "D:\Program Files\python\lib\socket.py", line 713, in create_connection
    sock.connect(sa)
ConnectionRefusedError: [WinError 10061] 由于目标计算机积极拒绝，无法连接。

During handling of the above exception, another exception occurred:

Traceback (most recent call last):
  File "D:\Program Files\python\lib\site-packages\django\db\backends\base\base.py", line 216, in ensure_connection
    self.connect()
  File "D:\Program Files\python\lib\site-packages\django\db\backends\base\base.py", line 194, in connect
    self.connection = self.get_new_connection(conn_params)
  File "D:\Program Files\python\lib\site-packages\django\db\backends\mysql\base.py", line 227, in get_new_connection
    return Database.connect(**conn_params)
  File "D:\Program Files\python\lib\site-packages\pymysql\__init__.py", line 90, in Connect
    return Connection(*args, **kwargs)
  File "D:\Program Files\python\lib\site-packages\pymysql\connections.py", line 706, in __init__
    self.connect()
  File "D:\Program Files\python\lib\site-packages\pymysql\connections.py", line 963, in connect
    raise exc
pymysql.err.OperationalError: (2003, "Can't connect to MySQL server on '127.0.0.1' ([WinError 10061] 由于目标计算机积极拒绝，无法连接。)")

The above exception was the direct cause of the following exception:

Traceback (most recent call last):
  File "D:\Program Files\python\lib\site-packages\django\core\handlers\exception.py", line 34, in inner
    response = get_response(request)
  File "D:\Program Files\python\lib\site-packages\django\core\handlers\base.py", line 126, in _get_response
    response = self.process_exception_by_middleware(e, request)
  File "D:\Program Files\python\lib\site-packages\django\core\handlers\base.py", line 124, in _get_response
    response = wrapped_callback(request, *callback_args, **callback_kwargs)
  File "D:\Program Files\python\lib\site-packages\django\contrib\auth\decorators.py", line 20, in _wrapped_view
    if test_func(request.user):
  File "D:\Program Files\python\lib\site-packages\django\contrib\auth\decorators.py", line 44, in <lambda>
    lambda u: u.is_authenticated,
  File "D:\Program Files\python\lib\site-packages\django\utils\functional.py", line 213, in inner
    self._setup()
  File "D:\Program Files\python\lib\site-packages\django\utils\functional.py", line 347, in _setup
    self._wrapped = self._setupfunc()
  File "D:\Program Files\python\lib\site-packages\django\contrib\auth\middleware.py", line 24, in <lambda>
    request.user = SimpleLazyObject(lambda: get_user(request))
  File "D:\Program Files\python\lib\site-packages\django\contrib\auth\middleware.py", line 12, in get_user
    request._cached_user = auth.get_user(request)
  File "D:\Program Files\python\lib\site-packages\django\contrib\auth\__init__.py", line 182, in get_user
    user_id = _get_user_session_key(request)
  File "D:\Program Files\python\lib\site-packages\django\contrib\auth\__init__.py", line 59, in _get_user_session_key
    return get_user_model()._meta.pk.to_python(request.session[SESSION_KEY])
  File "D:\Program Files\python\lib\site-packages\django\contrib\sessions\backends\base.py", line 55, in __getitem__
    return self._session[key]
  File "D:\Program Files\python\lib\site-packages\django\contrib\sessions\backends\base.py", line 195, in _get_session
    self._session_cache = self.load()
  File "D:\Program Files\python\lib\site-packages\django\contrib\sessions\backends\db.py", line 43, in load
    s = self._get_session_from_db()
  File "D:\Program Files\python\lib\site-packages\django\contrib\sessions\backends\db.py", line 34, in _get_session_from_db
    expire_date__gt=timezone.now()
  File "D:\Program Files\python\lib\site-packages\django\db\models\manager.py", line 82, in manager_method
    return getattr(self.get_queryset(), name)(*args, **kwargs)
  File "D:\Program Files\python\lib\site-packages\django\db\models\query.py", line 393, in get
    num = len(clone)
  File "D:\Program Files\python\lib\site-packages\django\db\models\query.py", line 250, in __len__
    self._fetch_all()
  File "D:\Program Files\python\lib\site-packages\django\db\models\query.py", line 1183, in _fetch_all
    self._result_cache = list(self._iterable_class(self))
  File "D:\Program Files\python\lib\site-packages\django\db\models\query.py", line 54, in __iter__
    results = compiler.execute_sql(chunked_fetch=self.chunked_fetch, chunk_size=self.chunk_size)
  File "D:\Program Files\python\lib\site-packages\django\db\models\sql\compiler.py", line 1059, in execute_sql
    cursor = self.connection.cursor()
  File "D:\Program Files\python\lib\site-packages\django\db\backends\base\base.py", line 255, in cursor
    return self._cursor()
  File "D:\Program Files\python\lib\site-packages\django\db\backends\base\base.py", line 232, in _cursor
    self.ensure_connection()
  File "D:\Program Files\python\lib\site-packages\django\db\backends\base\base.py", line 216, in ensure_connection
    self.connect()
  File "D:\Program Files\python\lib\site-packages\django\db\utils.py", line 89, in __exit__
    raise dj_exc_value.with_traceback(traceback) from exc_value
  File "D:\Program Files\python\lib\site-packages\django\db\backends\base\base.py", line 216, in ensure_connection
    self.connect()
  File "D:\Program Files\python\lib\site-packages\django\db\backends\base\base.py", line 194, in connect
    self.connection = self.get_new_connection(conn_params)
  File "D:\Program Files\python\lib\site-packages\django\db\backends\mysql\base.py", line 227, in get_new_connection
    return Database.connect(**conn_params)
  File "D:\Program Files\python\lib\site-packages\pymysql\__init__.py", line 90, in Connect
    return Connection(*args, **kwargs)
  File "D:\Program Files\python\lib\site-packages\pymysql\connections.py", line 706, in __init__
    self.connect()
  File "D:\Program Files\python\lib\site-packages\pymysql\connections.py", line 963, in connect
    raise exc
django.db.utils.OperationalError: (2003, "Can't connect to MySQL server on '127.0.0.1' ([WinError 10061] 由于目标计算机积极拒绝，无法连接。)")
2019-09-04 13:22:56,463 - django.request - WARNING - Not Found: /get_task_api_list
2019-09-04 13:56:37,245 - django.request - WARNING - Not Found: /get_task_api_list
2019-09-04 13:56:49,188 - django.request - WARNING - Not Found: /set_task_status/
2019-09-04 13:56:53,035 - django.request - WARNING - Not Found: /set_task_status/
2019-09-04 13:56:54,461 - django.request - WARNING - Not Found: /get_project_task
2019-09-04 13:57:33,519 - django.request - WARNING - Not Found: /get_task_api_list
2019-09-04 13:57:35,604 - django.request - WARNING - Not Found: /add_project_task
2019-09-04 13:57:40,050 - django.request - WARNING - Not Found: /add_project_task
2019-09-04 13:57:41,186 - django.request - WARNING - Not Found: /add_project_task
2019-09-04 13:58:19,023 - django.request - ERROR - Internal Server Error: /project_task/1
Traceback (most recent call last):
  File "D:\Program Files\python\lib\site-packages\django\contrib\sessions\backends\base.py", line 190, in _get_session
    return self._session_cache
AttributeError: 'SessionStore' object has no attribute '_session_cache'

During handling of the above exception, another exception occurred:

Traceback (most recent call last):
  File "D:\Program Files\python\lib\site-packages\pymysql\connections.py", line 916, in connect
    **kwargs)
  File "D:\Program Files\python\lib\socket.py", line 722, in create_connection
    raise err
  File "D:\Program Files\python\lib\socket.py", line 713, in create_connection
    sock.connect(sa)
ConnectionRefusedError: [WinError 10061] 由于目标计算机积极拒绝，无法连接。

During handling of the above exception, another exception occurred:

Traceback (most recent call last):
  File "D:\Program Files\python\lib\site-packages\django\db\backends\base\base.py", line 216, in ensure_connection
    self.connect()
  File "D:\Program Files\python\lib\site-packages\django\db\backends\base\base.py", line 194, in connect
    self.connection = self.get_new_connection(conn_params)
  File "D:\Program Files\python\lib\site-packages\django\db\backends\mysql\base.py", line 227, in get_new_connection
    return Database.connect(**conn_params)
  File "D:\Program Files\python\lib\site-packages\pymysql\__init__.py", line 90, in Connect
    return Connection(*args, **kwargs)
  File "D:\Program Files\python\lib\site-packages\pymysql\connections.py", line 706, in __init__
    self.connect()
  File "D:\Program Files\python\lib\site-packages\pymysql\connections.py", line 963, in connect
    raise exc
pymysql.err.OperationalError: (2003, "Can't connect to MySQL server on '127.0.0.1' ([WinError 10061] 由于目标计算机积极拒绝，无法连接。)")

The above exception was the direct cause of the following exception:

Traceback (most recent call last):
  File "D:\Program Files\python\lib\site-packages\django\core\handlers\exception.py", line 34, in inner
    response = get_response(request)
  File "D:\Program Files\python\lib\site-packages\django\core\handlers\base.py", line 126, in _get_response
    response = self.process_exception_by_middleware(e, request)
  File "D:\Program Files\python\lib\site-packages\django\core\handlers\base.py", line 124, in _get_response
    response = wrapped_callback(request, *callback_args, **callback_kwargs)
  File "D:\Program Files\python\lib\site-packages\django\contrib\auth\decorators.py", line 20, in _wrapped_view
    if test_func(request.user):
  File "D:\Program Files\python\lib\site-packages\django\contrib\auth\decorators.py", line 44, in <lambda>
    lambda u: u.is_authenticated,
  File "D:\Program Files\python\lib\site-packages\django\utils\functional.py", line 213, in inner
    self._setup()
  File "D:\Program Files\python\lib\site-packages\django\utils\functional.py", line 347, in _setup
    self._wrapped = self._setupfunc()
  File "D:\Program Files\python\lib\site-packages\django\contrib\auth\middleware.py", line 24, in <lambda>
    request.user = SimpleLazyObject(lambda: get_user(request))
  File "D:\Program Files\python\lib\site-packages\django\contrib\auth\middleware.py", line 12, in get_user
    request._cached_user = auth.get_user(request)
  File "D:\Program Files\python\lib\site-packages\django\contrib\auth\__init__.py", line 182, in get_user
    user_id = _get_user_session_key(request)
  File "D:\Program Files\python\lib\site-packages\django\contrib\auth\__init__.py", line 59, in _get_user_session_key
    return get_user_model()._meta.pk.to_python(request.session[SESSION_KEY])
  File "D:\Program Files\python\lib\site-packages\django\contrib\sessions\backends\base.py", line 55, in __getitem__
    return self._session[key]
  File "D:\Program Files\python\lib\site-packages\django\contrib\sessions\backends\base.py", line 195, in _get_session
    self._session_cache = self.load()
  File "D:\Program Files\python\lib\site-packages\django\contrib\sessions\backends\db.py", line 43, in load
    s = self._get_session_from_db()
  File "D:\Program Files\python\lib\site-packages\django\contrib\sessions\backends\db.py", line 34, in _get_session_from_db
    expire_date__gt=timezone.now()
  File "D:\Program Files\python\lib\site-packages\django\db\models\manager.py", line 82, in manager_method
    return getattr(self.get_queryset(), name)(*args, **kwargs)
  File "D:\Program Files\python\lib\site-packages\django\db\models\query.py", line 393, in get
    num = len(clone)
  File "D:\Program Files\python\lib\site-packages\django\db\models\query.py", line 250, in __len__
    self._fetch_all()
  File "D:\Program Files\python\lib\site-packages\django\db\models\query.py", line 1183, in _fetch_all
    self._result_cache = list(self._iterable_class(self))
  File "D:\Program Files\python\lib\site-packages\django\db\models\query.py", line 54, in __iter__
    results = compiler.execute_sql(chunked_fetch=self.chunked_fetch, chunk_size=self.chunk_size)
  File "D:\Program Files\python\lib\site-packages\django\db\models\sql\compiler.py", line 1059, in execute_sql
    cursor = self.connection.cursor()
  File "D:\Program Files\python\lib\site-packages\django\db\backends\base\base.py", line 255, in cursor
    return self._cursor()
  File "D:\Program Files\python\lib\site-packages\django\db\backends\base\base.py", line 232, in _cursor
    self.ensure_connection()
  File "D:\Program Files\python\lib\site-packages\django\db\backends\base\base.py", line 216, in ensure_connection
    self.connect()
  File "D:\Program Files\python\lib\site-packages\django\db\utils.py", line 89, in __exit__
    raise dj_exc_value.with_traceback(traceback) from exc_value
  File "D:\Program Files\python\lib\site-packages\django\db\backends\base\base.py", line 216, in ensure_connection
    self.connect()
  File "D:\Program Files\python\lib\site-packages\django\db\backends\base\base.py", line 194, in connect
    self.connection = self.get_new_connection(conn_params)
  File "D:\Program Files\python\lib\site-packages\django\db\backends\mysql\base.py", line 227, in get_new_connection
    return Database.connect(**conn_params)
  File "D:\Program Files\python\lib\site-packages\pymysql\__init__.py", line 90, in Connect
    return Connection(*args, **kwargs)
  File "D:\Program Files\python\lib\site-packages\pymysql\connections.py", line 706, in __init__
    self.connect()
  File "D:\Program Files\python\lib\site-packages\pymysql\connections.py", line 963, in connect
    raise exc
django.db.utils.OperationalError: (2003, "Can't connect to MySQL server on '127.0.0.1' ([WinError 10061] 由于目标计算机积极拒绝，无法连接。)")
2019-09-05 13:22:24,264 - log - INFO - click ok
2019-09-05 13:22:31,355 - log - ERROR - 获取园区和rs服务器数据时退出页面
2019-09-05 16:55:17,946 - django.request - WARNING - Not Found: /selectApiEnvName/
2019-09-05 17:16:26,974 - django.request - WARNING - Not Found: /selectApiEnvName/
2019-09-05 17:17:28,589 - django.request - WARNING - Not Found: /selectApiEnvName/
2019-09-05 17:18:45,597 - django.request - WARNING - Not Found: /selectApiEnvName/
2019-09-05 17:23:31,254 - django.request - WARNING - Not Found: /selectApiEnvName/
2019-09-05 17:24:57,265 - django.request - WARNING - Not Found: /selectApiEnvName/
2019-09-05 18:13:46,227 - django.request - WARNING - Not Found: /selectApiEnvName/
2019-09-05 18:13:48,530 - django.request - WARNING - Not Found: /selectApiEnvName/
2019-09-05 18:13:51,949 - django.request - WARNING - Not Found: /selectApiEnvName/
2019-09-05 18:26:50,610 - django.request - WARNING - Not Found: /selectApiEnvName/
2019-09-05 18:46:22,345 - django.request - WARNING - Not Found: /selectApiEnvName/
2019-09-05 18:46:36,921 - django.request - WARNING - Not Found: /selectApiEnvName/
2019-09-05 18:46:57,376 - django.request - WARNING - Not Found: /selectApiEnvName/
2019-09-05 18:46:58,885 - django.request - WARNING - Not Found: /selectApiEnvName/
2019-09-05 18:48:49,786 - django.request - WARNING - Not Found: /selectApiEnvName/
2019-09-05 18:51:05,867 - django.request - WARNING - Not Found: /selectApiEnvName/
2019-09-05 18:54:13,122 - django.request - WARNING - Not Found: /selectApiEnvName/
2019-09-05 18:54:59,415 - django.request - WARNING - Not Found: /selectApiEnvName/
2019-09-05 18:55:04,938 - django.request - WARNING - Not Found: /selectApiEnvName/
2019-09-05 18:56:33,023 - django.request - WARNING - Not Found: /selectApiEnvName/
2019-09-05 18:59:06,586 - django.request - WARNING - Not Found: /selectApiEnvName/
2019-09-05 19:22:32,422 - django.request - WARNING - Not Found: /get_task_cases
2019-09-05 19:22:32,437 - django.request - WARNING - Not Found: /selectApiEnvName/
2019-09-05 19:23:39,964 - django.request - WARNING - Not Found: /get_task_cases
2019-09-05 19:23:39,990 - django.request - WARNING - Not Found: /selectApiEnvName/
2019-09-05 19:23:49,892 - django.request - WARNING - Not Found: /get_task_cases
2019-09-05 19:23:49,906 - django.request - WARNING - Not Found: /selectApiEnvName/
2019-09-05 19:23:50,597 - django.request - WARNING - Not Found: /get_task_cases
2019-09-05 19:23:50,610 - django.request - WARNING - Not Found: /selectApiEnvName/
2019-09-05 19:23:51,307 - django.request - WARNING - Not Found: /get_task_cases
2019-09-05 19:23:51,317 - django.request - WARNING - Not Found: /selectApiEnvName/
2019-09-05 19:23:51,983 - django.request - WARNING - Not Found: /get_task_cases
2019-09-05 19:23:51,994 - django.request - WARNING - Not Found: /selectApiEnvName/
2019-09-05 19:23:52,629 - django.request - WARNING - Not Found: /get_task_cases
2019-09-05 19:23:52,642 - django.request - WARNING - Not Found: /selectApiEnvName/
2019-09-05 19:23:53,224 - django.request - WARNING - Not Found: /get_task_cases
2019-09-05 19:23:53,233 - django.request - WARNING - Not Found: /selectApiEnvName/
2019-09-05 19:23:53,863 - django.request - WARNING - Not Found: /get_task_cases
2019-09-05 19:23:53,876 - django.request - WARNING - Not Found: /selectApiEnvName/
2019-09-05 19:23:54,392 - django.request - WARNING - Not Found: /get_task_cases
2019-09-05 19:23:54,401 - django.request - WARNING - Not Found: /selectApiEnvName/
2019-09-05 19:23:55,023 - django.request - WARNING - Not Found: /get_task_cases
2019-09-05 19:23:55,035 - django.request - WARNING - Not Found: /selectApiEnvName/
2019-09-05 19:23:55,810 - django.request - WARNING - Not Found: /get_task_cases
2019-09-05 19:23:55,819 - django.request - WARNING - Not Found: /selectApiEnvName/
2019-09-05 19:23:56,332 - django.request - WARNING - Not Found: /get_task_cases
2019-09-05 19:23:56,342 - django.request - WARNING - Not Found: /selectApiEnvName/
2019-09-05 19:23:56,990 - django.request - WARNING - Not Found: /get_task_cases
2019-09-05 19:23:57,015 - django.request - WARNING - Not Found: /selectApiEnvName/
2019-09-05 19:23:57,766 - django.request - WARNING - Not Found: /get_task_cases
2019-09-05 19:23:57,776 - django.request - WARNING - Not Found: /selectApiEnvName/
2019-09-05 19:23:58,557 - django.request - WARNING - Not Found: /get_task_cases
2019-09-05 19:23:58,571 - django.request - WARNING - Not Found: /selectApiEnvName/
2019-09-05 19:23:59,247 - django.request - WARNING - Not Found: /get_task_cases
2019-09-05 19:23:59,258 - django.request - WARNING - Not Found: /selectApiEnvName/
2019-09-05 19:24:00,020 - django.request - WARNING - Not Found: /get_task_cases
2019-09-05 19:24:00,031 - django.request - WARNING - Not Found: /selectApiEnvName/
2019-09-05 19:24:00,626 - django.request - WARNING - Not Found: /get_task_cases
2019-09-05 19:24:00,634 - django.request - WARNING - Not Found: /selectApiEnvName/
2019-09-05 19:25:51,985 - django.request - WARNING - Not Found: /get_task_cases
2019-09-05 19:25:51,996 - django.request - WARNING - Not Found: /selectApiEnvName/
2019-09-05 21:01:42,974 - django.request - WARNING - Not Found: /get_task_cases
2019-09-05 21:01:42,990 - django.request - WARNING - Not Found: /selectApiEnvName/
2019-09-05 21:01:50,877 - django.request - WARNING - Not Found: /get_task_cases
2019-09-05 21:01:50,891 - django.request - WARNING - Not Found: /selectApiEnvName/
2019-09-05 21:01:52,879 - django.request - WARNING - Not Found: /get_task_cases
2019-09-05 21:01:52,897 - django.request - WARNING - Not Found: /selectApiEnvName/
2019-09-05 21:03:12,792 - django.request - WARNING - Not Found: /get_task_cases
2019-09-05 21:03:12,796 - django.request - WARNING - Not Found: /selectApiEnvName/
2019-09-05 21:05:29,762 - django.request - WARNING - Not Found: /get_task_cases
2019-09-05 21:05:29,778 - django.request - WARNING - Not Found: /selectApiEnvName/
2019-09-05 21:05:37,352 - django.request - WARNING - Not Found: /get_task_cases
2019-09-05 21:05:37,364 - django.request - WARNING - Not Found: /selectApiEnvName/
2019-09-05 21:06:50,592 - django.request - WARNING - Not Found: /get_task_cases
2019-09-05 21:06:50,610 - django.request - WARNING - Not Found: /selectApiEnvName/
2019-09-05 21:07:23,780 - django.request - WARNING - Not Found: /get_task_cases
2019-09-05 21:07:23,794 - django.request - WARNING - Not Found: /selectApiEnvName/
2019-09-05 21:07:41,567 - django.request - WARNING - Not Found: /get_task_cases
2019-09-05 21:07:41,579 - django.request - WARNING - Not Found: /selectApiEnvName/
2019-09-05 21:08:39,868 - django.request - WARNING - Not Found: /get_task_cases
2019-09-05 21:08:39,884 - django.request - WARNING - Not Found: /selectApiEnvName/
2019-09-05 21:08:53,662 - django.request - WARNING - Not Found: /get_task_cases
2019-09-05 21:08:53,682 - django.request - WARNING - Not Found: /selectApiEnvName/
2019-09-05 21:09:09,545 - django.request - WARNING - Not Found: /get_task_cases
2019-09-05 21:09:09,561 - django.request - WARNING - Not Found: /selectApiEnvName/
2019-09-05 21:09:48,931 - django.request - WARNING - Not Found: /get_task_cases
2019-09-05 21:09:48,949 - django.request - WARNING - Not Found: /selectApiEnvName/
2019-09-05 21:10:20,588 - django.request - WARNING - Not Found: /get_task_cases
2019-09-05 21:10:20,606 - django.request - WARNING - Not Found: /selectApiEnvName/
2019-09-05 21:10:56,144 - django.request - WARNING - Not Found: /get_task_cases
2019-09-05 21:10:56,159 - django.request - WARNING - Not Found: /selectApiEnvName/
2019-09-05 21:10:56,921 - django.request - WARNING - Not Found: /project_task/
2019-09-05 21:11:09,642 - django.request - WARNING - Not Found: /get_task_cases
2019-09-05 21:11:09,654 - django.request - WARNING - Not Found: /selectApiEnvName/
2019-09-05 21:11:25,716 - django.request - WARNING - Not Found: /get_task_cases
2019-09-05 21:11:25,721 - django.request - WARNING - Not Found: /selectApiEnvName/
2019-09-05 21:11:27,032 - django.request - WARNING - Not Found: /project_task//
2019-09-05 21:12:38,046 - django.request - WARNING - Not Found: /get_task_cases
2019-09-05 21:12:38,065 - django.request - WARNING - Not Found: /selectApiEnvName/
2019-09-05 21:12:38,514 - django.request - WARNING - Not Found: /project_task//
2019-09-05 21:12:41,465 - django.request - WARNING - Not Found: /get_task_cases
2019-09-05 21:12:41,469 - django.request - WARNING - Not Found: /selectApiEnvName/
2019-09-05 21:12:45,137 - django.request - WARNING - Not Found: /get_task_cases
2019-09-05 21:12:45,152 - django.request - WARNING - Not Found: /selectApiEnvName/
2019-09-05 21:15:30,873 - django.request - WARNING - Not Found: /get_task_cases
2019-09-05 21:15:30,875 - django.request - WARNING - Not Found: /selectApiEnvName/
2019-09-05 21:15:36,098 - django.request - WARNING - Not Found: /get_task_cases
2019-09-05 21:15:36,109 - django.request - WARNING - Not Found: /selectApiEnvName/
2019-09-05 21:16:38,739 - django.request - WARNING - Not Found: /get_task_cases
2019-09-05 21:16:38,746 - django.request - WARNING - Not Found: /selectApiEnvName/
2019-09-05 21:18:52,493 - django.request - WARNING - Not Found: /get_task_cases
2019-09-05 21:18:52,617 - django.request - WARNING - Not Found: /selectApiEnvName/
2019-09-05 21:29:08,707 - django.request - WARNING - Not Found: /selectApiEnvName/
2019-09-05 21:30:29,628 - django.request - WARNING - Not Found: /selectApiEnvName/
2019-09-05 21:30:31,301 - django.request - WARNING - Not Found: /selectApiEnvName/
2019-09-05 21:30:31,909 - django.request - WARNING - Not Found: /selectApiEnvName/
2019-09-05 21:30:32,290 - django.request - WARNING - Not Found: /selectApiEnvName/
2019-09-05 21:30:32,491 - django.request - WARNING - Not Found: /selectApiEnvName/
2019-09-05 21:30:32,658 - django.request - WARNING - Not Found: /selectApiEnvName/
2019-09-05 22:31:29,421 - django.request - ERROR - Internal Server Error: /add_project_task
Traceback (most recent call last):
  File "D:\Program Files\python\lib\site-packages\django\core\handlers\exception.py", line 34, in inner
    response = get_response(request)
  File "D:\Program Files\python\lib\site-packages\django\core\handlers\base.py", line 126, in _get_response
    response = self.process_exception_by_middleware(e, request)
  File "D:\Program Files\python\lib\site-packages\django\core\handlers\base.py", line 124, in _get_response
    response = wrapped_callback(request, *callback_args, **callback_kwargs)
  File "D:\Program Files\python\lib\site-packages\django\contrib\auth\decorators.py", line 21, in _wrapped_view
    return view_func(request, *args, **kwargs)
  File "D:\Program Files\python\lib\site-packages\django\views\decorators\http.py", line 40, in inner
    return func(request, *args, **kwargs)
  File "D:\Program Files\IAM\api\views.py", line 1100, in add_project_task
    task_name = task_data.get("project-task-add-name", "")
AttributeError: 'str' object has no attribute 'get'
2019-09-05 22:41:06,136 - tools.log - ERROR - (1048, "Column 'task_status' cannot be null")
2019-09-05 22:41:13,724 - tools.log - ERROR - (1048, "Column 'task_status' cannot be null")
2019-09-05 22:42:45,870 - django.request - WARNING - Not Found: /set_task_status/
2019-09-05 22:43:37,338 - django.request - WARNING - Not Found: /set_task_status/
2019-09-05 22:43:40,387 - django.request - WARNING - Not Found: /set_task_status/
2019-09-05 22:45:04,366 - django.request - WARNING - Not Found: /set_task_status/
2019-09-05 23:01:50,421 - django.request - WARNING - Not Found: /selectApiEnvName/
2019-09-05 23:01:59,840 - django.request - WARNING - Not Found: /selectApiEnvName/
2019-09-05 23:02:54,032 - django.request - WARNING - Not Found: /selectApiEnvName/
2019-09-05 23:08:39,516 - django.request - WARNING - Not Found: /selectApiEnvName/
2019-09-05 23:08:54,432 - django.request - WARNING - Not Found: /selectApiEnvName/
2019-09-05 23:11:39,232 - django.request - WARNING - Not Found: /selectApiEnvName/
2019-09-05 23:11:43,279 - django.request - WARNING - Not Found: /selectApiEnvName/
2019-09-06 12:47:28,258 - django.request - WARNING - Not Found: /selectApiEnvName/
2019-09-06 12:47:42,084 - django.request - WARNING - Not Found: /selectApiEnvName/
2019-09-06 12:47:44,990 - django.request - WARNING - Not Found: /selectApiEnvName/
2019-09-06 12:47:45,862 - django.request - WARNING - Not Found: /selectApiEnvName/
2019-09-06 12:47:52,367 - django.request - WARNING - Not Found: /selectApiEnvName/
2019-09-06 12:51:25,536 - django.request - WARNING - Not Found: /selectApiEnvName/
2019-09-06 12:51:26,547 - django.request - WARNING - Not Found: /selectApiEnvName/
2019-09-06 12:51:27,425 - django.request - WARNING - Not Found: /selectApiEnvName/
2019-09-06 12:51:28,064 - django.request - WARNING - Not Found: /selectApiEnvName/
2019-09-06 12:52:04,726 - django.request - WARNING - Not Found: /selectApiEnvName/
2019-09-06 12:53:33,236 - django.request - WARNING - Not Found: /caseTaskPost/
2019-09-06 13:46:20,523 - django.request - WARNING - Not Found: /selectApiEnvName/
2019-09-06 13:47:53,952 - django.request - WARNING - Not Found: /selectApiEnvName/
2019-09-06 13:56:06,716 - django.request - WARNING - Not Found: /selectApiEnvName/
2019-09-06 13:57:10,022 - django.request - WARNING - Not Found: /selectApiEnvName/
2019-09-06 14:12:37,800 - django.request - WARNING - Not Found: /selectApiEnvName/
2019-09-06 14:12:57,821 - django.request - WARNING - Not Found: /selectApiEnvName/
2019-09-06 14:13:11,341 - django.request - WARNING - Not Found: /selectApiEnvName/
2019-09-06 14:13:12,888 - django.request - WARNING - Not Found: /selectApiEnvName/
2019-09-06 14:13:13,936 - django.request - WARNING - Not Found: /selectApiEnvName/
2019-09-06 14:13:28,769 - django.request - WARNING - Not Found: /selectApiEnvName/
2019-09-06 14:14:54,654 - django.request - WARNING - Not Found: /selectApiEnvName/
2019-09-06 14:56:42,879 - django.request - WARNING - Not Found: /selectApiEnvName/
2019-09-06 14:56:46,915 - tools.log - ERROR - the JSON object must be str, bytes or bytearray, not 'NoneType'
2019-09-06 14:56:48,381 - django.request - WARNING - Not Found: /selectApiEnvName/
2019-09-06 15:05:22,630 - django.request - WARNING - Not Found: /selectApiEnvName/
2019-09-06 15:06:30,620 - django.request - WARNING - Not Found: /selectApiEnvName/
2019-09-06 15:11:18,270 - tools.log - ERROR - the JSON object must be str, bytes or bytearray, not 'NoneType'
2019-09-06 15:11:18,787 - django.request - WARNING - Not Found: /selectApiEnvName/
2019-09-06 15:11:22,599 - tools.log - ERROR - the JSON object must be str, bytes or bytearray, not 'NoneType'
2019-09-06 15:11:23,983 - django.request - WARNING - Not Found: /selectApiEnvName/
2019-09-06 15:12:41,039 - django.request - WARNING - Not Found: /selectApiEnvName/
2019-09-06 15:13:56,809 - django.request - WARNING - Not Found: /selectApiEnvName/
2019-09-06 15:13:56,878 - django.request - ERROR - Internal Server Error: /get_task_cases
Traceback (most recent call last):
  File "D:\Program Files\python\lib\site-packages\django\core\handlers\exception.py", line 34, in inner
    response = get_response(request)
  File "D:\Program Files\python\lib\site-packages\django\core\handlers\base.py", line 126, in _get_response
    response = self.process_exception_by_middleware(e, request)
  File "D:\Program Files\python\lib\site-packages\django\core\handlers\base.py", line 124, in _get_response
    response = wrapped_callback(request, *callback_args, **callback_kwargs)
  File "D:\Program Files\python\lib\site-packages\django\contrib\auth\decorators.py", line 21, in _wrapped_view
    return view_func(request, *args, **kwargs)
  File "D:\Program Files\python\lib\site-packages\django\views\decorators\http.py", line 40, in inner
    return func(request, *args, **kwargs)
  File "D:\Program Files\IAM\api\views.py", line 1199, in get_task_cases
    de['case_name'] = task_cases.case_name
AttributeError: 'QuerySet' object has no attribute 'case_name'
2019-09-06 15:14:59,080 - django.request - WARNING - Not Found: /selectApiEnvName/
2019-09-06 15:14:59,123 - django.request - ERROR - Internal Server Error: /get_task_cases
Traceback (most recent call last):
  File "D:\Program Files\python\lib\site-packages\django\core\handlers\exception.py", line 34, in inner
    response = get_response(request)
  File "D:\Program Files\python\lib\site-packages\django\core\handlers\base.py", line 126, in _get_response
    response = self.process_exception_by_middleware(e, request)
  File "D:\Program Files\python\lib\site-packages\django\core\handlers\base.py", line 124, in _get_response
    response = wrapped_callback(request, *callback_args, **callback_kwargs)
  File "D:\Program Files\python\lib\site-packages\django\contrib\auth\decorators.py", line 21, in _wrapped_view
    return view_func(request, *args, **kwargs)
  File "D:\Program Files\python\lib\site-packages\django\views\decorators\http.py", line 40, in inner
    return func(request, *args, **kwargs)
  File "D:\Program Files\IAM\api\views.py", line 1198, in get_task_cases
    de['id'] = task_case.id
AttributeError: 'dict' object has no attribute 'id'
2019-09-06 15:15:21,655 - django.request - WARNING - Not Found: /selectApiEnvName/
2019-09-06 15:15:21,691 - django.request - ERROR - Internal Server Error: /get_task_cases
Traceback (most recent call last):
  File "D:\Program Files\python\lib\site-packages\django\core\handlers\exception.py", line 34, in inner
    response = get_response(request)
  File "D:\Program Files\python\lib\site-packages\django\core\handlers\base.py", line 126, in _get_response
    response = self.process_exception_by_middleware(e, request)
  File "D:\Program Files\python\lib\site-packages\django\core\handlers\base.py", line 124, in _get_response
    response = wrapped_callback(request, *callback_args, **callback_kwargs)
  File "D:\Program Files\python\lib\site-packages\django\contrib\auth\decorators.py", line 21, in _wrapped_view
    return view_func(request, *args, **kwargs)
  File "D:\Program Files\python\lib\site-packages\django\views\decorators\http.py", line 40, in inner
    return func(request, *args, **kwargs)
  File "D:\Program Files\IAM\api\views.py", line 1198, in get_task_cases
    de['id'] = task_case.id
AttributeError: 'dict' object has no attribute 'id'
2019-09-06 15:15:42,991 - django.request - WARNING - Not Found: /selectApiEnvName/
2019-09-06 15:15:43,009 - django.request - ERROR - Internal Server Error: /get_task_cases
Traceback (most recent call last):
  File "D:\Program Files\python\lib\site-packages\django\core\handlers\exception.py", line 34, in inner
    response = get_response(request)
  File "D:\Program Files\python\lib\site-packages\django\core\handlers\base.py", line 126, in _get_response
    response = self.process_exception_by_middleware(e, request)
  File "D:\Program Files\python\lib\site-packages\django\core\handlers\base.py", line 124, in _get_response
    response = wrapped_callback(request, *callback_args, **callback_kwargs)
  File "D:\Program Files\python\lib\site-packages\django\contrib\auth\decorators.py", line 21, in _wrapped_view
    return view_func(request, *args, **kwargs)
  File "D:\Program Files\python\lib\site-packages\django\views\decorators\http.py", line 40, in inner
    return func(request, *args, **kwargs)
  File "D:\Program Files\IAM\api\views.py", line 1198, in get_task_cases
    de['id'] = task_case.id
AttributeError: 'dict' object has no attribute 'id'
2019-09-06 15:19:19,529 - django.request - WARNING - Not Found: /selectApiEnvName/
2019-09-06 15:19:19,548 - django.request - ERROR - Internal Server Error: /get_task_cases
Traceback (most recent call last):
  File "D:\Program Files\python\lib\site-packages\django\core\handlers\exception.py", line 34, in inner
    response = get_response(request)
  File "D:\Program Files\python\lib\site-packages\django\core\handlers\base.py", line 126, in _get_response
    response = self.process_exception_by_middleware(e, request)
  File "D:\Program Files\python\lib\site-packages\django\core\handlers\base.py", line 124, in _get_response
    response = wrapped_callback(request, *callback_args, **callback_kwargs)
  File "D:\Program Files\python\lib\site-packages\django\contrib\auth\decorators.py", line 21, in _wrapped_view
    return view_func(request, *args, **kwargs)
  File "D:\Program Files\python\lib\site-packages\django\views\decorators\http.py", line 40, in inner
    return func(request, *args, **kwargs)
  File "D:\Program Files\IAM\api\views.py", line 1198, in get_task_cases
    de['id'] = task_case['id']
TypeError: 'TaskCase' object is not subscriptable
2019-09-06 15:20:35,147 - django.request - WARNING - Not Found: /selectApiEnvName/
2019-09-06 15:20:35,168 - django.request - ERROR - Internal Server Error: /get_task_cases
Traceback (most recent call last):
  File "D:\Program Files\python\lib\site-packages\django\core\handlers\exception.py", line 34, in inner
    response = get_response(request)
  File "D:\Program Files\python\lib\site-packages\django\core\handlers\base.py", line 126, in _get_response
    response = self.process_exception_by_middleware(e, request)
  File "D:\Program Files\python\lib\site-packages\django\core\handlers\base.py", line 124, in _get_response
    response = wrapped_callback(request, *callback_args, **callback_kwargs)
  File "D:\Program Files\python\lib\site-packages\django\contrib\auth\decorators.py", line 21, in _wrapped_view
    return view_func(request, *args, **kwargs)
  File "D:\Program Files\python\lib\site-packages\django\views\decorators\http.py", line 40, in inner
    return func(request, *args, **kwargs)
  File "D:\Program Files\IAM\api\views.py", line 1198, in get_task_cases
    de['id'] = task_case['case_id']
TypeError: 'TaskCase' object is not subscriptable
2019-09-06 15:21:10,597 - django.request - WARNING - Not Found: /selectApiEnvName/
2019-09-06 15:21:10,654 - django.request - ERROR - Internal Server Error: /get_task_cases
Traceback (most recent call last):
  File "D:\Program Files\python\lib\site-packages\django\core\handlers\exception.py", line 34, in inner
    response = get_response(request)
  File "D:\Program Files\python\lib\site-packages\django\core\handlers\base.py", line 126, in _get_response
    response = self.process_exception_by_middleware(e, request)
  File "D:\Program Files\python\lib\site-packages\django\core\handlers\base.py", line 124, in _get_response
    response = wrapped_callback(request, *callback_args, **callback_kwargs)
  File "D:\Program Files\python\lib\site-packages\django\contrib\auth\decorators.py", line 21, in _wrapped_view
    return view_func(request, *args, **kwargs)
  File "D:\Program Files\python\lib\site-packages\django\views\decorators\http.py", line 40, in inner
    return func(request, *args, **kwargs)
  File "D:\Program Files\IAM\api\views.py", line 1202, in get_task_cases
    de['api_path'] = Api.objects.filter(id=case_api_id).values_list("api_path").first()
  File "D:\Program Files\python\lib\site-packages\django\db\models\manager.py", line 82, in manager_method
    return getattr(self.get_queryset(), name)(*args, **kwargs)
  File "D:\Program Files\python\lib\site-packages\django\db\models\query.py", line 841, in filter
    return self._filter_or_exclude(False, *args, **kwargs)
  File "D:\Program Files\python\lib\site-packages\django\db\models\query.py", line 859, in _filter_or_exclude
    clone.query.add_q(Q(*args, **kwargs))
  File "D:\Program Files\python\lib\site-packages\django\db\models\sql\query.py", line 1263, in add_q
    clause, _ = self._add_q(q_object, self.used_aliases)
  File "D:\Program Files\python\lib\site-packages\django\db\models\sql\query.py", line 1287, in _add_q
    split_subq=split_subq,
  File "D:\Program Files\python\lib\site-packages\django\db\models\sql\query.py", line 1225, in build_filter
    condition = self.build_lookup(lookups, col, value)
  File "D:\Program Files\python\lib\site-packages\django\db\models\sql\query.py", line 1096, in build_lookup
    lookup = lookup_class(lhs, rhs)
  File "D:\Program Files\python\lib\site-packages\django\db\models\lookups.py", line 20, in __init__
    self.rhs = self.get_prep_lookup()
  File "D:\Program Files\python\lib\site-packages\django\db\models\lookups.py", line 70, in get_prep_lookup
    return self.lhs.output_field.get_prep_value(self.rhs)
  File "D:\Program Files\python\lib\site-packages\django\db\models\fields\__init__.py", line 965, in get_prep_value
    return int(value)
TypeError: int() argument must be a string, a bytes-like object or a number, not 'tuple'
2019-09-06 15:22:27,441 - django.request - WARNING - Not Found: /selectApiEnvName/
2019-09-06 15:22:27,487 - django.request - ERROR - Internal Server Error: /get_task_cases
Traceback (most recent call last):
  File "D:\Program Files\python\lib\site-packages\django\core\handlers\exception.py", line 34, in inner
    response = get_response(request)
  File "D:\Program Files\python\lib\site-packages\django\core\handlers\base.py", line 126, in _get_response
    response = self.process_exception_by_middleware(e, request)
  File "D:\Program Files\python\lib\site-packages\django\core\handlers\base.py", line 124, in _get_response
    response = wrapped_callback(request, *callback_args, **callback_kwargs)
  File "D:\Program Files\python\lib\site-packages\django\contrib\auth\decorators.py", line 21, in _wrapped_view
    return view_func(request, *args, **kwargs)
  File "D:\Program Files\python\lib\site-packages\django\views\decorators\http.py", line 40, in inner
    return func(request, *args, **kwargs)
  File "D:\Program Files\IAM\api\views.py", line 1203, in get_task_cases
    de['api_path'] = Api.objects.filter(id=case_api_id).values_list("api_path").first()
  File "D:\Program Files\python\lib\site-packages\django\db\models\manager.py", line 82, in manager_method
    return getattr(self.get_queryset(), name)(*args, **kwargs)
  File "D:\Program Files\python\lib\site-packages\django\db\models\query.py", line 841, in filter
    return self._filter_or_exclude(False, *args, **kwargs)
  File "D:\Program Files\python\lib\site-packages\django\db\models\query.py", line 859, in _filter_or_exclude
    clone.query.add_q(Q(*args, **kwargs))
  File "D:\Program Files\python\lib\site-packages\django\db\models\sql\query.py", line 1263, in add_q
    clause, _ = self._add_q(q_object, self.used_aliases)
  File "D:\Program Files\python\lib\site-packages\django\db\models\sql\query.py", line 1287, in _add_q
    split_subq=split_subq,
  File "D:\Program Files\python\lib\site-packages\django\db\models\sql\query.py", line 1225, in build_filter
    condition = self.build_lookup(lookups, col, value)
  File "D:\Program Files\python\lib\site-packages\django\db\models\sql\query.py", line 1096, in build_lookup
    lookup = lookup_class(lhs, rhs)
  File "D:\Program Files\python\lib\site-packages\django\db\models\lookups.py", line 20, in __init__
    self.rhs = self.get_prep_lookup()
  File "D:\Program Files\python\lib\site-packages\django\db\models\lookups.py", line 70, in get_prep_lookup
    return self.lhs.output_field.get_prep_value(self.rhs)
  File "D:\Program Files\python\lib\site-packages\django\db\models\fields\__init__.py", line 965, in get_prep_value
    return int(value)
TypeError: int() argument must be a string, a bytes-like object or a number, not 'tuple'
2019-09-06 15:23:08,345 - django.request - WARNING - Not Found: /selectApiEnvName/
2019-09-06 15:23:08,407 - django.request - ERROR - Internal Server Error: /get_task_cases
Traceback (most recent call last):
  File "D:\Program Files\python\lib\site-packages\django\core\handlers\exception.py", line 34, in inner
    response = get_response(request)
  File "D:\Program Files\python\lib\site-packages\django\core\handlers\base.py", line 126, in _get_response
    response = self.process_exception_by_middleware(e, request)
  File "D:\Program Files\python\lib\site-packages\django\core\handlers\base.py", line 124, in _get_response
    response = wrapped_callback(request, *callback_args, **callback_kwargs)
  File "D:\Program Files\python\lib\site-packages\django\contrib\auth\decorators.py", line 21, in _wrapped_view
    return view_func(request, *args, **kwargs)
  File "D:\Program Files\python\lib\site-packages\django\views\decorators\http.py", line 40, in inner
    return func(request, *args, **kwargs)
  File "D:\Program Files\IAM\api\views.py", line 1204, in get_task_cases
    de['api_path'] = Api.objects.filter(id=case_api_id).values_list("api_path").first()
  File "D:\Program Files\python\lib\site-packages\django\db\models\manager.py", line 82, in manager_method
    return getattr(self.get_queryset(), name)(*args, **kwargs)
  File "D:\Program Files\python\lib\site-packages\django\db\models\query.py", line 841, in filter
    return self._filter_or_exclude(False, *args, **kwargs)
  File "D:\Program Files\python\lib\site-packages\django\db\models\query.py", line 859, in _filter_or_exclude
    clone.query.add_q(Q(*args, **kwargs))
  File "D:\Program Files\python\lib\site-packages\django\db\models\sql\query.py", line 1263, in add_q
    clause, _ = self._add_q(q_object, self.used_aliases)
  File "D:\Program Files\python\lib\site-packages\django\db\models\sql\query.py", line 1287, in _add_q
    split_subq=split_subq,
  File "D:\Program Files\python\lib\site-packages\django\db\models\sql\query.py", line 1225, in build_filter
    condition = self.build_lookup(lookups, col, value)
  File "D:\Program Files\python\lib\site-packages\django\db\models\sql\query.py", line 1096, in build_lookup
    lookup = lookup_class(lhs, rhs)
  File "D:\Program Files\python\lib\site-packages\django\db\models\lookups.py", line 20, in __init__
    self.rhs = self.get_prep_lookup()
  File "D:\Program Files\python\lib\site-packages\django\db\models\lookups.py", line 70, in get_prep_lookup
    return self.lhs.output_field.get_prep_value(self.rhs)
  File "D:\Program Files\python\lib\site-packages\django\db\models\fields\__init__.py", line 965, in get_prep_value
    return int(value)
TypeError: int() argument must be a string, a bytes-like object or a number, not 'tuple'
2019-09-06 15:24:42,333 - django.request - WARNING - Not Found: /selectApiEnvName/
2019-09-06 15:25:25,497 - django.request - WARNING - Not Found: /selectApiEnvName/
2019-09-06 15:25:44,541 - django.request - WARNING - Not Found: /selectApiEnvName/
2019-09-06 15:26:13,662 - django.request - WARNING - Not Found: /selectApiEnvName/
2019-09-06 15:27:45,544 - django.request - WARNING - Not Found: /selectApiEnvName/
2019-09-06 15:27:59,974 - django.request - WARNING - Not Found: /selectApiEnvName/
2019-09-06 15:40:59,449 - django.request - WARNING - Not Found: /caseTaskPost/
2019-09-06 15:57:40,872 - django.request - WARNING - Not Found: /task_detail/1/1
2019-09-08 14:58:59,362 - django.request - WARNING - Not Found: /task_detail/1/5
2019-09-08 15:16:58,287 - django.security.csrf - WARNING - Forbidden (CSRF token missing or incorrect.): /run_task
2019-09-08 15:17:09,004 - django.security.csrf - WARNING - Forbidden (CSRF token missing or incorrect.): /run_task
2019-09-08 15:18:38,705 - tools.log - ERROR - Thread.__init__() not called
2019-09-08 15:18:38,751 - django.request - ERROR - Internal Server Error: /run_task
Traceback (most recent call last):
  File "D:\Program Files\python\lib\site-packages\django\core\handlers\exception.py", line 34, in inner
    response = get_response(request)
  File "D:\Program Files\python\lib\site-packages\django\core\handlers\base.py", line 126, in _get_response
    response = self.process_exception_by_middleware(e, request)
  File "D:\Program Files\python\lib\site-packages\django\core\handlers\base.py", line 124, in _get_response
    response = wrapped_callback(request, *callback_args, **callback_kwargs)
  File "D:\Program Files\python\lib\site-packages\django\contrib\auth\decorators.py", line 21, in _wrapped_view
    return view_func(request, *args, **kwargs)
  File "D:\Program Files\python\lib\site-packages\django\views\decorators\http.py", line 40, in inner
    return func(request, *args, **kwargs)
  File "D:\Program Files\IAM\api\views.py", line 1273, in run_task
    rt.run()
  File "D:\Program Files\IAM\tools\task_run.py", line 87, in run
    self.logger.info("end_test:thread=%s,task=%s" % (self.getName(), self.task_id))
  File "D:\Program Files\python\lib\threading.py", line 1151, in getName
    return self.name
  File "D:\Program Files\python\lib\threading.py", line 1084, in name
    assert self._initialized, "Thread.__init__() not called"
AssertionError: Thread.__init__() not called
2019-09-08 15:22:06,216 - tools.log - INFO - start_test:thread=Thread-8,task=5
2019-09-08 15:22:06,328 - tools.log - ERROR - 'Case' object does not support item assignment
2019-09-08 15:22:06,329 - tools.log - INFO - end_test:thread=Thread-8,task=5
2019-09-08 15:22:15,279 - django.request - ERROR - Internal Server Error: /get_project_tasks
Traceback (most recent call last):
  File "D:\Program Files\python\lib\site-packages\django\core\handlers\exception.py", line 34, in inner
    response = get_response(request)
  File "D:\Program Files\python\lib\site-packages\django\core\handlers\base.py", line 126, in _get_response
    response = self.process_exception_by_middleware(e, request)
  File "D:\Program Files\python\lib\site-packages\django\core\handlers\base.py", line 124, in _get_response
    response = wrapped_callback(request, *callback_args, **callback_kwargs)
  File "D:\Program Files\python\lib\site-packages\django\contrib\auth\decorators.py", line 21, in _wrapped_view
    return view_func(request, *args, **kwargs)
  File "D:\Program Files\python\lib\site-packages\django\views\decorators\http.py", line 40, in inner
    return func(request, *args, **kwargs)
  File "D:\Program Files\IAM\api\views.py", line 1064, in get_project_tasks
    de['last_task_time'] = last_task_log.get('create_time')
AttributeError: 'TaskLog' object has no attribute 'get'
2019-09-08 16:11:41,424 - tools.log - INFO - start_test:thread=Thread-3,task=5
2019-09-08 16:11:41,620 - tools.log - ERROR - eval() arg 1 must be a string, bytes or code object
2019-09-08 16:11:41,620 - tools.log - INFO - end_test:thread=Thread-3,task=5
2019-09-08 16:13:53,926 - tools.log - INFO - start_test:thread=Thread-3,task=5
2019-09-08 16:13:54,046 - tools.log - ERROR - too many values to unpack (expected 2)
2019-09-08 16:13:54,046 - tools.log - INFO - end_test:thread=Thread-3,task=5
2019-09-08 16:18:32,654 - tools.log - INFO - start_test:thread=Thread-3,task=5
2019-09-08 16:18:32,843 - tools.log - ERROR - too many values to unpack (expected 2)
2019-09-08 16:18:32,843 - tools.log - INFO - end_test:thread=Thread-3,task=5
2019-09-08 16:19:45,462 - tools.log - INFO - start_test:thread=Thread-22,task=5
2019-09-08 16:19:45,661 - tools.log - ERROR - too many values to unpack (expected 2)
2019-09-08 16:19:45,661 - tools.log - INFO - end_test:thread=Thread-22,task=5
2019-09-08 16:21:07,610 - tools.log - INFO - start_test:thread=Thread-3,task=5
2019-09-08 16:21:07,809 - tools.log - ERROR - too many values to unpack (expected 2)
2019-09-08 16:21:07,810 - tools.log - INFO - end_test:thread=Thread-3,task=5
2019-09-08 16:21:50,590 - tools.log - INFO - start_test:thread=Thread-3,task=5
2019-09-08 16:21:50,723 - tools.log - ERROR - too many values to unpack (expected 2)
2019-09-08 16:21:50,723 - tools.log - INFO - end_test:thread=Thread-3,task=5
2019-09-08 16:23:10,723 - tools.log - INFO - start_test:thread=Thread-8,task=5
2019-09-08 16:23:10,889 - tools.log - ERROR - too many values to unpack (expected 2)
2019-09-08 16:23:10,889 - tools.log - INFO - end_test:thread=Thread-8,task=5
2019-09-08 16:29:04,133 - tools.log - INFO - start_test:thread=Thread-22,task=5
2019-09-08 16:29:07,024 - tools.log - ERROR - HTTPConnectionPool(host='api', port=80): Max retries exceeded with url: /user/mobileLogin (Caused by NewConnectionError('<urllib3.connection.HTTPConnection object at 0x04B16AF0>: Failed to establish a new connection: [Errno 11004] getaddrinfo failed',))
2019-09-08 16:29:07,024 - tools.log - INFO - end_test:thread=Thread-22,task=5
2019-09-08 16:32:22,592 - tools.log - INFO - start_test:thread=Thread-22,task=5
2019-09-08 16:32:22,723 - tools.log - ERROR - HTTPConnectionPool(host='qampxq.xiaohulu.comapi', port=80): Max retries exceeded with url: /user/mobileLogin (Caused by NewConnectionError('<urllib3.connection.HTTPConnection object at 0x04D742F0>: Failed to establish a new connection: [Errno 11004] getaddrinfo failed',))
2019-09-08 16:32:22,723 - tools.log - INFO - end_test:thread=Thread-22,task=5
2019-09-08 16:34:53,970 - tools.log - INFO - start_test:thread=Thread-22,task=5
2019-09-08 16:34:54,275 - tools.log - ERROR - local variable 'acstatus' referenced before assignment
2019-09-08 16:34:54,275 - tools.log - INFO - end_test:thread=Thread-22,task=5
2019-09-08 16:36:35,057 - tools.log - INFO - start_test:thread=Thread-3,task=5
2019-09-08 16:36:35,248 - tools.log - ERROR - (1048, "Column 'case' cannot be null")
2019-09-08 16:36:35,248 - tools.log - INFO - end_test:thread=Thread-3,task=5
2019-09-08 16:41:11,016 - tools.log - INFO - start_test:thread=Thread-3,task=5
2019-09-08 16:41:11,301 - tools.log - INFO - end_test:thread=Thread-3,task=5
2019-09-08 16:42:56,565 - tools.log - INFO - start_test:thread=Thread-7,task=5
2019-09-08 16:43:01,894 - tools.log - INFO - end_test:thread=Thread-7,task=5
2019-09-08 16:43:18,898 - tools.log - INFO - start_test:thread=Thread-9,task=5
2019-09-08 16:43:24,112 - tools.log - INFO - end_test:thread=Thread-9,task=5
2019-09-08 16:50:33,934 - tools.log - INFO - start_test:thread=Thread-3,task=5
2019-09-08 16:50:39,337 - tools.log - INFO - end_test:thread=Thread-3,task=5
2019-09-08 16:50:44,521 - tools.log - INFO - start_test:thread=Thread-5,task=5
2019-09-08 16:50:46,833 - tools.log - INFO - start_test:thread=Thread-7,task=5
2019-09-08 16:50:47,608 - tools.log - INFO - start_test:thread=Thread-9,task=5
2019-09-08 16:50:48,156 - tools.log - INFO - start_test:thread=Thread-11,task=5
2019-09-08 16:50:49,930 - tools.log - INFO - end_test:thread=Thread-5,task=5
2019-09-08 16:50:52,128 - tools.log - INFO - end_test:thread=Thread-7,task=5
2019-09-08 16:50:52,880 - tools.log - INFO - end_test:thread=Thread-9,task=5
2019-09-08 16:50:53,372 - tools.log - INFO - end_test:thread=Thread-11,task=5
2019-09-08 17:06:57,064 - django.request - WARNING - Not Found: /task_detail/1/5
2019-09-08 17:09:16,075 - tools.log - INFO - start_test:thread=Thread-37,task=5
2019-09-08 17:09:26,747 - tools.log - INFO - end_test:thread=Thread-37,task=5
2019-09-08 17:12:32,147 - tools.log - INFO - start_test:thread=Thread-3,task=5
2019-09-08 17:12:32,261 - tools.log - INFO - ==================== thread=Thread-3,task=5,case=test1 ====================
2019-09-08 17:12:33,480 - tools.log - INFO - ==================== thread=Thread-3,task=5,case=登陆失败 ====================
2019-09-08 17:12:34,687 - tools.log - INFO - end_test:thread=Thread-3,task=5
2019-09-08 17:19:47,528 - tools.log - INFO - start_test:thread=Thread-3,task=5
2019-09-08 17:19:47,663 - tools.log - INFO - ==================== thread=Thread-3,task=5,case=test1 ====================
2019-09-08 17:19:48,906 - tools.log - INFO - ==================== thread=Thread-3,task=5,case=登陆失败 ====================
2019-09-08 17:19:50,173 - tools.log - INFO - end_test:thread=Thread-3,task=5
2019-09-08 17:32:08,885 - tools.log - INFO - start_test:thread=Thread-8,task=5
2019-09-08 17:32:09,022 - tools.log - INFO - ==================== thread=Thread-8,task=5,case=test1 ====================
2019-09-08 17:32:10,281 - tools.log - INFO - ==================== thread=Thread-8,task=5,case=登陆失败 ====================
2019-09-08 17:32:11,502 - tools.log - INFO - end_test:thread=Thread-8,task=5
2019-09-08 17:34:27,151 - tools.log - INFO - start_test:thread=Thread-3,task=5
2019-09-08 17:34:27,566 - tools.log - INFO - ==================== thread=Thread-3,task=5,case=test1 ====================
2019-09-08 17:34:28,829 - tools.log - INFO - ==================== thread=Thread-3,task=5,case=登陆失败 ====================
2019-09-08 17:34:30,029 - tools.log - INFO - end_test:thread=Thread-3,task=5
2019-09-08 17:35:35,754 - tools.log - INFO - start_test:thread=Thread-3,task=5
2019-09-08 17:35:35,872 - tools.log - INFO - ==================== thread=Thread-3,task=5,case=test1 ====================
2019-09-08 17:35:37,073 - tools.log - INFO - ==================== thread=Thread-3,task=5,case=登陆失败 ====================
2019-09-08 17:35:38,302 - tools.log - INFO - end_test:thread=Thread-3,task=5
2019-09-08 17:36:28,975 - tools.log - INFO - start_test:thread=Thread-3,task=5
2019-09-08 17:36:29,133 - tools.log - INFO - ==================== thread=Thread-3,task=5,case=test1 ====================
2019-09-08 17:36:30,558 - tools.log - INFO - ==================== thread=Thread-3,task=5,case=登陆失败 ====================
2019-09-08 17:36:31,789 - tools.log - INFO - end_test:thread=Thread-3,task=5
2019-09-08 18:23:43,379 - django.request - WARNING - Not Found: /task_add/1/
2019-09-08 19:15:57,337 - django.request - WARNING - Not Found: /caseTaskPost/
2019-09-08 19:16:50,716 - django.request - WARNING - Not Found: /caseTaskPost/
2019-09-08 19:17:00,962 - django.request - WARNING - Not Found: /edit_project_task/
2019-09-08 19:17:10,504 - django.request - WARNING - Not Found: /edit_project_task/
2019-09-08 19:17:45,857 - django.security.csrf - WARNING - Forbidden (CSRF token missing or incorrect.): /edit_project_task/
2019-09-08 19:21:52,602 - django.request - WARNING - Not Found: /task_index/
2019-09-08 19:32:22,755 - django.request - WARNING - Not Found: /task_detail/1/5
2019-09-08 19:32:34,852 - django.request - ERROR - Internal Server Error: /search_project_tasks
Traceback (most recent call last):
  File "D:\Program Files\python\lib\site-packages\django\core\handlers\exception.py", line 34, in inner
    response = get_response(request)
  File "D:\Program Files\python\lib\site-packages\django\core\handlers\base.py", line 126, in _get_response
    response = self.process_exception_by_middleware(e, request)
  File "D:\Program Files\python\lib\site-packages\django\core\handlers\base.py", line 124, in _get_response
    response = wrapped_callback(request, *callback_args, **callback_kwargs)
  File "D:\Program Files\python\lib\site-packages\django\contrib\auth\decorators.py", line 21, in _wrapped_view
    return view_func(request, *args, **kwargs)
  File "D:\Program Files\python\lib\site-packages\django\views\decorators\http.py", line 40, in inner
    return func(request, *args, **kwargs)
  File "D:\Program Files\IAM\api\views.py", line 1095, in search_project_tasks
    de['last_task_time'] = last_task_log.get('create_time').strftime("%Y-%m-%d %H:%M:%S")
AttributeError: 'TaskLog' object has no attribute 'get'
2019-09-08 19:32:37,182 - django.request - ERROR - Internal Server Error: /search_project_tasks
Traceback (most recent call last):
  File "D:\Program Files\python\lib\site-packages\django\core\handlers\exception.py", line 34, in inner
    response = get_response(request)
  File "D:\Program Files\python\lib\site-packages\django\core\handlers\base.py", line 126, in _get_response
    response = self.process_exception_by_middleware(e, request)
  File "D:\Program Files\python\lib\site-packages\django\core\handlers\base.py", line 124, in _get_response
    response = wrapped_callback(request, *callback_args, **callback_kwargs)
  File "D:\Program Files\python\lib\site-packages\django\contrib\auth\decorators.py", line 21, in _wrapped_view
    return view_func(request, *args, **kwargs)
  File "D:\Program Files\python\lib\site-packages\django\views\decorators\http.py", line 40, in inner
    return func(request, *args, **kwargs)
  File "D:\Program Files\IAM\api\views.py", line 1095, in search_project_tasks
    de['last_task_time'] = last_task_log.get('create_time').strftime("%Y-%m-%d %H:%M:%S")
AttributeError: 'TaskLog' object has no attribute 'get'
2019-09-08 19:32:38,041 - django.request - ERROR - Internal Server Error: /search_project_tasks
Traceback (most recent call last):
  File "D:\Program Files\python\lib\site-packages\django\core\handlers\exception.py", line 34, in inner
    response = get_response(request)
  File "D:\Program Files\python\lib\site-packages\django\core\handlers\base.py", line 126, in _get_response
    response = self.process_exception_by_middleware(e, request)
  File "D:\Program Files\python\lib\site-packages\django\core\handlers\base.py", line 124, in _get_response
    response = wrapped_callback(request, *callback_args, **callback_kwargs)
  File "D:\Program Files\python\lib\site-packages\django\contrib\auth\decorators.py", line 21, in _wrapped_view
    return view_func(request, *args, **kwargs)
  File "D:\Program Files\python\lib\site-packages\django\views\decorators\http.py", line 40, in inner
    return func(request, *args, **kwargs)
  File "D:\Program Files\IAM\api\views.py", line 1095, in search_project_tasks
    de['last_task_time'] = last_task_log.get('create_time').strftime("%Y-%m-%d %H:%M:%S")
AttributeError: 'TaskLog' object has no attribute 'get'
2019-09-08 19:32:38,609 - django.request - ERROR - Internal Server Error: /search_project_tasks
Traceback (most recent call last):
  File "D:\Program Files\python\lib\site-packages\django\core\handlers\exception.py", line 34, in inner
    response = get_response(request)
  File "D:\Program Files\python\lib\site-packages\django\core\handlers\base.py", line 126, in _get_response
    response = self.process_exception_by_middleware(e, request)
  File "D:\Program Files\python\lib\site-packages\django\core\handlers\base.py", line 124, in _get_response
    response = wrapped_callback(request, *callback_args, **callback_kwargs)
  File "D:\Program Files\python\lib\site-packages\django\contrib\auth\decorators.py", line 21, in _wrapped_view
    return view_func(request, *args, **kwargs)
  File "D:\Program Files\python\lib\site-packages\django\views\decorators\http.py", line 40, in inner
    return func(request, *args, **kwargs)
  File "D:\Program Files\IAM\api\views.py", line 1095, in search_project_tasks
    de['last_task_time'] = last_task_log.get('create_time').strftime("%Y-%m-%d %H:%M:%S")
AttributeError: 'TaskLog' object has no attribute 'get'
2019-09-08 19:32:39,253 - django.request - ERROR - Internal Server Error: /search_project_tasks
Traceback (most recent call last):
  File "D:\Program Files\python\lib\site-packages\django\core\handlers\exception.py", line 34, in inner
    response = get_response(request)
  File "D:\Program Files\python\lib\site-packages\django\core\handlers\base.py", line 126, in _get_response
    response = self.process_exception_by_middleware(e, request)
  File "D:\Program Files\python\lib\site-packages\django\core\handlers\base.py", line 124, in _get_response
    response = wrapped_callback(request, *callback_args, **callback_kwargs)
  File "D:\Program Files\python\lib\site-packages\django\contrib\auth\decorators.py", line 21, in _wrapped_view
    return view_func(request, *args, **kwargs)
  File "D:\Program Files\python\lib\site-packages\django\views\decorators\http.py", line 40, in inner
    return func(request, *args, **kwargs)
  File "D:\Program Files\IAM\api\views.py", line 1095, in search_project_tasks
    de['last_task_time'] = last_task_log.get('create_time').strftime("%Y-%m-%d %H:%M:%S")
AttributeError: 'TaskLog' object has no attribute 'get'
2019-09-08 19:32:39,502 - django.request - ERROR - Internal Server Error: /search_project_tasks
Traceback (most recent call last):
  File "D:\Program Files\python\lib\site-packages\django\core\handlers\exception.py", line 34, in inner
    response = get_response(request)
  File "D:\Program Files\python\lib\site-packages\django\core\handlers\base.py", line 126, in _get_response
    response = self.process_exception_by_middleware(e, request)
  File "D:\Program Files\python\lib\site-packages\django\core\handlers\base.py", line 124, in _get_response
    response = wrapped_callback(request, *callback_args, **callback_kwargs)
  File "D:\Program Files\python\lib\site-packages\django\contrib\auth\decorators.py", line 21, in _wrapped_view
    return view_func(request, *args, **kwargs)
  File "D:\Program Files\python\lib\site-packages\django\views\decorators\http.py", line 40, in inner
    return func(request, *args, **kwargs)
  File "D:\Program Files\IAM\api\views.py", line 1095, in search_project_tasks
    de['last_task_time'] = last_task_log.get('create_time').strftime("%Y-%m-%d %H:%M:%S")
AttributeError: 'TaskLog' object has no attribute 'get'
2019-09-08 19:32:39,677 - django.request - ERROR - Internal Server Error: /search_project_tasks
Traceback (most recent call last):
  File "D:\Program Files\python\lib\site-packages\django\core\handlers\exception.py", line 34, in inner
    response = get_response(request)
  File "D:\Program Files\python\lib\site-packages\django\core\handlers\base.py", line 126, in _get_response
    response = self.process_exception_by_middleware(e, request)
  File "D:\Program Files\python\lib\site-packages\django\core\handlers\base.py", line 124, in _get_response
    response = wrapped_callback(request, *callback_args, **callback_kwargs)
  File "D:\Program Files\python\lib\site-packages\django\contrib\auth\decorators.py", line 21, in _wrapped_view
    return view_func(request, *args, **kwargs)
  File "D:\Program Files\python\lib\site-packages\django\views\decorators\http.py", line 40, in inner
    return func(request, *args, **kwargs)
  File "D:\Program Files\IAM\api\views.py", line 1095, in search_project_tasks
    de['last_task_time'] = last_task_log.get('create_time').strftime("%Y-%m-%d %H:%M:%S")
AttributeError: 'TaskLog' object has no attribute 'get'
2019-09-08 19:32:39,868 - django.request - ERROR - Internal Server Error: /search_project_tasks
Traceback (most recent call last):
  File "D:\Program Files\python\lib\site-packages\django\core\handlers\exception.py", line 34, in inner
    response = get_response(request)
  File "D:\Program Files\python\lib\site-packages\django\core\handlers\base.py", line 126, in _get_response
    response = self.process_exception_by_middleware(e, request)
  File "D:\Program Files\python\lib\site-packages\django\core\handlers\base.py", line 124, in _get_response
    response = wrapped_callback(request, *callback_args, **callback_kwargs)
  File "D:\Program Files\python\lib\site-packages\django\contrib\auth\decorators.py", line 21, in _wrapped_view
    return view_func(request, *args, **kwargs)
  File "D:\Program Files\python\lib\site-packages\django\views\decorators\http.py", line 40, in inner
    return func(request, *args, **kwargs)
  File "D:\Program Files\IAM\api\views.py", line 1095, in search_project_tasks
    de['last_task_time'] = last_task_log.get('create_time').strftime("%Y-%m-%d %H:%M:%S")
AttributeError: 'TaskLog' object has no attribute 'get'
2019-09-08 19:32:40,060 - django.request - ERROR - Internal Server Error: /search_project_tasks
Traceback (most recent call last):
  File "D:\Program Files\python\lib\site-packages\django\core\handlers\exception.py", line 34, in inner
    response = get_response(request)
  File "D:\Program Files\python\lib\site-packages\django\core\handlers\base.py", line 126, in _get_response
    response = self.process_exception_by_middleware(e, request)
  File "D:\Program Files\python\lib\site-packages\django\core\handlers\base.py", line 124, in _get_response
    response = wrapped_callback(request, *callback_args, **callback_kwargs)
  File "D:\Program Files\python\lib\site-packages\django\contrib\auth\decorators.py", line 21, in _wrapped_view
    return view_func(request, *args, **kwargs)
  File "D:\Program Files\python\lib\site-packages\django\views\decorators\http.py", line 40, in inner
    return func(request, *args, **kwargs)
  File "D:\Program Files\IAM\api\views.py", line 1095, in search_project_tasks
    de['last_task_time'] = last_task_log.get('create_time').strftime("%Y-%m-%d %H:%M:%S")
AttributeError: 'TaskLog' object has no attribute 'get'
2019-09-08 19:32:40,258 - django.request - ERROR - Internal Server Error: /search_project_tasks
Traceback (most recent call last):
  File "D:\Program Files\python\lib\site-packages\django\core\handlers\exception.py", line 34, in inner
    response = get_response(request)
  File "D:\Program Files\python\lib\site-packages\django\core\handlers\base.py", line 126, in _get_response
    response = self.process_exception_by_middleware(e, request)
  File "D:\Program Files\python\lib\site-packages\django\core\handlers\base.py", line 124, in _get_response
    response = wrapped_callback(request, *callback_args, **callback_kwargs)
  File "D:\Program Files\python\lib\site-packages\django\contrib\auth\decorators.py", line 21, in _wrapped_view
    return view_func(request, *args, **kwargs)
  File "D:\Program Files\python\lib\site-packages\django\views\decorators\http.py", line 40, in inner
    return func(request, *args, **kwargs)
  File "D:\Program Files\IAM\api\views.py", line 1095, in search_project_tasks
    de['last_task_time'] = last_task_log.get('create_time').strftime("%Y-%m-%d %H:%M:%S")
AttributeError: 'TaskLog' object has no attribute 'get'
2019-09-08 19:32:40,490 - django.request - ERROR - Internal Server Error: /search_project_tasks
Traceback (most recent call last):
  File "D:\Program Files\python\lib\site-packages\django\core\handlers\exception.py", line 34, in inner
    response = get_response(request)
  File "D:\Program Files\python\lib\site-packages\django\core\handlers\base.py", line 126, in _get_response
    response = self.process_exception_by_middleware(e, request)
  File "D:\Program Files\python\lib\site-packages\django\core\handlers\base.py", line 124, in _get_response
    response = wrapped_callback(request, *callback_args, **callback_kwargs)
  File "D:\Program Files\python\lib\site-packages\django\contrib\auth\decorators.py", line 21, in _wrapped_view
    return view_func(request, *args, **kwargs)
  File "D:\Program Files\python\lib\site-packages\django\views\decorators\http.py", line 40, in inner
    return func(request, *args, **kwargs)
  File "D:\Program Files\IAM\api\views.py", line 1095, in search_project_tasks
    de['last_task_time'] = last_task_log.get('create_time').strftime("%Y-%m-%d %H:%M:%S")
AttributeError: 'TaskLog' object has no attribute 'get'
2019-09-08 19:32:40,673 - django.request - ERROR - Internal Server Error: /search_project_tasks
Traceback (most recent call last):
  File "D:\Program Files\python\lib\site-packages\django\core\handlers\exception.py", line 34, in inner
    response = get_response(request)
  File "D:\Program Files\python\lib\site-packages\django\core\handlers\base.py", line 126, in _get_response
    response = self.process_exception_by_middleware(e, request)
  File "D:\Program Files\python\lib\site-packages\django\core\handlers\base.py", line 124, in _get_response
    response = wrapped_callback(request, *callback_args, **callback_kwargs)
  File "D:\Program Files\python\lib\site-packages\django\contrib\auth\decorators.py", line 21, in _wrapped_view
    return view_func(request, *args, **kwargs)
  File "D:\Program Files\python\lib\site-packages\django\views\decorators\http.py", line 40, in inner
    return func(request, *args, **kwargs)
  File "D:\Program Files\IAM\api\views.py", line 1095, in search_project_tasks
    de['last_task_time'] = last_task_log.get('create_time').strftime("%Y-%m-%d %H:%M:%S")
AttributeError: 'TaskLog' object has no attribute 'get'
2019-09-08 20:05:59,621 - django.request - WARNING - Not Found: /task_detail/1/5
2019-09-08 20:18:19,914 - django.request - WARNING - Not Found: /get_task_logs
2019-09-08 20:19:34,395 - django.request - WARNING - Not Found: /get_task_logs
2019-09-08 20:21:22,314 - django.request - WARNING - Not Found: /get_task_logs
2019-09-08 20:22:53,930 - django.request - WARNING - Not Found: /get_task_logs
2019-09-08 20:24:38,481 - django.request - WARNING - Not Found: /get_task_logs
2019-09-09 00:34:00,371 - django.request - WARNING - Not Found: /get_task_report_log_detail
2019-09-09 00:34:01,602 - django.request - WARNING - Not Found: /get_task_report_log_detail
2019-09-09 00:34:02,186 - django.request - WARNING - Not Found: /get_task_report_log_detail
2019-09-09 00:34:02,381 - django.request - WARNING - Not Found: /get_task_report_log_detail
2019-09-09 00:34:02,937 - django.request - WARNING - Not Found: /get_task_report_log_detail
2019-09-09 00:34:03,126 - django.request - WARNING - Not Found: /get_task_report_log_detail
2019-09-09 00:34:10,530 - django.request - WARNING - Not Found: /get_task_report_log_detail
2019-09-09 10:02:39,103 - tools.log - INFO - start_test:thread=Thread-18,task=5
2019-09-09 10:02:39,333 - tools.log - INFO - ==================== thread=Thread-18,task=5,case=test1 ====================
2019-09-09 10:02:40,901 - tools.log - INFO - case_status:1
2019-09-09 10:02:40,902 - tools.log - INFO - ==================== thread=Thread-18,task=5,case=登陆失败 ====================
2019-09-09 10:02:42,115 - tools.log - INFO - case_status:2
2019-09-09 10:02:42,116 - tools.log - INFO - end_test:thread=Thread-18,task=5
